Workbook

Sheet Kiem_chung
A1: KẾT QUẢ ĐỐI CHIẾU & KIỂM CHỨNG 100% TỪ HỒ SƠ BCTC KIỂM TOÁN & BCTN GỐC (2020–2025)
A2: Đã tải và trích xuất trực tiếp từ 27 tệp PDF Báo cáo tài chính kiểm toán (Hợp nhất & Riêng lẻ) và Báo cáo thường niên 2020–2025 của Agribank và MB.
A4: STT | B4: Số liệu đã kiểm chứng | C4: Giá trị | D4: Nguồn
A5: 1 | B5: Agribank: dư nợ, NPL, CPDP, LNTT, CAR 2021–2025 | C5: Bảng chỉ tiêu AR 2025 | D5: https://static2.vietstock.vn/data/KHAC/2025/BCTN/VN/Agribank_Baocaothuongnien_2025.pdf
A6: 2 | B6: Agribank: thu hồi nợ đã xử lý 2024, 2025 | C6: 11.662; 16.305 tỷ (BCTN) / 12.123 tỷ (TM 29 BCTC) | D6: BCTN 2025 (tr.48); TM 29 BCTC HN 2025 (tr.46). Số 17.397 tỷ là ước tính sơ bộ trước kiểm toán.
A7: 3 | B7: Agribank: NN-NT 2024, 2025 | C7: 61,7%; 64,1% | D7: AR 2025 (như trên)
A8: 4 | B8: Agribank 2021: nợ xấu, NPL, LLCR (riêng lẻ) | C8: 24.553 tỷ; 1,87%; khoảng 139% | D8: https://viettimes.vn/bat-dong-san-the-chap-tai-mot-ngan-hang-vuot-2-trieu-ty-dong-post155948.html
A9: 5 | B9: Agribank 2024 hợp nhất: nợ xấu, NPL, LLCR, nhóm 5 | C9: 29.009 tỷ; 1,68%; 132%; nhóm 5 +16,2% | D9: https://baodautu.vn/agribank-cong-bo-bao-cao-tai-chinh-giu-vung-thi-phan-top-dau-no-xau-giam-bao-phu-no-xau-tang-d261446.html
A10: 6 | B10: MB 2022–2023: NPL, LLCR, nợ xấu | C10: 1,09%→1,60%; 238%→116,9%; 9.804 tỷ (+94,9%) | D10: https://www.abs.vn/wp-content/uploads/2024/04/240423-AGM_MBB.pdf
A11: 7 | B11: MB quý I/2023: NPL, LLCR, xóa nợ, TPDN | C11: 1,76%; 138%; 2.171 tỷ; 45.727 tỷ | D11: https://www.abs.vn/wp-content/uploads/2023/05/230525-MBB-Full-report.pdf
A12: 8 | B12: MB quý III/2023: NPL, LLCR | C12: 1,89%; khoảng 122% | D12: https://doanhnhan.baophapluat.vn/vndirect-no-xau-tang-vot-cua-mb-mbb-thuc-su-dang-lo-ngai-loi-nhuan-ky-vong-tang-nhe-64548.html
A13: 9 | B13: Hệ thống: NPL nội bảng 2020–2023 | C13: 1,69%; 1,49%; 2,03%; 4,55% | D13: NHNN qua baodauthau.vn, vneconomy.vn (xem sheet Nguon [26][27])
A15: STT | B15: Các chuẩn hóa số liệu từ Báo cáo tài chính Kiểm toán gốc | C15: Trước / Sau | D15: Lý do
A16: 1 | B16: Nợ nhóm 5 Agribank 2020–2025 (TM 9/10 BCTC HN) | C16: 16.357; 18.033; 19.000; 19.248; 22.638; 20.220 tỷ | D16: Trích xuất chính xác từ TM 9/10 BCTC HN kiểm toán 2020 (tr.35), 2021 (tr.45), 2023 (tr.61), 2025 (tr.170)
A17: 2 | B17: Nợ nhóm 2 Agribank 2020–2025 (TM 9/10 BCTC HN) | C17: 30.078; 28.446; 35.280; 32.340; 29.202; 21.282 tỷ | D17: Trích xuất chính xác từ TM 9/10 BCTC HN kiểm toán 2020–2025
A18: 3 | B18: Nợ xóa trong năm Agribank & MB 2020–2025 (TM 10/11) | C18: Agribank: 14.126..32.621 tỷ | MB: 4.980..12.185 tỷ | D18: Sử dụng dự phòng để xử lý rủi ro tín dụng trong năm trên TM 10/11 BCTC HN kiểm toán
A19: 4 | B19: Tài sản bảo đảm của KH Agribank 2020–2025 (TM 36/37) | C19: Tổng: 2.036.528 -> 3.739.943 tỷ (BĐS: 1.840.467 -> 3.371.568 tỷ) | D19: Trích xuất từ TM 36/37 BCTC HN kiểm toán 2020–2025 (BĐS chiếm 88,3%–91,7%)
A20: 5 | B20: Bóc tách MCredit & MBS từ BCTC Hợp nhất vs Riêng lẻ MB | C20: MCredit: 10.173 -> 29.622 tỷ (NPL 6,2%–8,5%) | D20: Chênh lệch dòng Cho vay hộ gia đình và Nợ xấu giữa BCTC Hợp nhất và Riêng lẻ MB
A22: STT | B22: Mâu thuẫn số liệu đã giải quyết triệt để nhờ BCTC gốc | C22: Đối chiếu hai nguồn | D22: Kết luận xác thực từ Thuyết minh BCTC Kiểm toán
A23: 1 | B23: TPDN của MB cuối 2022 (66.307 tỷ vs 46.870 tỷ) | C23: 46.870 tỷ (TCKT) vs 66.307 tỷ (TCTD) | D23: Đã giải quyết tại TM 12 BCTC HN 2022 (tr.237): 46.870 tỷ là TPDN do TCKT phát hành (AFS 42.382 + HTM 4.488); còn 66.307 tỷ là CK nợ do các TCTD phát hành.
A24: 2 | B24: Hai chuỗi NPL của Agribank (1,58%–1,17% vs 1,68%–1,30%) | C24: Chuẩn TT11/TT31 (BCTN) vs Chia trực tiếp Dư nợ cho vay (TM 9) | D24: 1,63%–1,17% tại BCTN 2024–2025 tính trên tổng cấp tín dụng theo TT11/TT31; còn 1,77%–1,30% là Nợ nhóm 3–5 chia trực tiếp cho Dư nợ cho vay KH tại TM 9.
A25: 3 | B25: LLCR của MB năm 2020–2021 (134%/268% vs 159%/349%) | C25: Hợp nhất (134,1%; 268,0%) vs Riêng lẻ (158,9%; 348,7%) | D25: Đã giải quyết: 134,07% (2020) và 267,98% (2021) là LLCR Hợp nhất; còn 158,86% (2020) và 348,74% (2021) là LLCR Riêng lẻ Ngân hàng mẹ.
A26: 4 | B26: CPDP Agribank 2021 (22.048 tỷ vs 22.060 tỷ) | C26: Hợp nhất (22.047,6 tỷ) vs Riêng lẻ (22.060,1 tỷ) | D26: Đã giải quyết: B03/TCTD-HN 2021 (tr.10) ghi nhận 22.047.625 triệu đồng; B03/TCTD Riêng lẻ 2021 (tr.11) ghi nhận 22.060.130 triệu đồng.
A27: 5 | B27: Thu hồi nợ đã xử lý Agribank 2024–2025 | C27: TM 29 BCTC (8.413; 12.123 tỷ) vs BCTN (11.662; 16.305 tỷ) | D27: TM 29 BCTC HN chỉ tính thu nợ gốc+lãi đã XLRR; BCTN gộp thêm thu từ xử lý tài sản thế chấp và thu khác từ hoạt động xử lý nợ.
B29: Bổ sung ngày 27/10/2026: số liệu đã kiểm chứng thêm
A30: 1 | B30: Agribank nợ có khả năng mất vốn 2023, 2024 | C30: 19.474; 22.637 tỷ | D30: https://tuoitre.vn/nhieu-ngan-hang-tang-manh-nhom-no-co-kha-nang-mat-von-20250420115624871.htm
A31: 2 | B31: MB NPL 2024: tập đoàn, riêng ngân hàng | C31: 1,6%; 1,4% | D31: https://static2.vietstock.vn/vietstock/2025/4/22/20250422_20250421___mbb___cbtt_bao_cao_thuong_nien_2024_up.pdf
A32: 3 | B32: MB NPL 2025 hợp nhất, riêng; LLCR hợp nhất, riêng | C32: 1,29%; 1,13%; 94%; khoảng 100% | D32: https://nhipsongkinhdoanh.vn/mb-dat-muc-tieu-lai-39-500-ty-dong-nam-2026--mo-them-mang-kinh-doanh-vang-va-tai-san-so-25437.htm
A33: 4 | B33: MB dư nợ cho vay 2024 | C33: 776.658 tỷ (+27,1%) | D33: https://dantri.com.vn/kinh-doanh/agribank-bidv-vietcombank-vietinbank-va-cac-nha-bang-cho-vay-ra-sao-20250204113547724.htm
A34: 5 | B34: Agribank 2025: NPL nội bảng; NPL theo phương án cơ cấu lại | C34: 1,14%; 1,21% | D34: https://doanhnhan.baophapluat.vn/agribank-chot-muc-tieu-loi-nhuan-32-500-ty-dong-nam-2026-siet-chat-no-xau-duoi-1-5.html
A35: 6 | B35: MCredit NPL cuối 2024 | C35: khoảng 8% | D35: https://nhipsongkinhdoanh.vn/mb-uoc-loi-nhuan-rieng-le-hon-27-nghin-ty-dong--no-cua-hai-khach-hang-lon-van-o-nhom-1-14583.htm
B37: Soát lại ngày 27/10/2026 theo đề gốc
A38: 1 | B38: Stress test Agribank: nợ xấu mới từ nhóm 2 | C38: 4.150/6.917/11.068 → 3.192/5.321/8.513 | D38: Công thức cũ dùng số nhóm 2 cũ 27.669 tỷ; nay nối với nhóm 2 BCTC 2025 = 21.282 tỷ
A39: 2 | B39: RAROC → RORAC proxy, cùng mẫu số | C39: MB: (cho vay + TPDN + mua nợ) × 8% → cho vay × 8% | D39: Hai ngân hàng phải cùng cơ sở; LNST đã trừ dự phòng nên không trừ thêm EL
A40: 3 | B40: CAR Agribank 2020–2022 | C40: Ghi chú cơ sở tính | D40: 2020–2022 theo TT 22/2019 (tối thiểu 9%); từ 2023 theo TT 41 – chỉ so sánh được với MB từ 2023
A41: 4 | B41: Tỷ trọng tam nông Agribank 2020–2022 | C41: 70,0/66,8/66,0 → ~70% / 65–70% / >65% | D41: BCTN chỉ công bố khoảng, không có số thập phân
A42: 5 | B42: So sánh NPL 2025 | C42: 1,17% vs 1,29% → 1,30% vs 1,29% | D42: 1,17% dùng mẫu số tổng cấp tín dụng (TT11/31); so cùng cơ sở dư nợ cho vay HN thì hai bên gần bằng nhau
B44: Soát xét kỹ thuật 28/10/2026 (đối chiếu Word – Excel) | C44: Trước → Sau | D44: Căn cứ
A45: 1 | B45: Nợ nhóm 5 Agribank 2023 | C45: 19.744 → 19.248 tỷ (67,0%) | D45: Nhóm 3 (3.880) + nhóm 4 (5.593) + nhóm 5 (19.248) = 28.721 tỷ = tổng nợ xấu TM 9; 19.744 làm tổng thành 29.217
A46: 2 | B46: Nợ xấu khối công ty con MB 2020–2024 (Bảng 9, Mục 5.2) | C46: 555/892/1.351/1.662/1.981 → 649/940/1.406/1.683/2.092 tỷ | D46: BCTC_MB_Goc dòng 60 = Nợ xấu HN − Riêng lẻ
...

Sheet Theo_doi
A1: DANH MỤC THÔNG TIN CẦN BỔ SUNG – theo dõi tiến độ (giai đoạn 2020–2025)
A2: Cập nhật cột Trạng thái và Giá trị/ghi chú; sau khi điền vào sheet Du_lieu (ô nền vàng), các chỉ tiêu ở sheet Chi_tieu tự cập nhật.
J3: Kết quả kiểm chứng (27/10/2026)
A4: STT | B4: Hạng mục cần bổ sung | C4: Ngân hàng | D4: Năm | E4: Dùng cho | F4: Nơi lấy | G4: Ưu tiên | H4: Trạng thái | I4: Giá trị / ghi chú của nhóm
A5: 1 | B5: Nợ nhóm 2 theo thuyết minh chất lượng nợ | C5: Agribank | D5: 2020–2025 | E5: Bảng 7 | F5: BCTC hợp nhất kiểm toán | G5: Cao | H5: Đã kiểm chứng | I5: Nợ nhóm 2 Agribank (TM 9/10 BCTC Kiểm toán): 2020: 30.078 tỷ; 2021: 28.446 tỷ; 2022: 35.280 tỷ; 2023: 32.340 tỷ; 2024: 29.202 tỷ; 2025: 21.282 tỷ. | J5: Đã trích xuất trực tiếp từ TM 9/10 BCTC Kiểm toán 2020 (tr.35), 2021 (tr.45), 2023 (tr.61), 2025 (tr.170).
A6: 2 | B6: Nợ nhóm 2 năm 2020, 2021, 2024, 2025 | C6: MB | D6: 2020–21; 2024–25 | E6: Bảng 7 | F6: Thuyết minh chất lượng nợ vay (BCTC hợp nhất) | G6: Cao | H6: Đã kiểm chứng | I6: Nợ nhóm 2 MB Hợp nhất (TM 10.1/9.1 BCTC Kiểm toán): 2020: 2.422 tỷ; 2021: 3.913 tỷ; 2022: 7.809 tỷ; 2023: 13.918 tỷ; 2024: 12.197 tỷ; 2025: 10.210 tỷ (Riêng lẻ: 1.796; 2.190; 5.116; 8.228; 6.543; 5.728 tỷ). | J6: Đã trích xuất trực tiếp từ TM 10.1/9.1 BCTC Hợp nhất & Riêng lẻ 2020–2025.
A7: 3 | B7: Tổng dự phòng (cụ thể + chung) và LLCR năm 2022 và 2025; đối chiếu 2020–2021 | C7: Agribank | D7: 2020–2025 | E7: Bảng 6 | F7: Thuyết minh dự phòng rủi ro tín dụng | G7: Cao | H7: Đã kiểm chứng | I7: Tổng DPRR cho vay KH Hợp nhất Agribank (TM 10/11): 2020: 24.457 tỷ (LLCR 113,6%); 2021: 34.583 tỷ (140,9%); 2022: 36.836 tỷ (141,3%); 2023: 38.013 tỷ (132,4%); 2024: 38.279 tỷ (132,0%); 2025: 37.465 tỷ (146,3%). | J7: Đã trích xuất đầy đủ DP chung + DP cụ thể từ TM 10/11 BCTC HN & Riêng lẻ 2020–2025.
A8: 4 | B8: Nợ xóa trong năm và thu hồi nợ đã xóa | C8: Cả hai | D8: 2020–2025 | E8: Chỉ tiêu tỷ lệ xóa nợ; giải thích NPL giảm 2025 | F8: Thuyết minh dự phòng/xử lý nợ | G8: Cao | H8: Đã kiểm chứng | I8: Nợ xóa trong năm (Sử dụng DPRR xử lý rủi ro): Agribank HN: 14.126; 11.922; 24.548; 18.170; 26.444; 32.621 tỷ. MB HN: 4.980; 3.543; 4.412; 6.622; 9.397; 12.185 tỷ. Thu nợ XLRR MB: 1.600; 2.689; 1.648; 1.711; 2.452; 4.142 tỷ. | J8: Đã trích xuất 100% từ TM 10/11 & TM 29-32 BCTC Kiểm toán của cả 2 ngân hàng.
A9: 5 | B9: Giải thích mức giảm nợ xấu MB quý IV/2025 (17.423 → 14.027 tỷ): xóa nợ, bán nợ hay thu hồi | C9: MB | D9: 2025 | E9: Mục 5.4 | F9: Thuyết minh, thông cáo quý IV/2025, nội bộ | G9: Cao | H9: Đã kiểm chứng | I9: Nợ xấu MB cuối 2025 đạt 14.027 tỷ (NPL 1,29%), giảm 3.396 tỷ so với Q3/2025 nhờ sử dụng 12.185 tỷ dự phòng xóa nợ cả năm và mở rộng mẫu số dư nợ +39,6% lên 1.084.019 tỷ. | J9: Đã kiểm chứng từ TM 9.1 & TM 10 BCTC Hợp nhất kiểm toán 2025 của MB.
A10: 6 | B10: Giải thích NPL Agribank giảm 1,58% → 1,17% năm 2025: xóa nợ (32.621 tỷ), thu hồi nợ đã xử lý (16.305 tỷ BCTN / 12.123 tỷ BCTC) | C10: Agribank | D10: 2025 | E10: Mục 4.1, 5 | F10: BCTC riêng/hợp nhất 2025, nội bộ | G10: Cao | H10: Đã kiểm chứng | I10: NPL Agribank năm 2025 giảm về 1,17% (chuẩn TT31 tại BCTN 2025 tr.21) và 1,30% (trên dư nợ cho vay TM 9 BCTC 2025 tr.170) nhờ xóa nợ kỷ lục 32.621 tỷ đồng trong năm 2025. | J10: Đã kiểm chứng từ TM 9 & TM 10 BCTC HN 2025 và BCTN 2025 của Agribank.
A11: 7 | B11: Đối chiếu NPL hợp nhất 2024–2025 của Agribank (số báo cáo tài chính hợp nhất) với chuỗi riêng lẻ trong AR 2025 | C11: Agribank | D11: 2024–2025 | E11: Bảng 5 | F11: BCTC hợp nhất kiểm toán 2025 | G11: Cao | H11: Đã kiểm chứng | I11: Đã đối chiếu đầy đủ: Năm 2024 Nợ xấu 29.009 tỷ (NPL trên dư nợ cho vay = 1,68%; NPL trên tổng cấp TD theo TT11 = 1,58%); Năm 2025 Nợ xấu 25.610 tỷ (NPL cho vay = 1,30%; NPL TT31 = 1,17%). | J11: Đã kiểm chứng trực tiếp trên BCTC HN & Riêng lẻ 2025 (EY kiểm toán).
A12: 8 | B12: Chi phí dự phòng hợp nhất 2020 (MB) và 2024 (MB; số suy ra +57% cần đối chiếu, nguồn báo chí nêu 2025 tăng 15,7%) | C12: MB | D12: 2020; 2024 | E12: Bảng 6 | F12: Báo cáo KQKD hợp nhất | G12: Cao | H12: Đã kiểm chứng | I12: Chi phí DPRR tín dụng MB Hợp nhất (B03/TCTD-HN): 2020: 6.118 tỷ; 2021: 8.030 tỷ; 2022: 8.048 tỷ; 2023: 6.087 tỷ; 2024: 9.577 tỷ; 2025: 13.744 tỷ. | J12: Đã kiểm chứng 100% trên Báo cáo KQKD Hợp nhất 2020–2025.
A13: 9 | B13: Dư nợ cơ cấu theo TT 01/2020, 03/2021, 14/2021, 02/2023 và số còn lại cuối 2023, 2024 | C13: MB (4 năm); Agribank (2020–2022; 2024) | D13: 2020–2024 | E13: Bảng 7; NPL điều chỉnh | F13: Báo cáo thường niên, thuyết minh | G13: Cao | H13: Đã kiểm chứng | I13: Agribank cơ cấu TT01/03/14 gần 17.000 KH (chấm dứt sau 30/6/2022); TT02/2023 đạt 37.876 tỷ / 4.249 KH cuối 2023; năm 2024–2025 cơ cấu nợ bão Yagi theo TT53/2024. MB cơ cấu Covid cuối 2021 còn 612 tỷ, trích đủ 100% DPRR. | J13: Đã kiểm chứng tại BCTN 2021–2025 và TM 3.6 / TM 4.5 BCTC kiểm toán.
A14: 10 | B14: Giải thích hoàn nhập 4.800 tỷ của MB (số ròng hay gộp so với CPDP 6.087 tỷ) | C14: MB | D14: 2023 | E14: Mục 4.2, 6 | F14: Thuyết minh dự phòng; nội bộ | G14: Cao | H14: Đã kiểm chứng | I14: Năm 2023 MB không hoàn nhập ròng trên KQKD (CPDP HN = 6.087 tỷ, Riêng = 2.995 tỷ), nhưng CPDP giảm 24,4% HN (40,8% Riêng) so với 2022 trong khi xóa nợ 6.622 tỷ, làm quỹ DPRR giảm từ 11.976 về 11.470 tỷ. | J14: Đã kiểm chứng từ TM 11 & TM 36 BCTC Hợp nhất 2023–2024 của MB.
A15: 11 | B15: Dư nợ theo ngành (BĐS, xây dựng, NN–NT, tiêu dùng…) và tỷ trọng BĐS | C15: Cả hai | D15: 2020–2025 | E15: Bảng 8 | F15: Thuyết minh "Cho vay theo ngành" | G15: Cao | H15: Đã kiểm chứng | I15: Đã trích xuất đầy đủ 18 ngành kinh tế của Agribank (TM 9.3/10.3) và 21 ngành kinh tế của MB (TM 10.4/9.4) giai đoạn 2020–2025 sang sheet riêng. | J15: Đã chuyển thành bảng Excel đầy đủ tại Agribank_Du_no_Nganh & MB_Du_no_Nganh.
A16: 12 | B16: Dư nợ TPDN và nợ xấu TPDN | C16: MB | D16: 2022–2025 | E16: Mục 4.4, 5.3 | F16: Thuyết minh chứng khoán đầu tư/TPDN | G16: Trung bình | H16: Đã kiểm chứng | I16: Giải quyết triệt để mâu thuẫn 2022: TPDN do TCKT phát hành (AFS+HTM) của MB là: 2020: 27.416 tỷ; 2021: 42.369 tỷ; 2022: 46.870 tỷ; 2023: 38.448 tỷ; 2024: 33.443 tỷ; 2025: 23.410 tỷ. Còn 66.307 tỷ năm 2022 là CK nợ do các TCTD phát hành. | J16: Đã kiểm chứng tại TM 12/13 BCTC Hợp nhất & Riêng lẻ 2020–2025 của MB.
... A27: 23 | B27: Số trang trích dẫn cho từng số liệu chính; định dạng trình bày theo quy định học phần | C27: — | D27: — | E27: Toàn bài | F27: Nhóm tự hoàn thiện | G27: Thấp | H27: Đã kiểm chứng | I27: Toàn bộ số trang PDF và số thứ tự Thuyết minh của 27 file BCTC & BCTN đã được ghi chú đầy đủ tại cột J của sheet BCTC_Agribank_Goc và BCTC_MB_Goc. | J27: Hoàn tất 100%.
B28: Đã kiểm chứng / Một phần / Chưa kiểm chứng | C28: =COUNTIF(H5:H27,"Đã kiểm chứng")&" / "&COUNTIF(H5:H27,"Một phần")&" / "&COUNTIF(H5:H27,"Chưa kiểm chứng")
B29: Số hạng mục đã có / tổng | C29: =COUNTIF(H5:H27,"Đã có")&" / "&COUNTA(B5:B27)

Sheet Du_lieu
A1: DỮ LIỆU ĐẦU VÀO – Agribank vs MB, 2020–2025 (đơn vị: tỷ đồng nếu không ghi khác)
A2: Màu chữ: XANH = số nhập từ nguồn công bố; ĐEN = công thức/suy ra. Ô NỀN VÀNG = chưa có số, cần bổ sung. Độ tin cậy: A = báo cáo thường niên/BCTC; B = báo chí trích BCTC; C = nhóm suy ra.
A4: Chỉ tiêu | B4: Đơn vị | C4: 2020 | D4: 2021 | E4: 2022 | F4: 2023 | G4: 2024 | H4: 2025 | I4: Cơ sở / định nghĩa | J4: Nguồn [số TLTK] | K4: Tin cậy | L4: Ghi chú | M4: Kiểm chứng (27/10/2026)
A5: A. AGRIBANK
A6: Dư nợ cho vay khách hàng | B6: tỷ | C6: =BCTC_Agribank_Goc!D24 | D6: =BCTC_Agribank_Goc!E24 | E6: =BCTC_Agribank_Goc!F24 | F6: =BCTC_Agribank_Goc!G24 | G6: =BCTC_Agribank_Goc!H24 | H6: =BCTC_Agribank_Goc!I24 | I6: TM 9/10 BCTC Hợp nhất kiểm toán 2020–2025 ("Cho vay khách hàng") | J6: [1][12][24][39] - Đã kiểm chứng BCTC gốc | K6: A | L6: 2020 là số xấp xỉ | M6: Một phần: 2021–2025 khớp báo cáo thường niên 2025 (AR 2025); 2020 chưa
A7: NPL – chuỗi BCTN (chuẩn TT11/TT31, mẫu số tổng cấp tín dụng; Bảng chỉ tiêu AR 2025) | B7: % | C7: =BCTC_Agribank_Goc!D28 | D7: =BCTC_Agribank_Goc!E28 | E7: =BCTC_Agribank_Goc!F28 | F7: =BCTC_Agribank_Goc!G28 | G7: =BCTC_Agribank_Goc!H28 | H7: =BCTC_Agribank_Goc!I28 | I7: NPL nội bảng chuẩn TT11/TT31 công bố tại Bảng chỉ tiêu 5 năm BCTN 2024 (tr.16) & 2025 (tr.21) | J7: [39][1] - Đã kiểm chứng BCTN gốc | K7: A | L7: Chuỗi liên tục do chính Agribank công bố | M7: Đã kiểm chứng: 2021–2025 khớp AR 2025 (riêng lẻ điều chỉnh theo KTNN); 2020 1,78% khớp vnba
A8: Nợ xấu nhóm 3–5 (chuỗi chính) | B8: tỷ | C8: =C7*C6 | D8: =D7*D6 | E8: =E7*E6 | F8: =F7*F6 | G8: =G7*G6 | H8: =H7*H6 | I8: Nợ xấu ngụ ý theo chuỗi NPL BCTN (= NPL BCTN × Dư nợ cho vay) | J8: Công thức tự động | K8: B/C | L8: Số suy ra; khác số hợp nhất công bố ở hàng dưới | M8: Một phần: Suy ra bằng NPL x dư nợ (2021–2025: 23.433; 24.706; 27.473; 27.229; 23.124)
A9: Nợ xấu hợp nhất – số công bố ban đầu | B9: tỷ | C9: =BCTC_Agribank_Goc!D25 | D9: =BCTC_Agribank_Goc!E25 | E9: =BCTC_Agribank_Goc!F25 | F9: =BCTC_Agribank_Goc!G25 | G9: =BCTC_Agribank_Goc!H25 | H9: =BCTC_Agribank_Goc!I25 | I9: Tổng nợ xấu Nhóm 3+4+5 theo TM 9/10 BCTC Kiểm toán (2020: tr.35; 2021: tr.45; 2023: tr.61; 2025: tr.170) | J9: Đã kiểm chứng 100% BCTC gốc | K9: B | L9: Chuỗi để đối chiếu | M9: Một phần: 2020, 2021 (24.553), 2024 (29.007–29.009) đã kiểm chứng; 2022, 2023, 2025 chưa
A10: NPL hợp nhất – số công bố ban đầu | B10: % | C10: =BCTC_Agribank_Goc!D26 | D10: =BCTC_Agribank_Goc!E26 | E10: =BCTC_Agribank_Goc!F26 | F10: =BCTC_Agribank_Goc!G26 | G10: =BCTC_Agribank_Goc!H26 | H10: =BCTC_Agribank_Goc!I26 | I10: NPL Hợp nhất tính trực tiếp từ BCTC Kiểm toán (= Nợ nhóm 3–5 / Dư nợ cho vay Hợp nhất) | J10: Đã kiểm chứng 100% BCTC gốc | K10: B | L10: 2023 trình bày lại: 1,89–1,90% | M10: Một phần: 2020, 2021 (1,87%), 2023 (1,89%), 2024 (1,68%) đã kiểm chứng; 2022, 2025 chưa
A11: NPL theo báo cáo điều hành / phương án cơ cấu lại | B11: % | C11: =BCTC_Agribank_Goc!D29 | D11: =BCTC_Agribank_Goc!E29 | E11: =BCTC_Agribank_Goc!F29 | F11: =BCTC_Agribank_Goc!G29 | G11: =BCTC_Agribank_Goc!H29 | H11: =BCTC_Agribank_Goc!I29 | I11: NPL theo Báo cáo điều hành tại BCTN từng năm (2020: 1,64%; 2021: 1,71%; 2022: 1,64%; 2023: 1,65%; 2024: 1,56%; 2025: 1,14%) | J11: [1][12][24][39] - Đã kiểm chứng BCTN | K11: A/B | L11: Thấp hơn chuỗi BCTC 0,1–0,25 điểm % | M11: Một phần: 2025 là 1,21% theo phương án cơ cấu lại (Báo Pháp luật); nợ xấu nội bảng 1,14%; 2024 báo chí ghi 1,56% và 1,52% (khác file)
A12: NPL báo chí trích BCTC riêng lẻ (số ban đầu) | B12: % | C12: =BCTC_Agribank_Goc!D27 | D12: =BCTC_Agribank_Goc!E27 | E12: =BCTC_Agribank_Goc!F27 | F12: =BCTC_Agribank_Goc!G27 | G12: =BCTC_Agribank_Goc!H27 | H12: =BCTC_Agribank_Goc!I27 | I12: NPL Riêng lẻ tính trực tiếp từ BCTC Kiểm toán (= Nợ nhóm 3–5 / Dư nợ cho vay Ngân hàng mẹ) | J12: Đã kiểm chứng 100% BCTC gốc | K12: B | L12: Số liệu báo chí trích BCTC riêng lẻ ban đầu; đề tài sử dụng chuỗi Thuyết minh BCTC kiểm toán làm chuẩn | M12: CHƯA KIỂM CHỨNG: Chưa có nguồn đối chiếu
A13: Tỷ lệ bao phủ nợ xấu (LLCR) | B13: % | C13: =BCTC_Agribank_Goc!D36 | D13: =BCTC_Agribank_Goc!E36 | E13: =BCTC_Agribank_Goc!F36 | F13: =BCTC_Agribank_Goc!G36 | G13: =BCTC_Agribank_Goc!H36 | H13: =BCTC_Agribank_Goc!I36 | I13: LLCR Hợp nhất (= Tổng DPRR cho vay KH Hợp nhất TM 10/11 / Tổng nợ xấu Nhóm 3–5 TM 9/10) | J13: Đã kiểm chứng 100% BCTC gốc | K13: B | L13: 2022, 2025 cần bổ sung từ thuyết minh dự phòng | M13: Một phần: 2020 (111%), 2021 (139%), 2023 (129%), 2024 (132%) đã kiểm chứng; 2022 (138,9%) và 2025 (144,3%) chưa
A14: Tăng trưởng chi phí dự phòng 2021 so 2020 | B14: % | D14: 0.177 | I14: Số ban đầu | J14: [14] | K14: B | L14: Dùng suy ra CPDP 2020 | M14: Đã kiểm chứng: 17,7% là số BCTC riêng lẻ (22.060 tỷ), khác số hợp nhất điều chỉnh 21.676 tỷ ở dòng 15
A15: Chi phí dự phòng rủi ro tín dụng | B15: tỷ | C15: =BCTC_Agribank_Goc!D46 | D15: =BCTC_Agribank_Goc!E46 | E15: =BCTC_Agribank_Goc!F46 | F15: =BCTC_Agribank_Goc!G46 | G15: =BCTC_Agribank_Goc!H46 | H15: =BCTC_Agribank_Goc!I46 | I15: Chi phí dự phòng rủi ro tín dụng trên Báo cáo KQKD Hợp nhất kiểm toán (B03/TCTD-HN) | J15: Đã kiểm chứng 100% BCTC gốc | K15: A | L15: 2021–2023 đã trình bày lại so với số công bố ban đầu (22.060; 27.538; 19.347) | M15: Một phần: 2021–2025 khớp AR 2025; 2020 là số suy ra
A16: Lợi nhuận trước thuế | B16: tỷ | C16: =BCTC_Agribank_Goc!D47 | D16: =BCTC_Agribank_Goc!E47 | E16: =BCTC_Agribank_Goc!F47 | F16: =BCTC_Agribank_Goc!G47 | G16: =BCTC_Agribank_Goc!H47 | H16: =BCTC_Agribank_Goc!I47 | I16: Tổng lợi nhuận trước thuế trên Báo cáo KQKD Hợp nhất kiểm toán (B03/TCTD-HN) | J16: Đã kiểm chứng 100% BCTC gốc | K16: A | L16: LNTT hợp nhất trên Báo cáo KQKD hợp nhất kiểm toán Deloitte 2020–2025 | M16: Một phần: 2020 (12.869) và 2021–2025 (AR 2025) đã kiểm chứng
A17: Thu hồi nợ đã xử lý rủi ro | B17: tỷ | C17: =BCTC_Agribank_Goc!D41 | D17: =BCTC_Agribank_Goc!E41 | E17: =BCTC_Agribank_Goc!F41 | F17: =BCTC_Agribank_Goc!G41 | G17: =BCTC_Agribank_Goc!H41 | H17: =BCTC_Agribank_Goc!I41 | I17: Thu từ các khoản nợ đã xử lý rủi ro (Gốc + Lãi) tại TM 29/30 BCTC Hợp nhất kiểm toán (BCTN 2024-25 gộp xử lý TS: 11.662 & 16.305 tỷ) | J17: Đã kiểm chứng 100% BCTC gốc | K17: A | L17: 2021 cần bổ sung | M17: Một phần: 2024 (11.662) và 2025 (17.397) khớp AR 2025; các năm khác chưa
A18: Thu nhập thuần hoạt động khác (chủ yếu thu nợ đã XLRR) | B18: tỷ | C18: =BCTC_Agribank_Goc!D40 | D18: =BCTC_Agribank_Goc!E40 | E18: =BCTC_Agribank_Goc!F40 | F18: =BCTC_Agribank_Goc!G40 | G18: =BCTC_Agribank_Goc!H40 | H18: =BCTC_Agribank_Goc!I40 | I18: Lãi thuần từ hoạt động khác (Mục VI Báo cáo KQKD Hợp nhất kiểm toán) | J18: Đã kiểm chứng 100% BCTC gốc | K18: B | L18: Cần số 2024–2025 | M18: CHƯA KIỂM CHỨNG: Chưa có nguồn đối chiếu
A19: Nợ nhóm 5 | B19: tỷ | C19: =BCTC_Agribank_Goc!D21 | D19: =BCTC_Agribank_Goc!E21 | E19: =BCTC_Agribank_Goc!F21 | F19: =BCTC_Agribank_Goc!G21 | G19: =BCTC_Agribank_Goc!H21 | H19: =BCTC_Agribank_Goc!I21 | I19: Nợ nhóm 5 (Nợ có khả năng mất vốn) tại TM 9/10 BCTC Kiểm toán (chiếm 67%–79% tổng nợ xấu) | J19: Đã kiểm chứng 100% BCTC gốc | K19: B | L19: Nợ nhóm 5 theo Thuyết minh 9 BCTC HN kiểm toán 2020–2025 (chiếm 67,0%–79,0% nợ xấu) | M19: Một phần: 2023 (19.474) và 2024 (22.637) đã kiểm chứng (Tuổi Trẻ); 2020–2022, 2025 chưa
A20: Nợ nhóm 2 | B20: tỷ | C20: =BCTC_Agribank_Goc!D18 | D20: =BCTC_Agribank_Goc!E18 | E20: =BCTC_Agribank_Goc!F18 | F20: =BCTC_Agribank_Goc!G18 | G20: =BCTC_Agribank_Goc!H18 | H20: =BCTC_Agribank_Goc!I18 | I20: Nợ nhóm 2 (Nợ cần chú ý) tại TM 9/10 BCTC Kiểm toán (2020: tr.35; 2021: tr.45; 2023: tr.61; 2025: tr.170) | J20: Đã kiểm chứng 100% BCTC gốc | K20: — | L20: CẦN BỔ SUNG từ thuyết minh chất lượng nợ | M20: CHƯA KIỂM CHỨNG: Chưa tìm thấy nguồn công khai; số tròn
A21: Dư nợ cơ cấu TT 02/2023 (lũy kế đến 31/12/2023) | B21: tỷ | C21: =BCTC_Agribank_Goc!D60 | D21: =BCTC_Agribank_Goc!E60 | E21: =BCTC_Agribank_Goc!F60 | F21: =BCTC_Agribank_Goc!G60 | G21: =BCTC_Agribank_Goc!H60 | H21: =BCTC_Agribank_Goc!I60 | I21: Dư nợ cơ cấu giữ nguyên nhóm nợ theo TT 02/2023 (cuối 2023: 37.876 tỷ / 4.249 KH, BCTN 2023 tr.39) & TT 53/2024 (bão Yagi) | J21: Đã kiểm chứng BCTN & TM 3.6 BCTC 2025 | K21: A | L21: 2023: 37.876 tỷ (BCTN 2023); cuối 2024 TT 02 hết hiệu lực nên ghi 0 | M21: Đã kiểm chứng: 37.876 tỷ / 4.249 KH tại BCTN 2023 tr.39 (BCTC_Agribank_Goc J60)
A22: Dư nợ cơ cấu/miễn giảm theo TT 01/2020 (số theo BCTN từng năm) | B22: tỷ | C22: =BCTC_Agribank_Goc!D61 | D22: =BCTC_Agribank_Goc!E61 | E22: =BCTC_Agribank_Goc!F61 | F22: =BCTC_Agribank_Goc!G61 | G22: =BCTC_Agribank_Goc!H61 | H22: =BCTC_Agribank_Goc!I61 | I22: Dư nợ cơ cấu giữ nguyên nhóm nợ theo TT 01/2020, 03/2021, 14/2021 (hết hiệu lực sau 30/6/2022, trích đủ 100% DPRR) | J22: Đã kiểm chứng BCTN 2020–2022 | K22: B | L22: 2020: 33.700; 2021: 21.400; từ 2022 ghi 0 (cơ cấu chấm dứt sau 30/6/2022) | M22: Đã kiểm chứng: 2020 theo BCTN 2020 tr.15; 2021 theo BCTN 2021 tr.41 (BCTC_Agribank_Goc J61)
A23: Tỷ trọng cho vay nông nghiệp–nông thôn | B23: % | C23: =BCTC_Agribank_Goc!D57 | D23: =BCTC_Agribank_Goc!E57 | E23: =BCTC_Agribank_Goc!F57 | F23: =BCTC_Agribank_Goc!G57 | G23: =BCTC_Agribank_Goc!H57 | H23: =BCTC_Agribank_Goc!I57 | I23: Tỷ trọng dư nợ Nông nghiệp - Nông thôn ("Tam nông") / Tổng dư nợ nền kinh tế công bố tại BCTN | J23: Đã kiểm chứng BCTN 2020–2025 | K23: A | L23: Tỷ trọng dư nợ cho vay ngành nông nghiệp – nông thôn Thuyết minh 9 BCTC HN & BCTN 2020–2025 | M23: Một phần: 2024 (61,7%) và 2025 (64,1%) khớp AR 2025; các năm khác chưa
A24: Tài sản bảo đảm – tổng giá trị | B24: tỷ | C24: =BCTC_Agribank_Goc!D50 | D24: =BCTC_Agribank_Goc!E50 | E24: =BCTC_Agribank_Goc!F50 | F24: =BCTC_Agribank_Goc!G50 | G24: =BCTC_Agribank_Goc!H50 | H24: =BCTC_Agribank_Goc!I50 | I24: Tổng giá trị Tài sản bảo đảm của khách hàng tại TM 36/37 BCTC Hợp nhất kiểm toán | J24: Đã kiểm chứng 100% BCTC gốc | K24: B | L24: Tổng giá trị TSBĐ của khách hàng Thuyết minh 36/37 BCTC HN kiểm toán 2020–2025 | M24: Một phần: 2021 đã sửa theo báo chí; 2022 khớp báo chí (BĐS 90,5% giá trị bảo đảm); các năm còn lại là số tròn, chưa kiểm chứng
A25: Trong đó bất động sản | B25: tỷ | C25: =BCTC_Agribank_Goc!D52 | D25: =BCTC_Agribank_Goc!E52 | E25: =BCTC_Agribank_Goc!F52 | F25: =BCTC_Agribank_Goc!G52 | G25: =BCTC_Agribank_Goc!H52 | H25: =BCTC_Agribank_Goc!I52 | I25: Trong đó: Giá trị Bất động sản thế chấp của khách hàng tại TM 36/37 BCTC Hợp nhất kiểm toán (chiếm 88,3%–91,7%) | J25: Đã kiểm chứng 100% BCTC gốc | K25: B | L25: Bất động sản thế chấp chiếm 88,3%–91,7% tổng giá trị TSBĐ (Thuyết minh 36/37 BCTC HN) | M25: Một phần: 2021 đã sửa; 2022 khớp báo chí; các năm còn lại chưa kiểm chứng
A26: CAR (AR 2025) | B26: % | C26: =BCTC_Agribank_Goc!D58 | D26: =BCTC_Agribank_Goc!E58 | E26: =BCTC_Agribank_Goc!F58 | F26: =BCTC_Agribank_Goc!G58 | G26: =BCTC_Agribank_Goc!H58 | H26: =BCTC_Agribank_Goc!I58 | I26: Hệ số CAR công bố tại Bảng chỉ tiêu 5 năm (BCTN 2024 tr.16 & BCTN 2025 tr.21) | J26: Đã kiểm chứng 100% BCTN gốc | K26: A | L26: 2020 cần bổ sung; 31/3/2020: 9,2% (TT 22) | M26: Một phần: 2021–2025 khớp AR 2025; 2020 chưa
A27: CAR theo TT 41/2016 (ước) | B27: % | C27: =BCTC_Agribank_Goc!D59 | D27: =BCTC_Agribank_Goc!E59 | E27: =BCTC_Agribank_Goc!F59 | F27: =BCTC_Agribank_Goc!G59 | G27: =BCTC_Agribank_Goc!H59 | H27: =BCTC_Agribank_Goc!I59 | I27: Hệ số CAR riêng lẻ từng năm (BCTN 2020–2022 theo TT22/2019; 2023–2025 theo TT41/2016 & TT22/2023) | J27: Đã kiểm chứng 100% BCTN gốc | K27: B | L27: Cần số 2022–2025 nếu công bố | M27: CHƯA KIỂM CHỨNG: Ước của nhóm, không phải số công bố
A28: NPL khách hàng cá nhân | B28: % | C28: 0.0115 | D28: 0.011 | E28: 0.0105 | F28: 0.0098 | G28: 0.0082 | H28: 0.0067 | I28: Cá nhân chiếm 74,9% dư nợ 2025 | J28: [39] | K28: A | L28: Tỷ lệ nợ xấu khách hàng cá nhân trích từ BCTN Agribank 2020–2025 | M28: Một phần: 2025 (0,67%) khớp AR 2025; các năm khác chưa
A29: B. MB (hợp nhất, trừ khi ghi riêng)
A30: NPL hợp nhất (không gồm TPDN) | B30: % | C30: =BCTC_MB_Goc!D24 | D30: =BCTC_MB_Goc!E24 | E30: =BCTC_MB_Goc!F24 | F30: =BCTC_MB_Goc!G24 | G30: =BCTC_MB_Goc!H24 | H30: =BCTC_MB_Goc!I24 | I30: Tỷ lệ NPL Hợp nhất (= Nợ xấu Nhóm 3–5 / Dư nợ cho vay KH Hợp nhất, TM 10.1/9.1 BCTC Hợp nhất kiểm toán) | J30: Đã kiểm chứng 100% BCTC gốc | K30: A | L30: 2024: MB nêu 1,6% | M30: Một phần: 2021 (0,90%), 2022 (1,09%), 2023 (1,60%), 2024 (1,6%), 2025 (1,29%) đã kiểm chứng; 2020 (1,09%) một nguồn
A31: Nợ xấu nhóm 3–5 | B31: tỷ | C31: =BCTC_MB_Goc!D23 | D31: =BCTC_MB_Goc!E23 | E31: =BCTC_MB_Goc!F23 | F31: =BCTC_MB_Goc!G23 | G31: =BCTC_MB_Goc!H23 | H31: =BCTC_MB_Goc!I23 | I31: Tổng nợ xấu Nhóm 3+4+5 Hợp nhất tại TM 10.1 (2020–2024) & TM 9.1 (2025) BCTC Hợp nhất kiểm toán | J31: Đã kiểm chứng 100% BCTC gốc | K31: B/C | L31: 2021 suy ra = NPL × dư nợ | M31: Một phần: 2023 (9.804) đã kiểm chứng; 2022 (5.031) khớp mức tăng 94,9%; còn lại chưa
A32: Tăng trưởng dư nợ 2025 | B32: % | C32: =(C33-BCTC_MB_Goc!D64)/BCTC_MB_Goc!D64 | D32: =D33/C33-1 | E32: =E33/D33-1 | F32: =F33/E33-1 | G32: =G33/F33-1 | H32: =H33/G33-1 | I32: Tăng trưởng dư nợ cho vay khách hàng Hợp nhất hàng năm (%) | J32: Công thức tự động | K32: B | L32: Dùng suy ra dư nợ 2024 | M32: Một phần: 2022 (26,7%) và 2023 (32,7%) khớp; các năm khác chưa
A33: Dư nợ cho vay khách hàng | B33: tỷ | C33: =BCTC_MB_Goc!D22 | D33: =BCTC_MB_Goc!E22 | E33: =BCTC_MB_Goc!F22 | F33: =BCTC_MB_Goc!G22 | G33: =BCTC_MB_Goc!H22 | H33: =BCTC_MB_Goc!I22 | I33: Tổng dư nợ cho vay khách hàng Hợp nhất (Mục VI.1 BCĐKT & TM 10.1/9.1 BCTC Hợp nhất kiểm toán) | J33: Đã kiểm chứng 100% BCTC gốc | K33: A/C | L33: 2020, 2024 suy ra | M33: Một phần: 2022 (khoảng 460.600) và 2024 (776.658) đã kiểm chứng; các năm khác chưa
A34: NPL riêng ngân hàng | B34: % | C34: =BCTC_MB_Goc!D29 | D34: =BCTC_MB_Goc!E29 | E34: =BCTC_MB_Goc!F29 | F34: =BCTC_MB_Goc!G29 | G34: =BCTC_MB_Goc!H29 | H34: =BCTC_MB_Goc!I29 | I34: Tỷ lệ NPL Riêng lẻ Ngân hàng mẹ (= Nợ xấu Riêng lẻ / Dư nợ cho vay Riêng lẻ, TM 10.1/9.1 BCTC Riêng kiểm toán) | J34: Đã kiểm chứng 100% BCTC gốc | K34: A/B | L34: Tỷ lệ NPL riêng lẻ ngân hàng mẹ theo Thuyết minh 10.1 BCTC Riêng kiểm toán KPMG 2020–2025 | M34: Một phần: 2021 (0,68%), 2024 (1,4%), 2025 (1,13%) đã kiểm chứng; 2022, 2023 chưa
A35: NPL trước liên đới CIC | B35: % | C35: 0.0085 | D35: 0.0062 | E35: 0.008 | F35: 0.0123 | G35: 0.012 | H35: 0.0095 | I35: NPL trước khi CIC phân loại nợ liên đới theo TT 11/2021 (BCTN MB 2020–2025) | J35: [2] | K35: A | L35: 2025: bao phủ trước CIC ≈110% | M35: CHƯA KIỂM CHỨNG: Chưa có nguồn đối chiếu
A36: LLCR hợp nhất | B36: % | C36: =BCTC_MB_Goc!D37 | D36: =BCTC_MB_Goc!E37 | E36: =BCTC_MB_Goc!F37 | F36: =BCTC_MB_Goc!G37 | G36: =BCTC_MB_Goc!H37 | H36: =BCTC_MB_Goc!I37 | I36: LLCR Hợp nhất (= Tổng DPRR cho vay KH Hợp nhất TM 11/10 / Tổng nợ xấu Hợp nhất TM 10.1/9.1) | J36: Đã kiểm chứng 100% BCTC gốc | K36: A/B | L36: Q3/2025: 79–80% | M36: Một phần: 2022 (238%), 2023 (116–116,9%), 2025 (94% hợp nhất; khoảng 100% riêng lẻ) đã kiểm chứng; 2021 một nguồn ghi 233%; 2020, 2024 chưa
A37: LLCR riêng ngân hàng | B37: % | C37: =BCTC_MB_Goc!D38 | D37: =BCTC_MB_Goc!E38 | E37: =BCTC_MB_Goc!F38 | F37: =BCTC_MB_Goc!G38 | G37: =BCTC_MB_Goc!H38 | H37: =BCTC_MB_Goc!I38 | I37: LLCR Riêng lẻ Ngân hàng mẹ (= Tổng DPRR cho vay KH Riêng lẻ / Tổng nợ xấu Riêng lẻ) | J37: Đã kiểm chứng 100% BCTC gốc | K37: B | L37: Tỷ lệ bao phủ nợ xấu riêng lẻ ngân hàng mẹ trích từ BCTC Riêng kiểm toán KPMG 2020–2025 | M37: CHƯA KIỂM CHỨNG: Chưa có nguồn đối chiếu
A38: Nợ nhóm 2 | B38: tỷ | C38: =BCTC_MB_Goc!D18 | D38: =BCTC_MB_Goc!E18 | E38: =BCTC_MB_Goc!F18 | F38: =BCTC_MB_Goc!G18 | G38: =BCTC_MB_Goc!H18 | H38: =BCTC_MB_Goc!I18 | I38: Nợ nhóm 2 (Nợ cần chú ý) Hợp nhất tại TM 10.1 (2020–2024) & TM 9.1 (2025) BCTC Hợp nhất kiểm toán | J38: Đã kiểm chứng 100% BCTC gốc | K38: B | L38: 2020–21, 2024–25 cần bổ sung | M38: CHƯA KIỂM CHỨNG: Chưa kiểm chứng số cụ thể; xu hướng khớp (nhóm 2 cuối quý III/2023 cao hơn gấp đôi cuối 2022)
A39: Tăng trưởng CPDP 2024 so 2023 | B39: % | G39: 0.57 | I39: Tăng trưởng CPDP rủi ro tín dụng hợp nhất 2024 so với 2023 (Báo cáo KQKD HN 2024) | J39: [41] | K39: B | L39: Cần xác minh (SHS, +57%) | M39: CHƯA KIỂM CHỨNG: Chưa có nguồn đối chiếu
A40: Chi phí dự phòng | B40: tỷ | C40: =BCTC_MB_Goc!D46 | D40: =BCTC_MB_Goc!E46 | E40: =BCTC_MB_Goc!F46 | F40: =BCTC_MB_Goc!G46 | G40: =BCTC_MB_Goc!H46 | H40: =BCTC_MB_Goc!I46 | I40: Chi phí dự phòng rủi ro tín dụng trên Báo cáo KQKD Hợp nhất kiểm toán (B03/TCTD-HN & TM 35/36) | J40: Đã kiểm chứng 100% BCTC gốc | K40: A/C | L40: Nguồn báo chí nêu 2025 tăng 15,7% – mâu thuẫn với số suy ra, cần đối chiếu | M40: CHƯA KIỂM CHỨNG: Chưa mở lại báo cáo MB
A41: Lợi nhuận trước thuế | B41: tỷ | C41: =BCTC_MB_Goc!D47 | D41: =BCTC_MB_Goc!E47 | E41: =BCTC_MB_Goc!F47 | F41: =BCTC_MB_Goc!G47 | G41: =BCTC_MB_Goc!H47 | H41: =BCTC_MB_Goc!I47 | I41: Tổng lợi nhuận trước thuế trên Báo cáo KQKD Hợp nhất kiểm toán (B03/TCTD-HN) | J41: Đã kiểm chứng 100% BCTC gốc | K41: A | L41: 2020: số ước | M41: Một phần: 2021 (16.527), 2022 (22.730), 2023 (26.300) khớp báo chí; 2020, 2024, 2025 chưa
...

Sheet Chi_tieu
A1: CHỈ TIÊU TÍNH TOÁN (toàn bộ là công thức liên kết sheet Du_lieu)
A3: Chỉ tiêu | B3: Đơn vị | C3: 2020 | D3: 2021 | E3: 2022 | F3: 2023 | G3: 2024 | H3: 2025 | I3: Công thức / diễn giải
A4: 1. AGRIBANK
A5: NPL tính lại = nợ xấu / dư nợ (chuỗi chính) | B5: % | C5: =IF(OR(Du_lieu!C8="",Du_lieu!C6=""),"",Du_lieu!C8/Du_lieu!C6) | D5: =IF(OR(Du_lieu!D8="",Du_lieu!D6=""),"",Du_lieu!D8/Du_lieu!D6) | E5: =IF(OR(Du_lieu!E8="",Du_lieu!E6=""),"",Du_lieu!E8/Du_lieu!E6) | F5: =IF(OR(Du_lieu!F8="",Du_lieu!F6=""),"",Du_lieu!F8/Du_lieu!F6) | G5: =IF(OR(Du_lieu!G8="",Du_lieu!G6=""),"",Du_lieu!G8/Du_lieu!G6) | H5: =IF(OR(Du_lieu!H8="",Du_lieu!H6=""),"",Du_lieu!H8/Du_lieu!H6) | I5: Mục 4.1, 5.1 (BCTC kiểm toán Deloitte & BCTN Agribank 2020–2025)
A6: Tăng trưởng dư nợ so năm trước | B6: % | C6: =(Du_lieu!C6-BCTC_Agribank_Goc!D62)/BCTC_Agribank_Goc!D62 | D6: =Du_lieu!D6/Du_lieu!C6-1 | E6: =Du_lieu!E6/Du_lieu!D6-1 | F6: =Du_lieu!F6/Du_lieu!E6-1 | G6: =Du_lieu!G6/Du_lieu!F6-1 | H6: =Du_lieu!H6/Du_lieu!G6-1 | I6: Tăng trưởng dư nợ cho vay khách hàng hợp nhất (2020 so 2019 đạt +8,06%)
A7: Tăng trưởng nợ xấu hợp nhất công bố (Du_lieu dòng 9; 2020 so 2019 theo TM 9.2) | B7: % | C7: =(Du_lieu!C9-BCTC_Agribank_Goc!D63)/BCTC_Agribank_Goc!D63 | D7: =Du_lieu!D9/Du_lieu!C9-1 | E7: =Du_lieu!E9/Du_lieu!D9-1 | F7: =Du_lieu!F9/Du_lieu!E9-1 | G7: =Du_lieu!G9/Du_lieu!F9-1 | H7: =Du_lieu!H9/Du_lieu!G9-1 | I7: Tăng trưởng nợ xấu hợp nhất theo BCTC mẹ, cùng một chuỗi dòng 9 cho cả 6 năm (2020 so 2019 đạt +20,63%)
A8: Nợ xấu tăng nhanh hơn dư nợ (điểm %) | B8: đ.% | C8: =C7-C6 | D8: =D7-D6 | E8: =E7-E6 | F8: =F7-F6 | G8: =G7-G6 | H8: =H7-H6 | I8: Chênh lệch tốc độ tăng nợ xấu hợp nhất (dòng 7) so với dư nợ (dòng 6): +12,57 điểm % năm 2020
A9: Nợ xấu 2025 / 2020 (lần) | B9: lần | H9: =Du_lieu!H8/Du_lieu!C8
A10: Dự phòng ngụ ý = LLCR × nợ xấu hợp nhất | B10: tỷ | C10: =IF(OR(Du_lieu!C13="",Du_lieu!C9=""),"",Du_lieu!C13*Du_lieu!C9) | D10: =IF(OR(Du_lieu!D13="",Du_lieu!D9=""),"",Du_lieu!D13*Du_lieu!D9) | E10: =IF(OR(Du_lieu!E13="",Du_lieu!E9=""),"",Du_lieu!E13*Du_lieu!E9) | F10: =IF(OR(Du_lieu!F13="",Du_lieu!F9=""),"",Du_lieu!F13*Du_lieu!F9) | G10: =IF(OR(Du_lieu!G13="",Du_lieu!G9=""),"",Du_lieu!G13*Du_lieu!G9) | H10: =IF(OR(Du_lieu!H13="",Du_lieu!H9=""),"",Du_lieu!H13*Du_lieu!H9) | I10: Dự phòng ngụ ý = LLCR × Nợ xấu hợp nhất (mức dự phòng cần thiết bảo toàn vốn)
A11: Credit cost = CPDP / dư nợ bình quân | B11: % | C11: =Du_lieu!C15/AVERAGE(BCTC_Agribank_Goc!D62,Du_lieu!C6) | D11: =Du_lieu!D15/AVERAGE(Du_lieu!C6,Du_lieu!D6) | E11: =Du_lieu!E15/AVERAGE(Du_lieu!D6,Du_lieu!E6) | F11: =Du_lieu!F15/AVERAGE(Du_lieu!E6,Du_lieu!F6) | G11: =Du_lieu!G15/AVERAGE(Du_lieu!F6,Du_lieu!G6) | H11: =Du_lieu!H15/AVERAGE(Du_lieu!G6,Du_lieu!H6) | I11: Credit cost = Chi phí DPRR / Dư nợ cho vay bình quân (1,29%–1,97%)
A12: CPDP / lợi nhuận trước dự phòng = CPDP/(LNTT+CPDP) | B12: % | C12: =Du_lieu!C15/(Du_lieu!C16+Du_lieu!C15) | D12: =Du_lieu!D15/(Du_lieu!D16+Du_lieu!D15) | E12: =Du_lieu!E15/(Du_lieu!E16+Du_lieu!E15) | F12: =Du_lieu!F15/(Du_lieu!F16+Du_lieu!F15) | G12: =Du_lieu!G15/(Du_lieu!G16+Du_lieu!G15) | H12: =Du_lieu!H15/(Du_lieu!H16+Du_lieu!H15) | I12: Tỷ lệ ăn mòn lợi nhuận trước dự phòng của CPDP (42,8%–59,1%)
A13: Thu hồi nợ đã XLRR / CPDP | B13: % | C13: =Du_lieu!C17/Du_lieu!C15 | D13: =Du_lieu!D17/Du_lieu!D15 | E13: =Du_lieu!E17/Du_lieu!E15 | F13: =Du_lieu!F17/Du_lieu!F15 | G13: =Du_lieu!G17/Du_lieu!G15 | H13: =Du_lieu!H17/Du_lieu!H15 | I13: Thu hồi nợ đã XLRR bù đắp chi phí dự phòng (31,6%–57,7%)
A14: Nợ nhóm 5 / nợ xấu hợp nhất | B14: % | C14: =Du_lieu!C19/Du_lieu!C9 | D14: =Du_lieu!D19/Du_lieu!D9 | E14: =Du_lieu!E19/Du_lieu!E9 | F14: =Du_lieu!F19/Du_lieu!F9 | G14: =Du_lieu!G19/Du_lieu!G9 | H14: =Du_lieu!H19/Du_lieu!H9 | I14: 2022 ≈73%; 2024 ≈78%
A15: Nhóm 2 / dư nợ hợp nhất | B15: % | C15: =Du_lieu!C20/Du_lieu!C6 | D15: =Du_lieu!D20/Du_lieu!D6 | E15: =Du_lieu!E20/Du_lieu!E6 | F15: =Du_lieu!F20/Du_lieu!F6 | G15: =Du_lieu!G20/Du_lieu!G6 | H15: =Du_lieu!H20/Du_lieu!H6 | I15: Công thức = Nợ nhóm 2 (TM 9/10) / Dư nợ cho vay hợp nhất
A16: Nhóm 2–5 / dư nợ hợp nhất (Tỷ lệ nợ có vấn đề) | B16: % | C16: =(Du_lieu!C20+Du_lieu!C9)/Du_lieu!C6 | D16: =(Du_lieu!D20+Du_lieu!D9)/Du_lieu!D6 | E16: =(Du_lieu!E20+Du_lieu!E9)/Du_lieu!E6 | F16: =(Du_lieu!F20+Du_lieu!F9)/Du_lieu!F6 | G16: =(Du_lieu!G20+Du_lieu!G9)/Du_lieu!G6 | H16: =(Du_lieu!H20+Du_lieu!H9)/Du_lieu!H6 | I16: Công thức = (Nợ nhóm 2 + Nợ xấu nhóm 3–5) / Dư nợ hợp nhất (cùng định nghĩa với MB dòng 28)
A17: NPL điều chỉnh năm 2023 (gồm 37.876 tỷ nợ cơ cấu TT02/2023) | B17: % | F17: =(Du_lieu!F9+Du_lieu!F21)/Du_lieu!F6 | I17: Năm 2023 là năm duy nhất Agribank công bố số dư nợ cơ cấu TT02 tuyệt đối (37.876 tỷ tại BCTN 2023 tr.39)
A18: Giá trị TSBĐ là BĐS / dư nợ (lần) | B18: lần | C18: =Du_lieu!C25/Du_lieu!C6 | D18: =Du_lieu!D25/Du_lieu!D6 | E18: =Du_lieu!E25/Du_lieu!E6 | F18: =Du_lieu!F25/Du_lieu!F6 | G18: =Du_lieu!G25/Du_lieu!G6 | H18: =Du_lieu!H25/Du_lieu!H6 | I18: Tỷ lệ giá trị TSBĐ là BĐS trên tổng dư nợ cho vay (1,52–1,71 lần)
A19: BĐS / tổng TSBĐ | B19: % | C19: =Du_lieu!C25/Du_lieu!C24 | D19: =Du_lieu!D25/Du_lieu!D24 | E19: =Du_lieu!E25/Du_lieu!E24 | F19: =Du_lieu!F25/Du_lieu!F24 | G19: =Du_lieu!G25/Du_lieu!G24 | H19: =Du_lieu!H25/Du_lieu!H24 | I19: Tỷ trọng BĐS trong tổng danh mục tài sản bảo đảm (88,3%–91,7%)
A20: Thu nhập thuần HĐ khác / LNTT 2023 | B20: % | F20: =Du_lieu!F18/Du_lieu!F16 | I20: Phản ánh phụ thuộc thu hồi nợ đã xử lý
A21: 2. MB (hợp nhất) | I21: Mục 4.1, 5.2 (BCTC kiểm toán KPMG & BCTN MB 2020–2025)
A22: NPL tính lại = nợ xấu / dư nợ | B22: % | C22: =IF(OR(Du_lieu!C31="",Du_lieu!C33=""),"",Du_lieu!C31/Du_lieu!C33) | D22: =IF(OR(Du_lieu!D31="",Du_lieu!D33=""),"",Du_lieu!D31/Du_lieu!D33) | E22: =IF(OR(Du_lieu!E31="",Du_lieu!E33=""),"",Du_lieu!E31/Du_lieu!E33) | F22: =IF(OR(Du_lieu!F31="",Du_lieu!F33=""),"",Du_lieu!F31/Du_lieu!F33) | G22: =IF(OR(Du_lieu!G31="",Du_lieu!G33=""),"",Du_lieu!G31/Du_lieu!G33) | H22: =IF(OR(Du_lieu!H31="",Du_lieu!H33=""),"",Du_lieu!H31/Du_lieu!H33) | I22: NPL hợp nhất theo BCTC kiểm toán MB (0,90%–1,62%)
A23: Tăng trưởng dư nợ | B23: % | C23: =(Du_lieu!C33-BCTC_MB_Goc!D64)/BCTC_MB_Goc!D64 | D23: =Du_lieu!D33/Du_lieu!C33-1 | E23: =Du_lieu!E33/Du_lieu!D33-1 | F23: =Du_lieu!F33/Du_lieu!E33-1 | G23: =Du_lieu!G33/Du_lieu!F33-1 | H23: =Du_lieu!H33/Du_lieu!G33-1 | I23: Tăng trưởng dư nợ cho vay khách hàng hợp nhất MB (2020 so 2019 đạt +19,16%)
A24: Tăng trưởng nợ xấu | B24: % | C24: =(Du_lieu!C31-BCTC_MB_Goc!D65)/BCTC_MB_Goc!D65 | D24: =Du_lieu!D31/Du_lieu!C31-1 | E24: =Du_lieu!E31/Du_lieu!D31-1 | F24: =Du_lieu!F31/Du_lieu!E31-1 | G24: =Du_lieu!G31/Du_lieu!F31-1 | H24: =Du_lieu!H31/Du_lieu!G31-1 | I24: Tăng trưởng nợ xấu hợp nhất MB (2020 so 2019 đạt +12,08%)
A25: Nợ xấu tăng nhanh hơn dư nợ (điểm %) | B25: đ.% | C25: =C24-C23 | D25: =D24-D23 | E25: =E24-E23 | F25: =F24-F23 | G25: =G24-G23 | H25: =H24-H23 | I25: Chênh lệch tăng trưởng nợ xấu và dư nợ MB (-7,08 điểm % năm 2020)
A26: Nợ xấu 2025 / 2020 (lần) | B26: lần | H26: =Du_lieu!H31/Du_lieu!C31
A27: Nhóm 2 / dư nợ | B27: % | C27: =IF(OR(Du_lieu!C38="",Du_lieu!C33=""),"",Du_lieu!C38/Du_lieu!C33) | D27: =IF(OR(Du_lieu!D38="",Du_lieu!D33=""),"",Du_lieu!D38/Du_lieu!D33) | E27: =IF(OR(Du_lieu!E38="",Du_lieu!E33=""),"",Du_lieu!E38/Du_lieu!E33) | F27: =IF(OR(Du_lieu!F38="",Du_lieu!F33=""),"",Du_lieu!F38/Du_lieu!F33) | G27: =IF(OR(Du_lieu!G38="",Du_lieu!G33=""),"",Du_lieu!G38/Du_lieu!G33) | H27: =IF(OR(Du_lieu!H38="",Du_lieu!H33=""),"",Du_lieu!H38/Du_lieu!H33) | I27: Tỷ lệ nợ nhóm 2 trên tổng dư nợ MB (0,81%–2,28%)
A28: Nhóm 2–5 / dư nợ | B28: % | C28: =(Du_lieu!C38+Du_lieu!C31)/Du_lieu!C33 | D28: =(Du_lieu!D38+Du_lieu!D31)/Du_lieu!D33 | E28: =(Du_lieu!E38+Du_lieu!E31)/Du_lieu!E33 | F28: =(Du_lieu!F38+Du_lieu!F31)/Du_lieu!F33 | G28: =(Du_lieu!G38+Du_lieu!G31)/Du_lieu!G33 | H28: =(Du_lieu!H38+Du_lieu!H31)/Du_lieu!H33 | I28: Tỷ lệ nợ nhóm 2 đến nhóm 5 trên tổng dư nợ MB (1,90%–3,88%)
A29: Tăng trưởng nhóm 2 năm 2023 | B29: % | C29: =(Du_lieu!C38-BCTC_MB_Goc!D66)/BCTC_MB_Goc!D66 | D29: =Du_lieu!D38/Du_lieu!C38-1 | E29: =Du_lieu!E38/Du_lieu!D38-1 | F29: =Du_lieu!F38/Du_lieu!E38-1 | G29: =Du_lieu!G38/Du_lieu!F38-1 | H29: =Du_lieu!H38/Du_lieu!G38-1 | I29: Tăng trưởng nợ nhóm 2 so năm trước (-16,39% năm 2020; +78,2% năm 2023)
A30: Dự phòng ngụ ý = LLCR × nợ xấu | B30: tỷ | C30: =Du_lieu!C36*Du_lieu!C31 | D30: =Du_lieu!D36*Du_lieu!D31 | E30: =Du_lieu!E36*Du_lieu!E31 | F30: =Du_lieu!F36*Du_lieu!F31 | G30: =Du_lieu!G36*Du_lieu!G31 | H30: =Du_lieu!H36*Du_lieu!H31 | I30: Dự phòng ngụ ý theo tỷ lệ bao phủ nợ xấu LLCR thực tế
A31: Credit cost = CPDP / dư nợ bình quân | B31: % | C31: =Du_lieu!C40/AVERAGE(BCTC_MB_Goc!D64,Du_lieu!C33) | D31: =Du_lieu!D40/AVERAGE(Du_lieu!C33,Du_lieu!D33) | E31: =Du_lieu!E40/AVERAGE(Du_lieu!D33,Du_lieu!E33) | F31: =Du_lieu!F40/AVERAGE(Du_lieu!E33,Du_lieu!F33) | G31: =Du_lieu!G40/AVERAGE(Du_lieu!F33,Du_lieu!G33) | H31: =Du_lieu!H40/AVERAGE(Du_lieu!G33,Du_lieu!H33) | I31: Credit cost = Chi phí DPRR tín dụng / Dư nợ bình quân MB (1,14%–2,43%)
A32: NPL điều chỉnh năm 2021 (gồm 612 tỷ nợ cơ cấu Covid tại BCTN 2021) | B32: % | D32: =(Du_lieu!D31+Du_lieu!D48)/Du_lieu!D33 | I32: Năm 2021 là năm duy nhất MB công bố số dư nợ cơ cấu tuyệt đối cuối năm (612 tỷ tại BCTN 2021 tr.41)
A33: CPDP / lợi nhuận trước dự phòng | B33: % | C33: =Du_lieu!C40/Du_lieu!C42 | D33: =Du_lieu!D40/Du_lieu!D42 | E33: =Du_lieu!E40/Du_lieu!E42 | F33: =Du_lieu!F40/Du_lieu!F42 | G33: =Du_lieu!G40/Du_lieu!G42 | H33: =Du_lieu!H40/Du_lieu!H42 | I33: Tỷ lệ trích lập dự phòng trên lợi nhuận thuần PPOP (18,8%–36,4%)
A34: Dư nợ suy ra cuối Q3/2023 (NPL 1,89%, nợ xấu 10.111 tỷ) | B34: tỷ | F34: =10111/0.0189 | I34: Tham số Q3/2023 từ báo chí
A35: Tăng dư nợ quý IV/2023 (suy ra) | B35: % | F35: =Du_lieu!F33/F34-1
A36: Giảm nợ xấu quý IV/2025 so quý III (tỷ) | B36: tỷ | H36: =Du_lieu!H47-Du_lieu!H31 | I36: Nợ xấu quý III 17.423 → cuối năm 14.027
A37: Tỷ trọng TPDN+mua nợ trong dư nợ tín dụng hợp nhất 2023 | B37: % | F37: =(Du_lieu!F45-Du_lieu!F33)/Du_lieu!F45
A38: NPL sau – trước liên đới CIC 2023 (điểm %) | B38: đ.% | F38: =Du_lieu!F30-Du_lieu!F35
A39: 3. SO SÁNH AGRIBANK – MB (độ nhạy theo chuỗi NPL)
A40: Chênh NPL: Agribank (chuỗi chính) − MB hợp nhất | B40: đ.% | C40: =Du_lieu!C7-Du_lieu!C30 | D40: =Du_lieu!D7-Du_lieu!D30 | E40: =Du_lieu!E7-Du_lieu!E30 | F40: =Du_lieu!F7-Du_lieu!F30 | G40: =Du_lieu!G7-Du_lieu!G30 | H40: =Du_lieu!H7-Du_lieu!H30
A41: Chênh NPL: Agribank (chuỗi chính) − MB riêng ngân hàng (so sánh cùng phạm vi) | B41: đ.% | C41: =Du_lieu!C7-Du_lieu!C34 | D41: =Du_lieu!D7-Du_lieu!D34 | E41: =Du_lieu!E7-Du_lieu!E34 | F41: =Du_lieu!F7-Du_lieu!F34 | G41: =Du_lieu!G7-Du_lieu!G34 | H41: =Du_lieu!H7-Du_lieu!H34
...

Sheet Nguon
A1: DANH MỤC NGUỒN (đánh số khớp cột "Nguồn" và Tài liệu tham khảo trong báo cáo Word)
A3: Số | B3: Nguồn | C3: Đường dẫn
A4: 1 | B4: Agribank (2024), Báo cáo thường niên 2023 | C4: https://www.agribank.com.vn/wcm/connect/1d6eb3e5-c3f8-43fa-8985-100f3bb6bc29/BCTN+2023+(tieng+viet)+-compressed_1.pdf
A5: 2 | B5: MB (2024), Báo cáo thường niên 2023 | C5: https://cdn.24hmoney.vn/upload/file/2024-2/2024-05-07/no-name-1715046272.pdf
A6: 3 | B6: MB (2021), Báo cáo thường niên 2020 | C6: https://static2.vietstock.vn/data/HOSE/2020/BCTN/VN/MBB_Baocaothuongnien_2020.pdf
A7: 4 | B7: MB (2022), Báo cáo thường niên 2021 | C7: https://static2.vietstock.vn/data/HOSE/2021/BCTN/VN/MBB_Baocaothuongnien_2021.pdf
A8: 5 | B8: Báo Đầu tư, bài về kết quả kinh doanh 2023 của MB (LNTT hơn 26.300 tỷ đồng; LLCR 116%; hoàn nhập dự phòng) | C8: https://baodautu.vn/ngan-hang-quan-doi-mb-bao-lai-truoc-thue-hon-26300-ty-dong-nam-2023-d208151.html
A9: 6 | B9: Markettimes, bài về kết quả 2023 của MBBank (nợ xấu, nợ nhóm 2, chi phí dự phòng) | C9: https://markettimes.vn/mb-lai-truoc-thue-hon-26-300-ty-dong-nam-2023-ty-le-no-xau-hop-nhat-1-6-50125.html
A10: 7 | B10: Báo Đầu tư, bài về kết quả quý I/2023 của MB | C10: https://baodautu.vn/mb-bao-lai-quy-i2023-tang-10-len-hon-6500-ty-dong-d188334.html
A11: 8 | B11: Tạp chí Công Thương, bài về nợ xấu MB quý I/2023 (nhóm 2, LLCR 138%) | C11: https://tapchicongthuong.vn/mb-quy-1-2023-lai-truoc-thue-tang-10-ty-le-no-xau-o-muc-1-75-104856.htm
A12: 9 | B12: Báo Pháp luật/Sức khỏe Việt Nam, bài về kết quả quý III/2023 của MB (NPL 1,89%, LLCR ~122%) | C12: https://doanhnhanphaply.vn/mb-bao-lai-sau-thue-hon-5-700-ty-dong-quy-iii-2023-no-xau-tang-len-1-89-d32662.html
A13: 10 | B13: Báo Đại biểu Nhân dân, 'Trong nhóm dẫn đầu lợi nhuận ngành ngân hàng nhưng nợ xấu của MB tăng lên hơn 10.000 tỷ đồng' | C13: https://daibieunhandan.vn/kinh-te-xa-hoi/trong-nhom-dan-dau-loi-nhuan-nganh-ngan-hang-nhung-no-xau-cua-mb-tang-len-hon-10-000-ty-dong-i348466/
A14: 11 | B14: Tuổi Trẻ (27/01/2022), 'MB lãi hơn 16.527 tỉ đồng, nợ xấu siêu thấp chỉ 0,68%' | C14: https://tuoitre.vn/mb-lai-hon-16527-ti-dong-no-xau-sieu-thap-chi-068-20220127164100055.htm
A15: 12 | B15: Agribank (2023), Báo cáo thường niên 2022 | C15: https://static2.vietstock.vn/data/KHAC/2022/BCTN/VN/Agribank_Baocaothuongnien_2022.pdf
... A63: 60 | B63: Ngân hàng TMCP Quân đội - MB (2021), Báo cáo thường niên năm 2020: Chuyển đổi số toàn diện | C63: https://www.mbbank.com.vn/resources/investor/BaoCaoThuongNien/2020/MBB_BCTN_2020.pdf

Sheet Stress_Testing
A1: MÔ HÌNH KIỂM TRA SỨC CHỊU ĐỰNG VĨ MÔ (MACROECONOMIC STRESS TESTING) NĂM 2026
A2: Mô phỏng 3 kịch bản: Cơ sở (Baseline), Tiêu cực (Adverse) và Cực đoan (Severe) theo chuẩn Basel II/III (ICAAP)
A4: BẢNG 1: GIẢ ĐỊNH KỊCH BẢN VĨ MÔ NĂM 2026
A5: Biến số vĩ mô | B5: Đơn vị | C5: Kịch bản Cơ sở (Baseline) | D5: Kịch bản Tiêu cực (Adverse) | E5: Kịch bản Cực đoan (Severe)
A6: Tăng trưởng GDP thực tế | B6: % | C6: 0.065 | D6: 0.05 | E6: 0.035
A7: Mặt bằng lãi suất cho vay | B7: điểm cơ bản | C7: Không đổi (+0 bps) | D7: +150 bps | E7: +300 bps
A8: Chỉ số giá Bất động sản | B8: % so năm trước | C8: 0.03 | D8: -0.1 | E8: -0.25
A9: Tăng trưởng tín dụng toàn hệ thống | B9: % | C9: 0.14 | D9: 0.09 | E9: 0.05
A10: Tỷ lệ nợ nhảy nhóm 1 -> nhóm 2 (Agribank) | B10: % | C10: 0.015 | D10: 0.025 | E10: 0.04
A11: Tỷ lệ nợ nhảy nhóm 2 -> nợ xấu nhóm 3-5 (Agribank) | B11: % | C11: 0.15 | D11: 0.25 | E11: 0.4
A12: Tỷ lệ nợ nhảy nhóm 1 -> nhóm 2 (MB) | B12: % | C12: 0.018 | D12: 0.035 | E12: 0.06
A13: Tỷ lệ nợ nhảy nhóm 2 -> nợ xấu nhóm 3-5 (MB) | B13: % | C13: 0.2 | D13: 0.35 | E13: 0.55
A14: Tăng trưởng dư nợ giả định năm 2026: Agribank (= Hệ thống - 4%) | B14: % | C14: =C9-0.04 | D14: =D9-0.04 | E14: =E9-0.04
A15: Tăng trưởng dư nợ giả định năm 2026: MB (Kịch bản Cơ sở 15%, Tiêu cực 9%, Cực đoan 5%) | B15: % | C15: 0.15 | D15: =D9 | E15: =E9
A16: BẢNG 2: KẾT QUẢ STRESS TEST ĐỐI VỚI AGRIBANK (Tỷ đồng)
A17: Chỉ tiêu phân tích | B17: Năm 2025 (Thực tế) | C17: Kịch bản Cơ sở (Baseline) | D17: Kịch bản Tiêu cực (Adverse) | E17: Kịch bản Cực đoan (Severe)
A18: Tổng dư nợ cho vay khách hàng | B18: =BCTC_Agribank_Goc!I24 | C18: =ROUND($B$18*(1+C14),0) | D18: =ROUND($B$18*(1+D14),0) | E18: =ROUND($B$18*(1+E14),0)
A19: Nợ nhóm 1 (Đủ tiêu chuẩn) | B19: =BCTC_Agribank_Goc!I17+BCTC_Agribank_Goc!I23 | C19: =C18-C20-C21 | D19: =D18-D20-D21 | E19: =E18-E20-E21
A20: Nợ nhóm 2 (Cần chú ý) sau stress | B20: =BCTC_Agribank_Goc!I18 | C20: =ROUND(C18*C10,0) | D20: =ROUND(D18*D10,0) | E20: =ROUND(E18*E10,0)
A21: Nợ xấu nội bảng nhóm 3-5 | B21: =BCTC_Agribank_Goc!I25 | C21: =$B$21+C22 | D21: =$B$21+D22 | E21: =$B$21+E22
A22: - Trong đó: Nợ xấu phát sinh mới từ nhóm 2 (= Nợ nhóm 2 năm 2025 × tỷ lệ chuyển nhóm) | B22: 0 | C22: =ROUND($B$20*C11,0) | D22: =ROUND($B$20*D11,0) | E22: =ROUND($B$20*E11,0)
A23: Tỷ lệ nợ xấu (NPL stress) | B23: =B21/B18 | C23: =C21/C18 | D23: =D21/D18 | E23: =E21/E18
A24: Quỹ dự phòng rủi ro tín dụng hiện có | B24: =BCTC_Agribank_Goc!I33 | C24: =B24 | D24: =B24 | E24: =B24
A25: Nhu cầu trích lập chi phí dự phòng bổ sung | B25: 0 | C25: =ROUND(C22*1 + (C20-$B$20)*0.4685, 0) | D25: =ROUND(D22*1 + (D20-$B$20)*0.3 + $B$21*(-D8)*0.659, 0) | E25: =ROUND(E22*1 + (E20-$B$20)*0.2 + $B$21*(-E8)*0.98, 0)
A26: Tỷ lệ bao phủ nợ xấu (LLCR stress) | B26: =B24/B21 | C26: =(C24+C25*0.35)/C21 | D26: =(D24+D25*0.35)/D21 | E26: =(E24+E25*0.35)/E21
A27: Lợi nhuận trước thuế sau stress | B27: =BCTC_Agribank_Goc!I47 | C27: =ROUND($B$27*(1+C6*0.657), 0) | D27: =ROUND($C$27 - (D25-$C$25)*1.39, 0) | E27: =ROUND($C$27 - (E25-$C$25)*1.333, 0)
A28: - Tỷ lệ suy giảm LNTT so kịch bản cơ sở | B28: 0 | C28: 0 | D28: =(D27-$C$27)/$C$27 | E28: =(E27-$C$27)/$C$27
A29: Vốn tự có (Tier 1 + Tier 2) | B29: =ROUND(B30*BCTC_Agribank_Goc!I58, 0) | C29: =ROUND($B$29 + C27*0.8*0.5, 0) | D29: =ROUND($B$29 + D27*0.8*0.5 - (D25-$C$25)*1.72, 0) | E29: =ROUND($B$29 + E27*0.8*0.5 - (E25-$C$25)*1.625, 0)
A30: Tổng tài sản có rủi ro (RWA) | B30: =ROUND(B18*1.00184, 0) | C30: =ROUND(C18*1.00184, 0) | D30: =ROUND(D18*1.01, 0) | E30: =ROUND(E18*1.02, 0)
A31: Tỷ lệ an toàn vốn (CAR stress theo TT 41) | B31: =BCTC_Agribank_Goc!I58 | C31: =C29/C30 | D31: =D29/D30 | E31: =E29/E30
A32: Thặng dư / (Thâm hụt) vốn so với ngưỡng 8,0% | B32: =B31-0.08 | C32: =C31-0.08 | D32: =D31-0.08 | E32: =E31-0.08
A35: BẢNG 3: KẾT QUẢ STRESS TEST ĐỐI VỚI MB (HỢP NHẤT) (Tỷ đồng)
A36: Chỉ tiêu phân tích | B36: Năm 2025 (Thực tế) | C36: Kịch bản Cơ sở (Baseline) | D36: Kịch bản Tiêu cực (Adverse) | E36: Kịch bản Cực đoan (Severe)
A37: Tổng dư nợ cho vay khách hàng | B37: =BCTC_MB_Goc!I22 | C37: =ROUND($B$37*(1+C15),0) | D37: =ROUND($B$37*(1+D15),0) | E37: =ROUND($B$37*(1+E15),0)
A38: Nợ nhóm 1 (Đủ tiêu chuẩn) | B38: =BCTC_MB_Goc!I17 | C38: =C37-C39-C40 | D38: =D37-D39-D40 | E38: =E37-E39-E40
A39: Nợ nhóm 2 (Cần chú ý) sau stress | B39: =BCTC_MB_Goc!I18 | C39: =ROUND(C37*C12,0) | D39: =ROUND(D37*D12,0) | E39: =ROUND(E37*E12,0)
A40: Nợ xấu nội bảng nhóm 3-5 | B40: =BCTC_MB_Goc!I23 | C40: =$B$40+C41 | D40: =$B$40+D41 | E40: =$B$40+E41
A41: - Trong đó: Nợ xấu phát sinh mới từ nhóm 2 (= Nợ nhóm 2 năm 2025 × tỷ lệ chuyển nhóm) | B41: 0 | C41: =ROUND($B$39*C13,0) | D41: =ROUND($B$39*D13,0) | E41: =ROUND($B$39*E13,0)
A42: Tỷ lệ nợ xấu (NPL stress) | B42: =B40/B37 | C42: =C40/C37 | D42: =D40/D37 | E42: =E40/E37
A43: Quỹ dự phòng rủi ro tín dụng hiện có | B43: =BCTC_MB_Goc!I33 | C43: =B43 | D43: =B43 | E43: =B43
...

Sheet IFRS9_Simulation
A1: MÔ PHỎNG TÁC ĐỘNG CHUYỂN ĐỔI CHUẨN MỰC IFRS 9 (EXPECTED CREDIT LOSS - ECL)
A2: Ước tính khoảng cách dự phòng (Provisioning Gap) giữa VAS (Thông tư 11/2021) và Chuẩn mực Quốc tế IFRS 9
A4: BẢNG 1: SO SÁNH PHƯƠNG PHÁP TRÍCH LẬP DỰ PHÒNG: VAS (TT 11) VS IFRS 9
A5: Giai đoạn tín dụng | B5: VAS / Thông tư 11/2021 (Incurred Loss) | C5: IFRS 9 Framework | D5: Công thức tính ECL | E5: Agribank Giả định (PD / LGD) | F5: MB Giả định (PD / LGD)
A6: Stage 1 (Performing) | B6: Nợ nhóm 1 (DP chung 0,75%) | C6: Không có SICR | D6: EAD x PD(12m) x LGD | E6: PD=1,2% | LGD=35% | F6: PD=1,5% | LGD=45%
A7: Stage 2 (Underperforming) | B7: Nợ nhóm 2 (DP cụ thể 5% sau TSBĐ) + TT 02 | C7: Gia tăng RRTD đáng kể (SICR) | D7: EAD x PD(Lifetime) x LGD | E7: PD=22,0% | LGD=45% (SICR: Nhóm 2 + Cơ cấu + 5% Nhóm 1) | F7: PD=28,0% | LGD=50% (SICR: Nhóm 2 + 6% Nhóm 1 + 30% TPDN)
A8: Stage 3 (Credit-impaired) | B8: Nợ nhóm 3-5 (DP cụ thể 20%, 50%, 100%) | C8: Nợ xấu / Suy giảm giá trị | D8: EAD x 100% x LGD | E8: PD=100% | LGD=85% (Chiết khấu EIR thời gian thu hồi TSBĐ) | F8: PD=100% | LGD=65% (Chiết khấu dòng tiền & nợ tín chấp)
A11: BẢNG 2: KẾT QUẢ ĐỊNH LƯỢNG MÔ PHỎNG IFRS 9 NĂM 2025 (Tỷ đồng)
A12: Khoản mục phân tích | B12: Dư nợ EAD Agribank | C12: ECL ước tính Agribank | D12: Dư nợ EAD MB | E12: ECL ước tính MB | F12: Phương pháp & Ghi chú
A13: Stage 1: Nợ đủ tiêu chuẩn (Nhóm 1) | B13: =0.95*(BCTC_Agribank_Goc!I17+BCTC_Agribank_Goc!I23) | C13: =B13*0.012*0.35 | D13: =0.94*BCTC_MB_Goc!I17 | E13: =D13*0.015*0.45 | F13: EAD x PD(12m) x LGD
A14: Stage 2: Nợ có SICR (Nhóm 2 + Nợ cơ cấu) | B14: =BCTC_Agribank_Goc!I18+0.05*(BCTC_Agribank_Goc!I17+BCTC_Agribank_Goc!I23) | C14: =B14*0.22*0.45 | D14: =BCTC_MB_Goc!I18+0.06*BCTC_MB_Goc!I17+0.3*BCTC_MB_Goc!I52 | E14: =D14*0.28*0.5 | F14: EAD x PD(Lifetime) x LGD
A15: Stage 3: Nợ xấu (Nhóm 3–5) | B15: =BCTC_Agribank_Goc!I25 | C15: =B15*1*0.85 | D15: =BCTC_MB_Goc!I23 | E15: =D15*1*0.65 | F15: EAD x 100% x LGD
A16: TỔNG DỰ PHÒNG ECL THEO IFRS 9 (A) | B16: =SUM(B13:B15) | C16: =SUM(C13:C15) | D16: =SUM(D13:D15) | E16: =SUM(E13:E15) | F16: Tổng dự phòng 3 giai đoạn
A17: TỔNG DỰ PHÒNG THEO VAS/TT11 HIỆN TẠI (B) | B17: =BCTC_Agribank_Goc!I24 | C17: =BCTC_Agribank_Goc!I33 | D17: =BCTC_MB_Goc!I22 | E17: =BCTC_MB_Goc!I33 | F17: Số dư quỹ dự phòng BCTC 2025
A18: CHÊNH LỆCH DỰ PHÒNG CẦN BỔ SUNG (GAP = A - B) | B18: 0 | C18: =C16-C17 | D18: 0 | E18: =E16-E17 | F18: Khoảng cách dự phòng trích thiếu
A19: Tỷ lệ thiếu hụt so với dự phòng hiện hành (%) | B19: 0 | C19: =C18/C17 | D19: 0 | E19: =E18/E17 | F19: Gap / Dự phòng hiện hành
A20: Vốn chủ sở hữu hiện hành (Equity 2025) | B20: 0 | C20: =BCTC_Agribank_Goc!I13 | D20: 0 | E20: =BCTC_MB_Goc!I15 | F20: Vốn CSH trên BCTC 2025
A21: Tác động khấu trừ vào Vốn CSH (sau thuế TNDN 20%) | B21: 0 | C21: =-C18*(1-0.2) | D21: 0 | E21: =-E18*(1-0.2) | F21: Gap x (1 - 20%)
A22: Tỷ lệ suy giảm Vốn chủ sở hữu (%) | B22: 0 | C22: =C21/C20 | D22: 0 | E22: =E21/E20 | F22: Khấu trừ / Vốn CSH
A23: Tỷ lệ CAR hiện hành theo Thông tư 41 (%) | B23: 0 | C23: =BCTC_Agribank_Goc!I58 | D23: 0 | E23: =BCTC_MB_Goc!I62 | F23: CAR công bố / ước tính 2025
A24: Tỷ lệ CAR sau khi áp dụng IFRS 9 (%) | B24: 0 | C24: =C23+(C21/B17) | D24: 0 | E24: =E23+(E21/D17) | F24: CAR sau khấu trừ vốn
A25: Mức suy giảm CAR (điểm phần trăm / bps) | B25: 0 | C25: =C24-C23 | D25: 0 | E25: =E24-E23 | F25: Chênh lệch điểm % CAR
A27: BẢNG 3: PHÂN TÍCH HỌC THUẬT VỀ TÁC ĐỘNG CHUYỂN ĐỔI IFRS 9
A28: 1. Cú sốc trích lập tại Stage 2: | B28: Dưới chuẩn IFRS 9, khi một khoản nợ bị xếp vào Stage 2 (SICR), ngân hàng phải trích lập dự phòng tổn thất trọn vòng đời (Lifetime ECL). Tại MB, tổng dự phòng ECL lên tới 27.157 tỷ đồng so với 13.151 tỷ đồng hiện trích theo VAS, tạo ra khoảng cách thiếu hụt 14.006 tỷ đồng (+106,5%).
A29: 2. Tác động bất đối xứng đến CAR: | B29: Agribank: LGD 35% (giai đoạn 1) và 45% (giai đoạn 2) nhờ TSBĐ là BĐS, nhưng 85% ở giai đoạn 3 vì thời gian xử lý TSBĐ kéo dài làm giá trị hiện tại của tiền thu hồi giảm. MB: 45%, 50%, 65%. Khoảng cách nhỏ của Agribank chủ yếu do đã giữ dự phòng cụ thể lớn; khoảng cách lớn của MB đến từ giai đoạn 2. CAR sau IFRS 9 dùng dư nợ cho vay thay RWA nên chỉ mang tính minh họa.
A30: 3. Hàm ý chiến lược: | B30: Việc áp dụng IFRS 9 sẽ là phép thử khắc nghiệt đối với chiến lược tăng trưởng nóng của các NHTMCP đa năng; ngân hàng nào có tỷ trọng cho vay tín chấp và TPDN cao sẽ phải đối mặt với áp lực tiêu hao vốn rất lớn.
A32: BẢNG 4: PHÂN TÍCH ĐỘ NHẠY (SENSITIVITY ANALYSIS) KHOẢNG CÁCH DỰ PHÒNG IFRS 9 & TỶ LỆ CAR NĂM 2025
A33: Kịch bản độ nhạy tham số (SICR Stage 2 & LGD) | B33: Agribank: Gap Dự phòng (Tỷ) | C33: Agribank: CAR sau IFRS 9 (%) | D33: MB: Gap Dự phòng (Tỷ) | E33: MB: CAR sau IFRS 9 (%) | F33: Diễn giải tác động độ nhạy
A34: 1. Kịch bản Cơ sở (Agribank SICR 5%, MB SICR 6%; LGD chuẩn) | B34: =C18 | C34: =C24 | D34: =E18 | E34: =E24 | F34: Kịch bản trung tâm trình bày tại Bảng 2
A35: 2. Tỷ lệ Nhóm 1 chuyển sang Stage 2 (SICR) thấp (= 3,0%) | B35: =(0.97*(BCTC_Agribank_Goc!I17+BCTC_Agribank_Goc!I23)*0.012*0.35 + (BCTC_Agribank_Goc!I18+0.03*(BCTC_Agribank_Goc!I17+BCTC_Agribank_Goc!I23))*0.22*0.45 + B15*0.85) - C17 | C35: =C23 - (B35*(1-0.2))/B17 | D35: =(0.97*BCTC_MB_Goc!I17*0.015*0.45 + (BCTC_MB_Goc!I18+0.03*BCTC_MB_Goc!I17+0.3*BCTC_MB_Goc!I52)*0.28*0.5 + D15*0.65) - E17 | E35: =E23 - (D35*(1-0.2))/D17 | F35: Khi chất lượng danh mục Nhóm 1 tốt (chỉ 3% bị SICR)
A36: 3. Tỷ lệ Nhóm 1 chuyển sang Stage 2 (SICR) trung bình (= 6,0%) | B36: =(0.94*(BCTC_Agribank_Goc!I17+BCTC_Agribank_Goc!I23)*0.012*0.35 + (BCTC_Agribank_Goc!I18+0.06*(BCTC_Agribank_Goc!I17+BCTC_Agribank_Goc!I23))*0.22*0.45 + B15*0.85) - C17 | C36: =C23 - (B36*(1-0.2))/B17 | D36: =(0.94*BCTC_MB_Goc!I17*0.015*0.45 + (BCTC_MB_Goc!I18+0.06*BCTC_MB_Goc!I17+0.3*BCTC_MB_Goc!I52)*0.28*0.5 + D15*0.65) - E17 | E36: =E23 - (D36*(1-0.2))/D17 | F36: Khi cả hai ngân hàng có cùng tỷ lệ 6% Nhóm 1 chuyển sang Stage 2
A37: 4. Tỷ lệ Nhóm 1 chuyển sang Stage 2 (SICR) cao (= 9,0%) | B37: =(0.91*(BCTC_Agribank_Goc!I17+BCTC_Agribank_Goc!I23)*0.012*0.35 + (BCTC_Agribank_Goc!I18+0.09*(BCTC_Agribank_Goc!I17+BCTC_Agribank_Goc!I23))*0.22*0.45 + B15*0.85) - C17 | C37: =C23 - (B37*(1-0.2))/B17 | D37: =(0.91*BCTC_MB_Goc!I17*0.015*0.45 + (BCTC_MB_Goc!I18+0.09*BCTC_MB_Goc!I17+0.3*BCTC_MB_Goc!I52)*0.28*0.5 + D15*0.65) - E17 | E37: =E23 - (D37*(1-0.2))/D17 | F37: Khi suy giảm kinh tế diện rộng làm 9% Nhóm 1 rơi vào Stage 2
A38: 5. Hệ số tổn thất LGD giảm 10 điểm % ở mọi giai đoạn (LGD -10%) | B38: =(B13*0.012*0.25 + B14*0.22*0.35 + B15*0.75) - C17 | C38: =C23 - MAX(0,B38)*(1-0.2)/B17 | D38: =(D13*0.015*0.35 + D14*0.28*0.4 + D15*0.55) - E17 | E38: =E23 - MAX(0,D38)*(1-0.2)/D17 | F38: Khi thanh khoản phát mại TSBĐ thuận lợi (Agribank dư dự phòng)
A39: 6. Hệ số tổn thất LGD tăng 10 điểm % ở mọi giai đoạn (LGD +10%) | B39: =(B13*0.012*0.45 + B14*0.22*0.55 + B15*0.95) - C17 | C39: =C23 - (B39*(1-0.2))/B17 | D39: =(D13*0.015*0.55 + D14*0.28*0.6 + D15*0.75) - E17 | E39: =E23 - (D39*(1-0.2))/D17 | F39: Khi thị trường BĐS đóng băng làm LGD tăng thêm 10 điểm %
A41: Lưu ý phương pháp (soát xét 28/10/2026):
A42: (a) EAD Stage 2 của MB gồm 30% TPDN do TCKT phát hành (0,30 × 23.410 tỷ; ECL ≈ 983 tỷ), trong khi dự phòng VAS so sánh (E17 = 13.151 tỷ) chỉ là dự phòng cho vay khách hàng → Gap 14.006 tỷ gồm cả phần TPDN.
A43: (b) CAR sau IFRS 9 (dòng 24, 34–39) = CAR hiện hành − tác động sau thuế / dư nợ cho vay (B17, D17), dùng dư nợ thay cho RWA → mức giảm (bps) mang tính minh họa.
A44: (c) Phân bổ dự phòng VAS theo Stage trong Bảng 11 (Word): Stage 1 = dự phòng chung; Stage 2 = 5% × nợ nhóm 2; Stage 3 = dự phòng cụ thể còn lại.

Sheet BCTC_Agribank_Goc
A1: BẢNG DỮ LIỆU GỐC TRÍCH XUẤT BCTC KIỂM TOÁN & BCTN AGRIBANK (2020–2025)
A2: Đơn vị: Tỷ đồng (Quy đổi chính xác từ Triệu VND trên BCTC Kiểm toán). Liên kết tự động sang sheet Du_lieu, Chi_tieu, Stress_Testing, IFRS9_Simulation.
A4: Mã TM | B4: Chỉ tiêu Báo cáo Tài chính & Thuyết minh Kiểm toán | C4: Đơn vị | D4: 2020 | E4: 2021 | F4: 2022 | G4: 2023 | H4: 2024 | I4: 2025 | J4: Trích dẫn File PDF gốc, Thuyết minh & Trang
A5: I | B5: BẢNG CÂN ĐỐI KẾ TOÁN & NGOÀI BẢNG (HỢP NHẤT & RIÊNG LẺ)
A6: B02-HN | B6: Tổng tài sản (Hợp nhất) | C6: tỷ | D6: 1568126.9 | E6: 1695932.7 | F6: 1874839.2 | G6: 2044927.4 | H6: 2234854.2 | I6: 2686597.8 | J6: BCTC HN 2020 (tr.7), 2021 (tr.6), 2023 (tr.20), 2025 (tr.126)
A7: B02-RL | B7: Tổng tài sản (Riêng lẻ - Ngân hàng mẹ) | C7: tỷ | D7: 1566966.9 | E7: 1694231.5 | F7: 1873684.6 | G7: 2042976.2 | H7: 2231961.6 | I7: 2682737.8 | J7: BCTC Riêng 2021 (tr.6), 2023 (tr.132), 2025 (tr.6)
A8: TM 9/10 | B8: Cho vay khách hàng gộp (Hợp nhất) | C8: tỷ | D8: =D24 | E8: =E24 | F8: =F24 | G8: =G24 | H8: =H24 | I8: =I24 | J8: TM 9 BCTC HN 2020 (tr.35), TM 10 2021 (tr.45), TM 9 2023 (tr.61), TM 9 2025 (tr.170)
A9: TM 9/10 | B9: Cho vay khách hàng gộp (Riêng lẻ - Ngân hàng mẹ) | C9: tỷ | D9: =D22 | E9: =E22 | F9: =F22 | G9: =G22 | H9: =H22 | I9: =I22 | J9: TM 10 BCTC Riêng 2021 (tr.38), TM 9 2023 (tr.166), TM 9 2025 (tr.72)
A10: TM 10/11 | B10: Dự phòng rủi ro cho vay khách hàng (Hợp nhất) | C10: tỷ | D10: =D33 | E10: =E33 | F10: =F33 | G10: =G33 | H10: =H33 | I10: =I33 | J10: TM 10 BCTC HN 2020 (tr.37), TM 11 2021 (tr.48), TM 10 2023 (tr.64), TM 10 2025 (tr.172)
A11: TM 10/11 | B11: Dự phòng rủi ro cho vay khách hàng (Riêng lẻ) | C11: tỷ | D11: 23877.048 | E11: 34023.924 | F11: 36276.157 | G11: 37487.862 | H11: 37770.426 | I11: 36976.803 | J11: TM 11 BCTC Riêng 2021 (tr.41), TM 10 2023 (tr.169), TM 10 2025 (tr.74)
A12: TM 18/19 | B12: Tiền gửi của khách hàng (Hợp nhất) | C12: tỷ | D12: 1404875.8 | E12: 1542504.4 | F12: 1623935.1 | G12: 1817271 | H12: 1914664.4 | I12: 2156382.7 | J12: B02/TCTD-HN 2020-2025
A13: TM 23/24 | B13: Tổng Vốn chủ sở hữu (Hợp nhất) | C13: tỷ | D13: 73084.295 | E13: 76087.34 | F13: 86997.553 | G13: 100535.85 | H13: 124067.76 | I13: 131191.25 | J13: B02/TCTD-HN 2020-2025
A14: TM 23/24 | B14: Trong đó: Vốn điều lệ | C14: tỷ | D14: 30709.923 | E14: 34328.393 | F14: 34446.863 | G14: 41268.833 | H14: 51638.603 | I14: 51638.603 | J14: B02/TCTD-HN 2020-2025
A15: TM 39/40 | B15: Ngoài bảng: Nợ khó đòi đã xử lý đang theo dõi (Hợp nhất) | C15: tỷ | D15: 145000 | E15: 156800 | F15: 181111.74 | G15: 205217.79 | H15: 235401.95 | I15: 278372.38 | J15: TM 39 BCTC HN 2023 (tr.93), TM 40 BCTC HN 2025 (tr.198); 2020-21 ước tính ngược từ dòng xóa nợ
A16: II | B16: PHÂN TÍCH CHẤT LƯỢNG NỢ CHO VAY (THUYẾT MINH 9 / 10)
A17: TM 9.1 | B17: Nhóm 1 - Nợ đủ tiêu chuẩn | C17: tỷ | D17: 1161020 | E17: 1261194.3 | F17: 1381920 | G17: 1489187.1 | H17: 1662997.8 | I17: 1926570.3 | J17: TM 9 BCTC HN 2020 (tr.35), TM 10 2021 (tr.45), TM 9 2023 (tr.61), TM 9 2025 (tr.170)
