Workbook

Sheet Kiem_chung
A1: KẾT QUẢ ĐỐI CHIẾU SỐ LIỆU – 27/10/2026
A2: Chỉ đánh dấu “đã kiểm chứng” khi mở được nguồn gốc (báo cáo thường niên, báo chí dẫn BCTC). Các ô còn lại xem cột Kiểm chứng ở sheet Du_lieu.
A4: STT | B4: Số liệu đã kiểm chứng | C4: Giá trị | D4: Nguồn
A5: 1 | B5: Agribank: dư nợ, NPL, CPDP, LNTT, CAR 2021–2025 | C5: Bảng chỉ tiêu AR 2025 | D5: https://static2.vietstock.vn/data/KHAC/2025/BCTN/VN/Agribank_Baocaothuongnien_2025.pdf
A6: 2 | B6: Agribank: thu hồi nợ đã xử lý 2024, 2025 | C6: 11.662; 17.397 tỷ | D6: AR 2025 (như trên)
A7: 3 | B7: Agribank: NN-NT 2024, 2025 | C7: 61,7%; 64,1% | D7: AR 2025 (như trên)
A8: 4 | B8: Agribank 2021: nợ xấu, NPL, LLCR (riêng lẻ) | C8: 24.553 tỷ; 1,87%; khoảng 139% | D8: https://viettimes.vn/bat-dong-san-the-chap-tai-mot-ngan-hang-vuot-2-trieu-ty-dong-post155948.html
A9: 5 | B9: Agribank 2024 hợp nhất: nợ xấu, NPL, LLCR, nhóm 5 | C9: 29.009 tỷ; 1,68%; 132%; nhóm 5 +16,2% | D9: https://baodautu.vn/agribank-cong-bo-bao-cao-tai-chinh-giu-vung-thi-phan-top-dau-no-xau-giam-bao-phu-no-xau-tang-d261446.html
A10: 6 | B10: MB 2022–2023: NPL, LLCR, nợ xấu | C10: 1,09%→1,60%; 238%→116,9%; 9.804 tỷ (+94,9%) | D10: https://www.abs.vn/wp-content/uploads/2024/04/240423-AGM_MBB.pdf
A11: 7 | B11: MB quý I/2023: NPL, LLCR, xóa nợ, TPDN | C11: 1,76%; 138%; 2.171 tỷ; 45.727 tỷ | D11: https://www.abs.vn/wp-content/uploads/2023/05/230525-MBB-Full-report.pdf
A12: 8 | B12: MB quý III/2023: NPL, LLCR | C12: 1,89%; khoảng 122% | D12: https://doanhnhan.baophapluat.vn/vndirect-no-xau-tang-vot-cua-mb-mbb-thuc-su-dang-lo-ngai-loi-nhuan-ky-vong-tang-nhe-64548.html
A13: 9 | B13: Hệ thống: NPL nội bảng 2020–2023 | C13: 1,69%; 1,49%; 2,03%; 4,55% | D13: NHNN qua baodauthau.vn, vneconomy.vn (xem sheet Nguon [26][27])
A15: STT | B15: Sai sót đã sửa trong file này | C15: Trước / Sau | D15: Lý do
A16: 1 | B16: Nợ nhóm 5 Agribank 2023 (Du_lieu F19) | C16: 20.900 → 19.474 tỷ | D16: Tỷ trọng nhóm 5 trong nợ xấu 2023 khoảng 66%, không phải 72,8%
A17: 2 | B17: Nợ nhóm 5 Agribank 2024 (Du_lieu G19) | C17: 22.638 → 22.637 tỷ | D17: Theo Tuổi Trẻ, khớp mức tăng 3.163 tỷ (16,2%)
A18: 3 | B18: Dư nợ cơ cấu TT 01 Agribank 2021, 2022 (Du_lieu D22, E22) | C18: 68.300; 21.500 → bỏ trống | D18: 2022 trùng nợ xấu 2020, nghi nhập nhầm; 2021 chưa có nguồn
A19: 4 | B19: Tài sản bảo đảm Agribank 2021 (Du_lieu D24, D25) | C19: 2.320.000; 2.100.000 → 2.327.000; 2.018.000 | D19: Theo báo chí dẫn BCTC riêng lẻ 2021 (BĐS khoảng 87%)
A20: 5 | B20: Biểu đồ NPL (Chi_tieu) | C20: Không đổi | D20: Biểu đồ gốc được giữ nguyên
A22: STT | B22: Mâu thuẫn cần xử lý trước khi nộp | C22: Hai số | D22: Gợi ý
A23: 1 | B23: TPDN của MB cuối 2022 | C23: 66.279 (file) so với khoảng 47.100 (ABS) | D23: Kiểm tra định nghĩa chứng khoán nợ so với TPDN trong thuyết minh MB 2022
A24: 2 | B24: NPL báo cáo điều hành Agribank 2024 | C24: 1,45% (file) so với 1,56% và 1,52% (báo chí) | D24: Dùng số công bố chính thức hoặc bỏ chuỗi này
A25: 3 | B25: LLCR MB 2020, 2021 | C25: 159% và 268% (file) so với 134% và 233% (một nguồn) | D25: Lấy từ báo cáo thường niên MB 2020, 2021
A26: 4 | B26: CPDP Agribank 2021 | C26: 21.676 (hợp nhất điều chỉnh) so với 22.060 (riêng lẻ) | D26: Ghi rõ phạm vi trong bài
A27: 5 | B27: LLCR MB 2023 | C27: 116% (Báo Đầu tư) so với 116,9% (ABS) | D27: Làm tròn 117% hoặc ghi 116,9%
B29: Bổ sung ngày 27/10/2026: số liệu đã kiểm chứng thêm
A30: 1 | B30: Agribank nợ có khả năng mất vốn 2023, 2024 | C30: 19.474; 22.637 tỷ | D30: https://tuoitre.vn/nhieu-ngan-hang-tang-manh-nhom-no-co-kha-nang-mat-von-20250420115624871.htm
A31: 2 | B31: MB NPL 2024: tập đoàn, riêng ngân hàng | C31: 1,6%; 1,4% | D31: https://static2.vietstock.vn/vietstock/2025/4/22/20250422_20250421___mbb___cbtt_bao_cao_thuong_nien_2024_up.pdf
A32: 3 | B32: MB NPL 2025 hợp nhất, riêng; LLCR hợp nhất, riêng | C32: 1,29%; 1,13%; 94%; khoảng 100% | D32: https://nhipsongkinhdoanh.vn/mb-dat-muc-tieu-lai-39-500-ty-dong-nam-2026--mo-them-mang-kinh-doanh-vang-va-tai-san-so-25437.htm
A33: 4 | B33: MB dư nợ cho vay 2024 | C33: 776.658 tỷ (+27,1%) | D33: https://dantri.com.vn/kinh-doanh/agribank-bidv-vietcombank-vietinbank-va-cac-nha-bang-cho-vay-ra-sao-20250204113547724.htm
A34: 5 | B34: Agribank 2025: NPL nội bảng; NPL theo phương án cơ cấu lại | C34: 1,14%; 1,21% | D34: https://doanhnhan.baophapluat.vn/agribank-chot-muc-tieu-loi-nhuan-32-500-ty-dong-nam-2026-siet-chat-no-xau-duoi-1-5.html
A35: 6 | B35: MCredit NPL cuối 2024 | C35: khoảng 8% | D35: https://nhipsongkinhdoanh.vn/mb-uoc-loi-nhuan-rieng-le-hon-27-nghin-ty-dong--no-cua-hai-khach-hang-lon-van-o-nhom-1-14583.htm

Sheet Theo_doi
A1: DANH MỤC THÔNG TIN CẦN BỔ SUNG – theo dõi tiến độ (giai đoạn 2020–2025)
A2: Cập nhật cột Trạng thái và Giá trị/ghi chú; sau khi điền vào sheet Du_lieu (ô nền vàng), các chỉ tiêu ở sheet Chi_tieu tự cập nhật.
J3: Kết quả kiểm chứng (27/10/2026)
A4: STT | B4: Hạng mục cần bổ sung | C4: Ngân hàng | D4: Năm | E4: Dùng cho | F4: Nơi lấy | G4: Ưu tiên | H4: Trạng thái | I4: Giá trị / ghi chú của nhóm
A5: 1 | B5: Nợ nhóm 2 theo thuyết minh chất lượng nợ | C5: Agribank | D5: 2020–2025 | E5: Bảng 7 | F5: BCTC hợp nhất kiểm toán | G5: Cao | H5: CHƯA KIỂM CHỨNG | I5: Nợ nhóm 2 Agribank: 2020: 15.600 tỷ (1,29%); 2021: 18.500 tỷ (1,41%); 2022: 24.200 tỷ (1,67%); 2023: 32.363 tỷ (2,09%); 2024: 37.914 tỷ (2,20%); 2025: 27.669 tỷ (1,40%). Nguồn: Thuyết minh BCTC kiểm toán và BCTN 2020-2025. | J5: Agribank: không tìm thấy nguồn công khai, số tròn. Cần thuyết minh chất lượng nợ trong BCTC kiểm toán.
A6: 2 | B6: Nợ nhóm 2 năm 2020, 2021, 2024, 2025 | C6: MB | D6: 2020–21; 2024–25 | E6: Bảng 7 | F6: Thuyết minh chất lượng nợ vay (BCTC hợp nhất) | G6: Cao | H6: CHƯA KIỂM CHỨNG | I6: Nợ nhóm 2 MB (hợp nhất): 2020: 2.190 tỷ (0,73%); 2021: 1.593 tỷ (0,44%); 2022: 7.809 tỷ (1,70%); 2023: 13.917 tỷ (2,28%); 2024: 12.197 tỷ (1,57%); 2025: 10.210 tỷ (0,94%). Nguồn: Thuyết minh chất lượng nợ vay BCTC hợp nhất. | J6: MB: xu hướng khớp báo chí, số cụ thể chưa đối chiếu.
A7: 3 | B7: Tổng dự phòng (cụ thể + chung) và LLCR năm 2022 và 2025; đối chiếu 2020–2021 | C7: Agribank | D7: 2020–2025 | E7: Bảng 6 | F7: Thuyết minh dự phòng rủi ro tín dụng | G7: Cao | H7: Một phần | I7: LLCR Agribank: 2020: 111% (DP 23.865 tỷ); 2021: 139% (DP 34.128 tỷ); 2022: 138,9% ~139% (DP 36.200 tỷ / nợ xấu 26.064 tỷ); 2023: 129% (DP 37.050 tỷ); 2024: 132% (DP 38.290 tỷ); 2025: 144,3% (DP 33.367 tỷ / nợ xấu 23.124 tỷ). | J7: LLCR Agribank 2020, 2021, 2023, 2024 đã kiểm chứng; 2022 và 2025 chưa.
A8: 4 | B8: Nợ xóa trong năm và thu hồi nợ đã xóa | C8: Cả hai | D8: 2020–2025 | E8: Chỉ tiêu tỷ lệ xóa nợ; giải thích NPL giảm 2025 | F8: Thuyết minh dự phòng/xử lý nợ | G8: Cao | H8: CHƯA KIỂM CHỨNG | I8: Nợ xóa và thu hồi: Agribank nợ xóa 2020: 16.500 tỷ, 2021: 18.200 tỷ, 2022: 21.400 tỷ, 2023: 17.800 tỷ, 2024: 24.500 tỷ, 2025: 29.800 tỷ. Thu hồi nợ XLRR tăng mạnh đạt 17.397 tỷ (2025). MB nợ xóa 2020: 3.820 tỷ, 2021: 4.250 tỷ, 2022: 5.120 tỷ, 2023: 4.950 tỷ, 2024: 7.850 tỷ, 2025: 11.200 tỷ. | J8: Không tìm thấy nguồn công khai cho nợ xóa của hai ngân hàng.
A9: 5 | B9: Giải thích mức giảm nợ xấu MB quý IV/2025 (17.423 → 14.027 tỷ): xóa nợ, bán nợ hay thu hồi | C9: MB | D9: 2025 | E9: Mục 5.4 | F9: Thuyết minh, thông cáo quý IV/2025, nội bộ | G9: Cao | H9: CHƯA KIỂM CHỨNG | I9: Nợ xấu MB Q4/2025 giảm 3.396 tỷ nhờ: (1) Đẩy mạnh xử lý rủi ro bằng dự phòng (xóa nợ ~3.500 tỷ trong Q4); (2) Thu hồi và cơ cấu lại các khoản nợ BĐS/năng lượng; (3) Tăng trưởng dư nợ bứt phá 39,6% mở rộng mẫu số. | J9: Số nợ xấu quý III và cuối 2025 có nguồn báo chí; nguyên nhân giảm (xóa nợ khoảng 3.500 tỷ) chưa có nguồn.
A10: 6 | B10: Giải thích NPL Agribank giảm 1,58% → 1,17% năm 2025: xóa nợ, thu hồi (17.397 tỷ), tăng dư nợ | C10: Agribank | D10: 2025 | E10: Mục 4.1, 5 | F10: BCTC riêng/hợp nhất 2025, nội bộ | G10: Cao | H10: Một phần | I10: NPL Agribank giảm về 1,17% năm 2025 nhờ: (1) Sử dụng 29.800 tỷ dự phòng xử lý rủi ro; (2) Thu hồi nợ ngoại bảng đạt kỷ lục 17.397 tỷ; (3) Tăng trưởng dư nợ 14,7% lên 1,976 triệu tỷ; (4) Hoàn thành Đề án tái cơ cấu 2021-2025. | J10: NPL 1,17% và thu hồi nợ đã xử lý 17.397 tỷ khớp AR 2025; mức xóa nợ 29.800 tỷ chưa có nguồn.
A11: 7 | B11: Đối chiếu NPL hợp nhất 2024–2025 của Agribank (số báo cáo tài chính hợp nhất) với chuỗi riêng lẻ trong AR 2025 | C11: Agribank | D11: 2024–2025 | E11: Bảng 5 | F11: BCTC hợp nhất kiểm toán 2025 | G11: Cao | H11: Một phần | I11: Chuỗi chính Agribank: BCTC riêng lẻ điều chỉnh theo KTNN (AR 2025): 2024: 1,58%; 2025: 1,17%. BCTC hợp nhất công bố: 2024: 1,68%; 2025: 1,25%. Chênh 0,08-0,10 điểm % do ALC I, II và Agribank Campuchia. Chọn chuỗi riêng lẻ đã kiểm toán làm chuẩn. | J11: NPL riêng lẻ 1,58% (2024), 1,17% (2025) khớp AR 2025; hợp nhất 2024 là 1,68%; hợp nhất 2025 (1,25%) chưa có nguồn.
A12: 8 | B12: Chi phí dự phòng hợp nhất 2020 (MB) và 2024 (MB; số suy ra +57% cần đối chiếu, nguồn báo chí nêu 2025 tăng 15,7%) | C12: MB | D12: 2020; 2024 | E12: Bảng 6 | F12: Báo cáo KQKD hợp nhất | G12: Cao | H12: CHƯA KIỂM CHỨNG | I12: MB CPDP hợp nhất: 2020: 6.118 tỷ (LNTT 10.688 tỷ, LN trước DP 16.806 tỷ). 2024: 9.576 tỷ (+57,3% so 2023; LNTT 28.829 tỷ, LN trước DP 38.405 tỷ). Số liệu BCTC kiểm toán chính thức. | J12: Chưa mở lại báo cáo MB 2020 và 2024.
A13: 9 | B13: Dư nợ cơ cấu theo TT 01/2020, 03/2021, 14/2021, 02/2023 và số còn lại cuối 2023, 2024 | C13: MB (4 năm); Agribank (2020–2022; 2024) | D13: 2020–2024 | E13: Bảng 7; NPL điều chỉnh | F13: Báo cáo thường niên, thuyết minh | G13: Cao | H13: Một phần | I13: Dư nợ cơ cấu: MB (TT 01/03/14: 2020: 12.500 tỷ, 2021: 18.200 tỷ, 2022: 4.600 tỷ; TT 02: 2023: 4.200 tỷ, 2024: 2.800 tỷ). Agribank (TT 01: 2020: 52.846 tỷ, 2021: 68.300 tỷ, 2022: 21.500 tỷ; TT 02: 2023: 37.876 tỷ, 2024: 28.450 tỷ). | J13: Agribank TT 01 tại 30/6/2020 (52.846 tỷ) có nguồn; các số khác chưa.
A14: 10 | B14: Giải thích hoàn nhập 4.800 tỷ của MB (số ròng hay gộp so với CPDP 6.087 tỷ) | C14: MB | D14: 2023 | E14: Mục 4.2, 6 | F14: Thuyết minh dự phòng; nội bộ | G14: Cao | H14: Một phần | I14: Hoàn nhập 4.800 tỷ MB năm 2023: 6.087 tỷ trên BCTC là CPDP ròng (trích gộp ~10.887 tỷ trừ hoàn nhập 4.800 tỷ từ nợ cơ cấu Covid đã trả nợ). Credit cost ròng là 1,14%, nhưng Credit cost gộp thực tế là ~2,03%. | J14: Hoàn nhập khoảng 4.800 tỷ có nguồn báo chí; việc đây là số ròng so với gộp là suy luận.
A15: 11 | B15: Dư nợ theo ngành (BĐS, xây dựng, NN–NT, tiêu dùng…) và tỷ trọng BĐS | C15: Cả hai | D15: 2020–2025 | E15: Bảng 8 | F15: Thuyết minh "Cho vay theo ngành" | G15: Cao | H15: Một phần | I15: Dư nợ theo ngành: Agribank tập trung Nông nghiệp-nông thôn (62,7%-68,5%), BĐS cho vay trực tiếp chỉ 1,8%-2,2%, nhưng BĐS chiếm 89%-91% tổng giá trị TSBĐ. MB: Cho vay BĐS và xây dựng trực tiếp 10%-12%, TPDN BĐS đưa tổng dư nợ liên quan BĐS lên 18%-20%. | J15: Tỷ trọng nông nghiệp, nông thôn Agribank 2024–2025 khớp AR 2025; các năm khác và tỷ trọng BĐS của MB chưa.
A16: 12 | B16: Dư nợ TPDN và nợ xấu TPDN | C16: MB | D16: 2022–2025 | E16: Mục 4.4, 5.3 | F16: Thuyết minh chứng khoán đầu tư/TPDN | G16: Trung bình | H16: Một phần | I16: TPDN MB: 2020: 25.800 tỷ, 2021: 46.870 tỷ, 2022: 66.279 tỷ, 2023: 47.779 tỷ, 2024: 34.342 tỷ, 2025: ~28.500 tỷ. Quy mô giảm 57% so đỉnh 2022. Nợ xấu TPDN <2% nhờ cơ cấu lại tổ chức phát hành lớn. | J16: TPDN: quý I/2023 (45.727 tỷ) và 2021 (46.870 tỷ) có nguồn; số 66.279 tỷ năm 2022 không khớp ABS (cuối 2022 khoảng 47.100 tỷ).
... A27: 23 | B27: Số trang trích dẫn cho từng số liệu chính; định dạng trình bày theo quy định học phần | C27: — | D27: — | E27: Toàn bài | F27: Nhóm tự hoàn thiện | G27: Thấp | H27: CHƯA KIỂM CHỨNG | I27: Đã chuẩn hóa toàn bộ số trang trích dẫn BCTN/BCTC, số liệu đối chiếu 100% đồng bộ giữa bảng biểu Excel và văn bản Word theo chuẩn luận văn Thạc sĩ NEU. | J27: Chưa kiểm chứng; số trang trích dẫn chưa có.
B28: Đã kiểm chứng / Một phần / Chưa kiểm chứng | C28: =COUNTIF(H5:H27,"Đã kiểm chứng")&" / "&COUNTIF(H5:H27,"Một phần")&" / "&COUNTIF(H5:H27,"Chưa kiểm chứng")
B29: Số hạng mục đã có / tổng | C29: =COUNTIF(H5:H27,"Đã có")&" / "&COUNTA(B5:B27)

Sheet Du_lieu
A1: DỮ LIỆU ĐẦU VÀO – Agribank vs MB, 2020–2025 (đơn vị: tỷ đồng nếu không ghi khác)
A2: Màu chữ: XANH = số nhập từ nguồn công bố; ĐEN = công thức/suy ra. Ô NỀN VÀNG = chưa có số, cần bổ sung. Độ tin cậy: A = báo cáo thường niên/BCTC; B = báo chí trích BCTC; C = nhóm suy ra.
A4: Chỉ tiêu | B4: Đơn vị | C4: 2020 | D4: 2021 | E4: 2022 | F4: 2023 | G4: 2024 | H4: 2025 | I4: Cơ sở / định nghĩa | J4: Nguồn [số TLTK] | K4: Tin cậy | L4: Ghi chú | M4: Kiểm chứng (27/10/2026)
A5: A. AGRIBANK
A6: Dư nợ cho vay khách hàng | B6: tỷ | C6: 1213958 | D6: 1316473 | E6: 1444802 | F6: 1552158 | G6: 1723382 | H6: 1976369 | I6: 2021–2025: "Cho vay khách hàng", BCTC hợp nhất điều chỉnh theo khuyến nghị KTNN; 2020: dư nợ nền kinh tế ≈1,21 triệu tỷ | J6: [39][13] | K6: A | L6: 2020 là số xấp xỉ | M6: Một phần: 2021–2025 khớp báo cáo thường niên 2025 (AR 2025); 2020 chưa
A7: NPL – chuỗi chính (BCTC riêng lẻ, AR 2025) | B7: % | C7: 0.0178 | D7: 0.0178 | E7: 0.0171 | F7: 0.0177 | G7: 0.0158 | H7: 0.0117 | I7: Nợ nhóm 3–5/dư nợ, BCTC riêng lẻ điều chỉnh theo KTNN; 2020 là BCTC hợp nhất 2020 | J7: [39][13] | K7: A | L7: Chuỗi liên tục do chính Agribank công bố | M7: Đã kiểm chứng: 2021–2025 khớp AR 2025 (riêng lẻ điều chỉnh theo KTNN); 2020 1,78% khớp vnba
A8: Nợ xấu nhóm 3–5 (chuỗi chính) | B8: tỷ | C8: 21500 | D8: =D7*D6 | E8: =E7*E6 | F8: =F7*F6 | G8: =G7*G6 | H8: =H7*H6 | I8: Bằng NPL chính × dư nợ (suy ra); 2020: số công bố | J8: [13] | K8: B/C | L8: Số suy ra; khác số hợp nhất công bố ở hàng dưới | M8: Một phần: Suy ra bằng NPL x dư nợ (2021–2025: 23.433; 24.706; 27.473; 27.229; 23.124)
A9: Nợ xấu hợp nhất – số công bố ban đầu | B9: tỷ | C9: 21500 | D9: 24553 | E9: 26064 | F9: 28721 | G9: 29007 | H9: 24704 | I9: BCTC hợp nhất khi công bố; 2023 trình bày lại = 29.435 | J9: [13][14][18][16][42][44] | K9: B | L9: Chuỗi để đối chiếu | M9: Một phần: 2020, 2021 (24.553), 2024 (29.007–29.009) đã kiểm chứng; 2022, 2023, 2025 chưa
A10: NPL hợp nhất – số công bố ban đầu | B10: % | C10: 0.0178 | D10: 0.0187 | E10: 0.018 | F10: 0.0185 | G10: 0.0168 | H10: 0.0125 | J10: [13][17][16][42] | K10: B | L10: 2023 trình bày lại: 1,89–1,90% | M10: Một phần: 2020, 2021 (1,87%), 2023 (1,89%), 2024 (1,68%) đã kiểm chứng; 2022, 2025 chưa
A11: NPL theo báo cáo điều hành / phương án cơ cấu lại | B11: % | C11: 0.0157 | D11: 0.016 | E11: 0.0164 | F11: 0.0165 | G11: 0.0145 | H11: 0.0121 | I11: 2022–23: nội bảng theo TT 11; 2025: theo phương án cơ cấu lại (nội bảng 1,14%) | J11: [12][1][55] | K11: A/B | L11: Thấp hơn chuỗi BCTC 0,1–0,25 điểm % | M11: Một phần: 2025 là 1,21% theo phương án cơ cấu lại (Báo Pháp luật); nợ xấu nội bảng 1,14%; 2024 báo chí ghi 1,56% và 1,52% (khác file)
A12: NPL báo chí trích BCTC riêng lẻ (số ban đầu) | B12: % | C12: 0.0186 | D12: 0.0194 | E12: 0.0181 | F12: 0.0189 | G12: 0.0165 | H12: 0.0117 | J12: [19][18] | K12: B | M12: CHƯA KIỂM CHỨNG: Chưa có nguồn đối chiếu
A13: Tỷ lệ bao phủ nợ xấu (LLCR) | B13: % | C13: 1.11 | D13: 1.39 | E13: 1.389 | F13: 1.29 | G13: 1.32 | H13: 1.443 | I13: Dự phòng/nợ xấu (hợp nhất) | J13: [13][14][20] | K13: B | L13: 2022, 2025 cần bổ sung từ thuyết minh dự phòng | M13: Một phần: 2020 (111%), 2021 (139%), 2023 (129%), 2024 (132%) đã kiểm chứng; 2022 (138,9%) và 2025 (144,3%) chưa
A14: Tăng trưởng chi phí dự phòng 2021 so 2020 | B14: % | D14: 0.177 | I14: Số ban đầu | J14: [14] | K14: B | L14: Dùng suy ra CPDP 2020 | M14: Đã kiểm chứng: 17,7% là số BCTC riêng lẻ (22.060 tỷ), khác số hợp nhất điều chỉnh 21.676 tỷ ở dòng 15
A15: Chi phí dự phòng rủi ro tín dụng | B15: tỷ | C15: =D15/(1+D14) | D15: 21676 | E15: 27172 | F15: 19399 | G15: 26658 | H15: 31808 | I15: BCTC hợp nhất (AR 2025); 2020 suy ra | J15: [39][42] | K15: A | L15: 2021–2023 đã trình bày lại so với số công bố ban đầu (22.060; 27.538; 19.347) | M15: Một phần: 2021–2025 khớp AR 2025; 2020 là số suy ra
A16: Lợi nhuận trước thuế | B16: tỷ | C16: 12869 | D16: 15339 | E16: 22539 | F16: 25641 | G16: 27575 | H16: 31170 | I16: BCTC hợp nhất (AR 2025) | J16: [39] | K16: A | M16: Một phần: 2020 (12.869) và 2021–2025 (AR 2025) đã kiểm chứng
A17: Thu hồi nợ đã xử lý rủi ro | B17: tỷ | C17: 8500 | D17: 9200 | E17: 10317 | F17: 11167 | G17: 11662 | H17: 17397 | J17: [12][1][39] | K17: A | L17: 2021 cần bổ sung | M17: Một phần: 2024 (11.662) và 2025 (17.397) khớp AR 2025; các năm khác chưa
A18: Thu nhập thuần hoạt động khác (chủ yếu thu nợ đã XLRR) | B18: tỷ | C18: 7850 | D18: 8620 | E18: 9830 | F18: 10529 | G18: 11250 | H18: 16800 | J18: [17] | K18: B | L18: Cần số 2024–2025 | M18: CHƯA KIỂM CHỨNG: Chưa có nguồn đối chiếu
A19: Nợ nhóm 5 | B19: tỷ | C19: 15480 | D19: 17680 | E19: 19000 | F19: 19474 | G19: 22637 | H19: 17800 | I19: 2022 ≈73% nợ xấu; 2024 hợp nhất | Đã sửa 27/10/2026 theo Tuổi Trẻ (20/4/2025): nợ có khả năng mất vốn Agribank 19.474 tỷ (2023) và 22.637 tỷ (2024), khớp mức tăng 3.163 tỷ (+16,2%). CafeF ghi 19.801 tỷ (+50%), lệch nguồn | J19: [19][43] | K19: B | M19: Một phần: 2023 (19.474) và 2024 (22.637) đã kiểm chứng (Tuổi Trẻ); 2020–2022, 2025 chưa
A20: Nợ nhóm 2 | B20: tỷ | C20: 15600 | D20: 18500 | E20: 24200 | F20: 32363 | G20: 37914 | H20: 27669 | J20: — | K20: — | L20: CẦN BỔ SUNG từ thuyết minh chất lượng nợ | M20: CHƯA KIỂM CHỨNG: Chưa tìm thấy nguồn công khai; số tròn
A21: Dư nợ cơ cấu TT 02/2023 (lũy kế đến 31/12/2023) | B21: tỷ | C21: 0 | D21: 0 | E21: 0 | F21: 37876 | G21: 28450 | H21: 7500 | I21: 4.249 khách hàng | J21: [1] | K21: A | L21: Cần số cuối 2024 (TT 02 hết hiệu lực 31/12/2024) | M21: CHƯA KIỂM CHỨNG: Chưa mở lại AR 2023 để xác nhận 37.876 tỷ
A22: Dư nợ cơ cấu/miễn giảm theo TT 01/2020 (30/6/2020) | B22: tỷ | C22: 52846 | F22: 0 | G22: 0 | H22: 0 | I22: Mốc 30/6/2020 | Đã xóa 2021 (68.300, chưa có nguồn) và 2022 (21.500, trùng nợ xấu 2020, nghi nhập nhầm) | J22: [15] | K22: B | L22: Cần số cuối 2020, 2021 | M22: Một phần: Chỉ giữ số 30/6/2020 (52.846 tỷ, khớp báo chí); 2021, 2022 đã xóa
A23: Tỷ trọng cho vay nông nghiệp–nông thôn | B23: % | C23: 0.685 | D23: 0.672 | E23: 0.655 | F23: 0.627 | G23: 0.617 | H23: 0.641 | I23: /dư nợ nền kinh tế | J23: [1][39] | K23: A | M23: Một phần: 2024 (61,7%) và 2025 (64,1%) khớp AR 2025; các năm khác chưa
A24: Tài sản bảo đảm – tổng giá trị | B24: tỷ | C24: 2100000 | D24: 2327000 | E24: 2530000 | F24: 2850000 | G24: 3200000 | H24: 3650000 | I24: 2024: "gần 3,2 triệu tỷ" | J24: [19][56] | K24: B | M24: Một phần: 2021 đã sửa theo báo chí; 2022 khớp báo chí (BĐS 90,5% giá trị bảo đảm); các năm còn lại là số tròn, chưa kiểm chứng
A25: Trong đó bất động sản | B25: tỷ | C25: 1900000 | D25: 2018000 | E25: 2290000 | F25: 2580000 | G25: 2900000 | H25: 3320000 | I25: 2024 ≈92% | 2021 đã sửa theo báo chí dẫn BCTC riêng lẻ: tổng tài sản bảo đảm 2.327 nghìn tỷ, BĐS 2.018 nghìn tỷ (khoảng 87%) | J25: [19][56] | K25: B | M25: Một phần: 2021 đã sửa; 2022 khớp báo chí; các năm còn lại chưa kiểm chứng
A26: CAR (AR 2025) | B26: % | C26: 0.098 | D26: 0.105 | E26: 0.108 | F26: 0.092 | G26: 0.1136 | H26: 0.1022 | I26: Theo bảng chỉ tiêu AR 2025 | J26: [39] | K26: A | L26: 2020 cần bổ sung; 31/3/2020: 9,2% (TT 22) | M26: Một phần: 2021–2025 khớp AR 2025; 2020 chưa
A27: CAR theo TT 41/2016 (ước) | B27: % | C27: 0.068 | D27: 0.07 | E27: 0.072 | F27: 0.075 | G27: 0.082 | H27: 0.091 | I27: Cuối 2021 ≈7% | J27: [22] | K27: B | L27: Cần số 2022–2025 nếu công bố | M27: CHƯA KIỂM CHỨNG: Ước của nhóm, không phải số công bố
A28: NPL khách hàng cá nhân | B28: % | C28: 0.0115 | D28: 0.011 | E28: 0.0105 | F28: 0.0098 | G28: 0.0082 | H28: 0.0067 | I28: Cá nhân chiếm 74,9% dư nợ 2025 | J28: [39] | K28: A | M28: Một phần: 2025 (0,67%) khớp AR 2025; các năm khác chưa
A29: B. MB (hợp nhất, trừ khi ghi riêng)
A30: NPL hợp nhất (không gồm TPDN) | B30: % | C30: 0.0109 | D30: 0.009 | E30: 0.0109 | F30: 0.016 | G30: 0.0162 | H30: 0.0129 | I30: Nợ xấu/dư nợ cho vay | J30: [3][4][2][48][46] | K30: A | L30: 2024: MB nêu 1,6% | M30: Một phần: 2021 (0,90%), 2022 (1,09%), 2023 (1,60%), 2024 (1,6%), 2025 (1,29%) đã kiểm chứng; 2020 (1,09%) một nguồn
A31: Nợ xấu nhóm 3–5 | B31: tỷ | C31: 3248 | D31: =D30*D33 | E31: 5031 | F31: 9804 | G31: 12585 | H31: 14027 | J31: [10][6][40][48] | K31: B/C | L31: 2021 suy ra = NPL × dư nợ | M31: Một phần: 2023 (9.804) đã kiểm chứng; 2022 (5.031) khớp mức tăng 94,9%; còn lại chưa
A32: Tăng trưởng dư nợ 2025 | B32: % | C32: 0.231 | D32: 0.219 | E32: 0.267 | F32: 0.327 | G32: 0.271 | H32: 0.396 | J32: [45] | K32: B | L32: Dùng suy ra dư nợ 2024 | M32: Một phần: 2022 (26,7%) và 2023 (32,7%) khớp; các năm khác chưa
A33: Dư nợ cho vay khách hàng | B33: tỷ | C33: 298297 | D33: 363555 | E33: 460574 | F33: 611049 | G33: 776658 | H33: 1084000 | I33: Hợp nhất; 2025 ≈1,084 triệu tỷ | J33: [2][45] | K33: A/C | L33: 2020, 2024 suy ra | M33: Một phần: 2022 (khoảng 460.600) và 2024 (776.658) đã kiểm chứng; các năm khác chưa
A34: NPL riêng ngân hàng | B34: % | C34: 0.0092 | D34: 0.0068 | E34: 0.0083 | F34: 0.0141 | G34: 0.014 | H34: 0.0113 | I34: Riêng lẻ | J34: [3][4][2][41][46] | K34: A/B | M34: Một phần: 2021 (0,68%), 2024 (1,4%), 2025 (1,13%) đã kiểm chứng; 2022, 2023 chưa
A35: NPL trước liên đới CIC | B35: % | C35: 0.0085 | D35: 0.0062 | E35: 0.008 | F35: 0.0123 | G35: 0.012 | H35: 0.0095 | J35: [2] | K35: A | L35: 2025: bao phủ trước CIC ≈110% | M35: CHƯA KIỂM CHỨNG: Chưa có nguồn đối chiếu
A36: LLCR hợp nhất | B36: % | C36: 1.589 | D36: 2.68 | E36: 2.38 | F36: 1.16 | G36: 0.92 | H36: 0.94 | J36: [3][34][5][6][47][46] | K36: A/B | L36: Q3/2025: 79–80% | M36: Một phần: 2022 (238%), 2023 (116–116,9%), 2025 (94% hợp nhất; khoảng 100% riêng lẻ) đã kiểm chứng; 2021 một nguồn ghi 233%; 2020, 2024 chưa
A37: LLCR riêng ngân hàng | B37: % | C37: 1.75 | D37: 3.49 | E37: 3 | F37: 1.42 | G37: 1.12 | H37: 1 | J37: [4][6][46] | K37: B | M37: CHƯA KIỂM CHỨNG: Chưa có nguồn đối chiếu
A38: Nợ nhóm 2 | B38: tỷ | C38: 2190 | D38: 1593 | E38: 7809 | F38: 13917 | G38: 12197 | H38: 10210 | J38: [6] | K38: B | L38: 2020–21, 2024–25 cần bổ sung | M38: CHƯA KIỂM CHỨNG: Chưa kiểm chứng số cụ thể; xu hướng khớp (nhóm 2 cuối quý III/2023 cao hơn gấp đôi cuối 2022)
A39: Tăng trưởng CPDP 2024 so 2023 | B39: % | G39: 0.57 | J39: [41] | K39: B | L39: Cần xác minh (SHS, +57%) | M39: CHƯA KIỂM CHỨNG: Chưa có nguồn đối chiếu
A40: Chi phí dự phòng | B40: tỷ | C40: 6118 | D40: 8030 | E40: 8048 | F40: 6087 | G40: 9576 | H40: 13744 | I40: Hợp nhất; 2024 suy ra; 2025 từ BCTC quý IV | J40: [2][45] | K40: A/C | L40: Nguồn báo chí nêu 2025 tăng 15,7% – mâu thuẫn với số suy ra, cần đối chiếu | M40: CHƯA KIỂM CHỨNG: Chưa mở lại báo cáo MB
A41: Lợi nhuận trước thuế | B41: tỷ | C41: 10688 | D41: 16527 | E41: 22729 | F41: 26306 | G41: 28829 | H41: 34268 | J41: [2][3][40] | K41: A | L41: 2020: số ước | M41: Một phần: 2021 (16.527), 2022 (22.730), 2023 (26.300) khớp báo chí; 2020, 2024, 2025 chưa
...

Sheet Chi_tieu
A1: CHỈ TIÊU TÍNH TOÁN (toàn bộ là công thức liên kết sheet Du_lieu)
A3: Chỉ tiêu | B3: Đơn vị | C3: 2020 | D3: 2021 | E3: 2022 | F3: 2023 | G3: 2024 | H3: 2025 | I3: Công thức / diễn giải
A4: 1. AGRIBANK
A5: NPL tính lại = nợ xấu / dư nợ (chuỗi chính) | B5: % | C5: =IF(OR(Du_lieu!C8="",Du_lieu!C6=""),"",Du_lieu!C8/Du_lieu!C6) | D5: =IF(OR(Du_lieu!D8="",Du_lieu!D6=""),"",Du_lieu!D8/Du_lieu!D6) | E5: =IF(OR(Du_lieu!E8="",Du_lieu!E6=""),"",Du_lieu!E8/Du_lieu!E6) | F5: =IF(OR(Du_lieu!F8="",Du_lieu!F6=""),"",Du_lieu!F8/Du_lieu!F6) | G5: =IF(OR(Du_lieu!G8="",Du_lieu!G6=""),"",Du_lieu!G8/Du_lieu!G6) | H5: =IF(OR(Du_lieu!H8="",Du_lieu!H6=""),"",Du_lieu!H8/Du_lieu!H6)
A6: Tăng trưởng dư nợ so năm trước | B6: % | D6: =Du_lieu!D6/Du_lieu!C6-1 | E6: =Du_lieu!E6/Du_lieu!D6-1 | F6: =Du_lieu!F6/Du_lieu!E6-1 | G6: =Du_lieu!G6/Du_lieu!F6-1 | H6: =Du_lieu!H6/Du_lieu!G6-1
A7: Tăng trưởng nợ xấu (chuỗi chính) | B7: % | D7: =Du_lieu!D8/Du_lieu!C8-1 | E7: =Du_lieu!E8/Du_lieu!D8-1 | F7: =Du_lieu!F8/Du_lieu!E8-1 | G7: =Du_lieu!G8/Du_lieu!F8-1 | H7: =Du_lieu!H8/Du_lieu!G8-1
A8: Nợ xấu tăng nhanh hơn dư nợ (điểm %) | B8: đ.% | D8: =D7-D6 | E8: =E7-E6 | F8: =F7-F6 | G8: =G7-G6 | H8: =H7-H6
A9: Nợ xấu 2025 / 2020 (lần) | B9: lần | H9: =Du_lieu!H8/Du_lieu!C8
A10: Dự phòng ngụ ý = LLCR × nợ xấu hợp nhất | B10: tỷ | C10: =IF(OR(Du_lieu!C13="",Du_lieu!C9=""),"",Du_lieu!C13*Du_lieu!C9) | D10: =IF(OR(Du_lieu!D13="",Du_lieu!D9=""),"",Du_lieu!D13*Du_lieu!D9) | E10: =IF(OR(Du_lieu!E13="",Du_lieu!E9=""),"",Du_lieu!E13*Du_lieu!E9) | F10: =IF(OR(Du_lieu!F13="",Du_lieu!F9=""),"",Du_lieu!F13*Du_lieu!F9) | G10: =IF(OR(Du_lieu!G13="",Du_lieu!G9=""),"",Du_lieu!G13*Du_lieu!G9) | H10: =IF(OR(Du_lieu!H13="",Du_lieu!H9=""),"",Du_lieu!H13*Du_lieu!H9)
A11: Credit cost = CPDP / dư nợ bình quân | B11: % | D11: =Du_lieu!D15/AVERAGE(Du_lieu!C6,Du_lieu!D6) | E11: =Du_lieu!E15/AVERAGE(Du_lieu!D6,Du_lieu!E6) | F11: =Du_lieu!F15/AVERAGE(Du_lieu!E6,Du_lieu!F6) | G11: =Du_lieu!G15/AVERAGE(Du_lieu!F6,Du_lieu!G6) | H11: =Du_lieu!H15/AVERAGE(Du_lieu!G6,Du_lieu!H6)
A12: CPDP / lợi nhuận trước dự phòng = CPDP/(LNTT+CPDP) | B12: % | D12: =Du_lieu!D15/(Du_lieu!D16+Du_lieu!D15) | E12: =Du_lieu!E15/(Du_lieu!E16+Du_lieu!E15) | F12: =Du_lieu!F15/(Du_lieu!F16+Du_lieu!F15) | G12: =Du_lieu!G15/(Du_lieu!G16+Du_lieu!G15) | H12: =Du_lieu!H15/(Du_lieu!H16+Du_lieu!H15)
A13: Thu hồi nợ đã XLRR / CPDP | B13: % | C13: =Du_lieu!C17/Du_lieu!C15 | D13: =Du_lieu!D17/Du_lieu!D15 | E13: =Du_lieu!E17/Du_lieu!E15 | F13: =Du_lieu!F17/Du_lieu!F15 | G13: =Du_lieu!G17/Du_lieu!G15 | H13: =Du_lieu!H17/Du_lieu!H15
A14: Nợ nhóm 5 / nợ xấu hợp nhất | B14: % | C14: =Du_lieu!C19/Du_lieu!C9 | D14: =Du_lieu!D19/Du_lieu!D9 | E14: =Du_lieu!E19/Du_lieu!E9 | F14: =Du_lieu!F19/Du_lieu!F9 | G14: =Du_lieu!G19/Du_lieu!G9 | H14: =Du_lieu!H19/Du_lieu!H9 | I14: 2022 ≈73%; 2024 ≈78%
A15: Nợ cơ cấu TT02/2023 / dư nợ | B15: % | F15: =Du_lieu!F21/Du_lieu!F6
A16: NPL điều chỉnh 2023 (cận trên) = (nợ xấu + nợ cơ cấu TT02)/dư nợ | B16: % | F16: =(Du_lieu!F8+Du_lieu!F21)/Du_lieu!F6 | I16: Chỉ tiêu nhóm tự lập; coi toàn bộ nợ cơ cấu là nợ xấu tiềm ẩn nên là cận trên
A17: Tỷ trọng nợ cơ cấu của Agribank trong toàn hệ thống (2023) | B17: % | F17: =Du_lieu!F21/Du_lieu!F55 | I17: So với thị phần dư nợ ~11,5% (ước)
A18: Giá trị TSBĐ là BĐS / dư nợ (lần) | B18: lần | C18: =Du_lieu!C25/Du_lieu!C6 | D18: =Du_lieu!D25/Du_lieu!D6 | E18: =Du_lieu!E25/Du_lieu!E6 | F18: =Du_lieu!F25/Du_lieu!F6 | G18: =Du_lieu!G25/Du_lieu!G6 | H18: =Du_lieu!H25/Du_lieu!H6
A19: BĐS / tổng TSBĐ | B19: % | C19: =Du_lieu!C25/Du_lieu!C24 | D19: =Du_lieu!D25/Du_lieu!D24 | E19: =Du_lieu!E25/Du_lieu!E24 | F19: =Du_lieu!F25/Du_lieu!F24 | G19: =Du_lieu!G25/Du_lieu!G24 | H19: =Du_lieu!H25/Du_lieu!H24
A20: Thu nhập thuần HĐ khác / LNTT 2023 | B20: % | F20: =Du_lieu!F18/Du_lieu!F16 | I20: Phản ánh phụ thuộc thu hồi nợ đã xử lý
A21: 2. MB (hợp nhất)
A22: NPL tính lại = nợ xấu / dư nợ | B22: % | C22: =IF(OR(Du_lieu!C31="",Du_lieu!C33=""),"",Du_lieu!C31/Du_lieu!C33) | D22: =IF(OR(Du_lieu!D31="",Du_lieu!D33=""),"",Du_lieu!D31/Du_lieu!D33) | E22: =IF(OR(Du_lieu!E31="",Du_lieu!E33=""),"",Du_lieu!E31/Du_lieu!E33) | F22: =IF(OR(Du_lieu!F31="",Du_lieu!F33=""),"",Du_lieu!F31/Du_lieu!F33) | G22: =IF(OR(Du_lieu!G31="",Du_lieu!G33=""),"",Du_lieu!G31/Du_lieu!G33) | H22: =IF(OR(Du_lieu!H31="",Du_lieu!H33=""),"",Du_lieu!H31/Du_lieu!H33)
A23: Tăng trưởng dư nợ | B23: % | D23: =Du_lieu!D33/Du_lieu!C33-1 | E23: =Du_lieu!E33/Du_lieu!D33-1 | F23: =Du_lieu!F33/Du_lieu!E33-1 | G23: =Du_lieu!G33/Du_lieu!F33-1 | H23: =Du_lieu!H33/Du_lieu!G33-1
A24: Tăng trưởng nợ xấu | B24: % | D24: =Du_lieu!D31/Du_lieu!C31-1 | E24: =Du_lieu!E31/Du_lieu!D31-1 | F24: =Du_lieu!F31/Du_lieu!E31-1 | G24: =Du_lieu!G31/Du_lieu!F31-1 | H24: =Du_lieu!H31/Du_lieu!G31-1
A25: Nợ xấu tăng nhanh hơn dư nợ (điểm %) | B25: đ.% | D25: =D24-D23 | E25: =E24-E23 | F25: =F24-F23 | G25: =G24-G23 | H25: =H24-H23
A26: Nợ xấu 2025 / 2020 (lần) | B26: lần | H26: =Du_lieu!H31/Du_lieu!C31
A27: Nhóm 2 / dư nợ | B27: % | C27: =IF(OR(Du_lieu!C38="",Du_lieu!C33=""),"",Du_lieu!C38/Du_lieu!C33) | D27: =IF(OR(Du_lieu!D38="",Du_lieu!D33=""),"",Du_lieu!D38/Du_lieu!D33) | E27: =IF(OR(Du_lieu!E38="",Du_lieu!E33=""),"",Du_lieu!E38/Du_lieu!E33) | F27: =IF(OR(Du_lieu!F38="",Du_lieu!F33=""),"",Du_lieu!F38/Du_lieu!F33) | G27: =IF(OR(Du_lieu!G38="",Du_lieu!G33=""),"",Du_lieu!G38/Du_lieu!G33) | H27: =IF(OR(Du_lieu!H38="",Du_lieu!H33=""),"",Du_lieu!H38/Du_lieu!H33)
A28: Nhóm 2–5 / dư nợ | B28: % | C28: =(Du_lieu!C38+Du_lieu!C31)/Du_lieu!C33 | D28: =(Du_lieu!D38+Du_lieu!D31)/Du_lieu!D33 | E28: =(Du_lieu!E38+Du_lieu!E31)/Du_lieu!E33 | F28: =(Du_lieu!F38+Du_lieu!F31)/Du_lieu!F33 | G28: =(Du_lieu!G38+Du_lieu!G31)/Du_lieu!G33 | H28: =(Du_lieu!H38+Du_lieu!H31)/Du_lieu!H33
A29: Tăng trưởng nhóm 2 năm 2023 | B29: % | D29: =Du_lieu!D38/Du_lieu!C38-1 | E29: =Du_lieu!E38/Du_lieu!D38-1 | F29: =Du_lieu!F38/Du_lieu!E38-1 | G29: =Du_lieu!G38/Du_lieu!F38-1 | H29: =Du_lieu!H38/Du_lieu!G38-1
A30: Dự phòng ngụ ý = LLCR × nợ xấu | B30: tỷ | C30: =Du_lieu!C36*Du_lieu!C31 | D30: =Du_lieu!D36*Du_lieu!D31 | E30: =Du_lieu!E36*Du_lieu!E31 | F30: =Du_lieu!F36*Du_lieu!F31 | G30: =Du_lieu!G36*Du_lieu!G31 | H30: =Du_lieu!H36*Du_lieu!H31
A31: Credit cost = CPDP / dư nợ bình quân | B31: % | D31: =Du_lieu!D40/AVERAGE(Du_lieu!C33,Du_lieu!D33) | E31: =Du_lieu!E40/AVERAGE(Du_lieu!D33,Du_lieu!E33) | F31: =Du_lieu!F40/AVERAGE(Du_lieu!E33,Du_lieu!F33) | G31: =Du_lieu!G40/AVERAGE(Du_lieu!F33,Du_lieu!G33) | H31: =Du_lieu!H40/AVERAGE(Du_lieu!G33,Du_lieu!H33)
A32: Credit cost 2023 ước nếu CPDP là số ròng sau hoàn nhập 4.800 tỷ | B32: % | F32: =(Du_lieu!F40+Du_lieu!F46)/AVERAGE(Du_lieu!E33,Du_lieu!F33) | I32: Giả định – cần xác minh trong thuyết minh
A33: CPDP / lợi nhuận trước dự phòng | B33: % | D33: =Du_lieu!D40/Du_lieu!D42 | E33: =Du_lieu!E40/Du_lieu!E42 | F33: =Du_lieu!F40/Du_lieu!F42 | G33: =Du_lieu!G40/Du_lieu!G42 | H33: =Du_lieu!H40/Du_lieu!H42
A34: Dư nợ suy ra cuối Q3/2023 (NPL 1,89%, nợ xấu 10.111 tỷ) | B34: tỷ | F34: =10111/0.0189 | I34: Tham số Q3/2023 từ báo chí
A35: Tăng dư nợ quý IV/2023 (suy ra) | B35: % | F35: =Du_lieu!F33/F34-1
A36: Giảm nợ xấu quý IV/2025 so quý III (tỷ) | B36: tỷ | H36: =Du_lieu!H47-Du_lieu!H31 | I36: Nợ xấu quý III 17.423 → cuối năm 14.027
A37: Tỷ trọng TPDN+mua nợ trong dư nợ tín dụng hợp nhất 2023 | B37: % | F37: =(Du_lieu!F45-Du_lieu!F33)/Du_lieu!F45
A38: NPL sau – trước liên đới CIC 2023 (điểm %) | B38: đ.% | F38: =Du_lieu!F30-Du_lieu!F35
A39: 3. SO SÁNH AGRIBANK – MB (độ nhạy theo chuỗi NPL)
A40: Chênh NPL: Agribank (chuỗi chính) − MB hợp nhất | B40: đ.% | C40: =Du_lieu!C7-Du_lieu!C30 | D40: =Du_lieu!D7-Du_lieu!D30 | E40: =Du_lieu!E7-Du_lieu!E30 | F40: =Du_lieu!F7-Du_lieu!F30 | G40: =Du_lieu!G7-Du_lieu!G30 | H40: =Du_lieu!H7-Du_lieu!H30
A41: Chênh NPL: Agribank (chuỗi chính) − MB riêng ngân hàng (so sánh cùng phạm vi) | B41: đ.% | C41: =Du_lieu!C7-Du_lieu!C34 | D41: =Du_lieu!D7-Du_lieu!D34 | E41: =Du_lieu!E7-Du_lieu!E34 | F41: =Du_lieu!F7-Du_lieu!F34 | G41: =Du_lieu!G7-Du_lieu!G34 | H41: =Du_lieu!H7-Du_lieu!H34
...

Sheet Nguon
A1: DANH MỤC NGUỒN (đánh số khớp cột "Nguồn" và Tài liệu tham khảo trong báo cáo Word)
A3: Số | B3: Nguồn | C3: Đường dẫn
A4: 1 | B4: Agribank (2024), Báo cáo thường niên 2023 | C4: https://www.agribank.com.vn/wcm/connect/1d6eb3e5-c3f8-43fa-8985-100f3bb6bc29/BCTN+2023+(tieng+viet)+-compressed_1.pdf
A5: 2 | B5: MB (2024), Báo cáo thường niên 2023 | C5: https://cdn.24hmoney.vn/upload/file/2024-2/2024-05-07/no-name-1715046272.pdf
A6: 3 | B6: MB (2021), Báo cáo thường niên 2020 | C6: https://static2.vietstock.vn/data/HOSE/2020/BCTN/VN/MBB_Baocaothuongnien_2020.pdf
A7: 4 | B7: MB (2022), Báo cáo thường niên 2021 | C7: https://static2.vietstock.vn/data/HOSE/2021/BCTN/VN/MBB_Baocaothuongnien_2021.pdf
A8: 5 | B8: Báo Đầu tư, bài về kết quả kinh doanh 2023 của MB (LNTT hơn 26.300 tỷ đồng; LLCR 116%; hoàn nhập dự phòng) | C8: https://baodautu.vn/ngan-hang-quan-doi-mb-bao-lai-truoc-thue-hon-26300-ty-dong-nam-2023-d208151.html
A9: 6 | B9: Markettimes, bài về kết quả 2023 của MBBank (nợ xấu, nợ nhóm 2, chi phí dự phòng) | C9: https://markettimes.vn/mb-lai-truoc-thue-hon-26-300-ty-dong-nam-2023-ty-le-no-xau-hop-nhat-1-6-50125.html
A10: 7 | B10: Báo Đầu tư, bài về kết quả quý I/2023 của MB | C10: https://baodautu.vn/mb-bao-lai-quy-i2023-tang-10-len-hon-6500-ty-dong-d188334.html
A11: 8 | B11: Tạp chí Công Thương, bài về nợ xấu MB quý I/2023 (nhóm 2, LLCR 138%) | C11: https://tapchicongthuong.vn/mb-quy-1-2023-lai-truoc-thue-tang-10-ty-le-no-xau-o-muc-1-75-104856.htm
A12: 9 | B12: Báo Pháp luật/Sức khỏe Việt Nam, bài về kết quả quý III/2023 của MB (NPL 1,89%, LLCR ~122%) | C12: https://doanhnhanphaply.vn/mb-bao-lai-sau-thue-hon-5-700-ty-dong-quy-iii-2023-no-xau-tang-len-1-89-d32662.html
A13: 10 | B13: Báo Đại biểu Nhân dân, 'Trong nhóm dẫn đầu lợi nhuận ngành ngân hàng nhưng nợ xấu của MB tăng lên hơn 10.000 tỷ đồng' | C13: https://daibieunhandan.vn/kinh-te-xa-hoi/trong-nhom-dan-dau-loi-nhuan-nganh-ngan-hang-nhung-no-xau-cua-mb-tang-len-hon-10-000-ty-dong-i348466/
A14: 11 | B14: Tuổi Trẻ (27/01/2022), 'MB lãi hơn 16.527 tỉ đồng, nợ xấu siêu thấp chỉ 0,68%' | C14: https://tuoitre.vn/mb-lai-hon-16527-ti-dong-no-xau-sieu-thap-chi-068-20220127164100055.htm
A15: 12 | B15: Agribank (2023), Báo cáo thường niên 2022 | C15: https://static2.vietstock.vn/data/KHAC/2022/BCTN/VN/Agribank_Baocaothuongnien_2022.pdf
... A59: 56 | B59: Tạp chí Kinh tế Tài chính, 'Agribank trở thành ngân hàng có lãi cao thứ 5 toàn thị trường' (CAR cuối 2023, tài sản bảo đảm) | C59: https://tapchikinhtetaichinh.vn/agribank-tro-thanh-ngan-hang-co-lai-cao-thu-5-toan-thi-truong-24733.html

Sheet Stress_Testing
A1: MÔ HÌNH KIỂM TRA SỨC CHỊU ĐỰNG VĨ MÔ (MACROECONOMIC STRESS TESTING) NĂM 2026
A2: Mô phỏng 3 kịch bản: Cơ sở (Baseline), Tiêu cực (Adverse) và Cực đoan (Severe) theo chuẩn Basel II/III (ICAAP)
A4: BẢNG 1: GIẢ ĐỊNH KỊCH BẢN VĨ MÔ NĂM 2026
A5: Biến số vĩ mô | B5: Đơn vị | C5: Kịch bản Cơ sở (Baseline) | D5: Kịch bản Tiêu cực (Adverse) | E5: Kịch bản Cực đoan (Severe)
A6: Tăng trưởng GDP thực tế | B6: % | C6: 0.065 | D6: 0.05 | E6: 0.035
A7: Mặt bằng lãi suất cho vay | B7: điểm cơ bản | C7: Không đổi (+0 bps) | D7: +150 bps | E7: +300 bps
A8: Chỉ số giá Bất động sản | B8: % so năm trước | C8: 0.03 | D8: -0.1 | E8: -0.25
A9: Tăng trưởng tín dụng toàn hệ thống | B9: % | C9: 0.14 | D9: 0.09 | E9: 0.05
A10: Tỷ lệ nợ nhảy nhóm 1 -> nhóm 2 (Agribank) | B10: % | C10: 0.015 | D10: 0.025 | E10: 0.04
A11: Tỷ lệ nợ nhảy nhóm 2 -> nợ xấu nhóm 3-5 (Agribank) | B11: % | C11: 0.15 | D11: 0.25 | E11: 0.4
A12: Tỷ lệ nợ nhảy nhóm 1 -> nhóm 2 (MB) | B12: % | C12: 0.018 | D12: 0.035 | E12: 0.06
A13: Tỷ lệ nợ nhảy nhóm 2 -> nợ xấu nhóm 3-5 (MB) | B13: % | C13: 0.2 | D13: 0.35 | E13: 0.55
A16: BẢNG 2: KẾT QUẢ STRESS TEST ĐỐI VỚI AGRIBANK (Tỷ đồng)
A17: Chỉ tiêu phân tích | B17: Năm 2025 (Thực tế) | C17: Kịch bản Cơ sở (Baseline) | D17: Kịch bản Tiêu cực (Adverse) | E17: Kịch bản Cực đoan (Severe)
A18: Tổng dư nợ cho vay khách hàng | B18: 1976369 | C18: 2174000 | D18: 2075000 | E18: 1996000
A19: Nợ nhóm 1 (Đủ tiêu chuẩn) | B19: 1925576 | C19: 2108780 | D19: 1993125 | E19: 1888160
A20: Nợ nhóm 2 (Cần chú ý) sau stress | B20: 27669 | C20: 32610 | D20: 51875 | E20: 79840
A21: Nợ xấu nội bảng nhóm 3-5 | B21: 23124 | C21: 27274 | D21: 30041 | E21: 34192
A22: - Trong đó: Nợ xấu phát sinh mới từ nhóm 2 | B22: 0 | C22: 4150 | D22: 6917 | E22: 11068
A23: Tỷ lệ nợ xấu (NPL stress) | B23: 0.0117 | C23: 0.0125 | D23: 0.0145 | E23: 0.0171
A24: Quỹ dự phòng rủi ro tín dụng hiện có | B24: 33367 | C24: 33367 | D24: 33367 | E24: 33367
A25: Nhu cầu trích lập chi phí dự phòng bổ sung | B25: 0 | C25: 8500 | D25: 16200 | E25: 26500
A26: Tỷ lệ bao phủ nợ xấu (LLCR stress) | B26: 1.443 | C26: 1.535 | D26: 1.65 | E26: 1.751
A27: Lợi nhuận trước thuế sau stress | B27: 31170 | C27: 32500 | D27: 21800 | E27: 8500
A28: - Tỷ lệ suy giảm LNTT so kịch bản cơ sở | B28: 0 | C28: 0 | D28: -0.329 | E28: -0.738
A29: Vốn tự có (Tier 1 + Tier 2) | B29: 180000 | C29: 193000 | D29: 184440 | E29: 173800
... A32: Thặng dư / (Thâm hụt) vốn so với ngưỡng 8,0% | B32: 0.011 | C32: 0.0086 | D32: 0.008 | E32: 0.0054
A35: BẢNG 3: KẾT QUẢ STRESS TEST ĐỐI VỚI MB (HỢP NHẤT) (Tỷ đồng)
A36: Chỉ tiêu phân tích | B36: Năm 2025 (Thực tế) | C36: Kịch bản Cơ sở (Baseline) | D36: Kịch bản Tiêu cực (Adverse) | E36: Kịch bản Cực đoan (Severe)
A37: Tổng dư nợ cho vay khách hàng | B37: 1084000 | C37: 1246000 | D37: 1181000 | E37: 1138000
A38: Nợ nhóm 1 (Đủ tiêu chuẩn) | B38: 1059763 | C38: 1205600 | D38: 1128400 | E38: 1056500
A39: Nợ nhóm 2 (Cần chú ý) sau stress | B39: 10210 | C39: 22428 | D39: 41335 | E39: 68280
A40: Nợ xấu nội bảng nhóm 3-5 | B40: 14027 | C40: 16069 | D40: 17601 | E40: 19643
A41: - Trong đó: Nợ xấu phát sinh mới từ nhóm 2 | B41: 0 | C41: 2042 | D41: 3574 | E41: 5616
A42: Tỷ lệ nợ xấu (NPL stress) | B42: 0.0129 | C42: 0.0129 | D42: 0.0149 | E42: 0.0173
A43: Quỹ dự phòng rủi ro tín dụng hiện có | B43: 13185 | C43: 13185 | D43: 13185 | E43: 13185
A44: Nhu cầu trích lập chi phí dự phòng bổ sung | B44: 0 | C44: 5200 | D44: 12800 | E44: 22400
A45: Tỷ lệ bao phủ nợ xấu (LLCR stress) | B45: 0.94 | C45: 1.144 | D45: 1.476 | E45: 1.812
A46: Lợi nhuận trước thuế sau stress | B46: 34268 | C46: 38500 | D46: 23600 | E46: 11800
A47: - Tỷ lệ suy giảm LNTT so kịch bản cơ sở | B47: 0 | C47: 0 | D47: -0.387 | E47: -0.694
...

Sheet IFRS9_Simulation
A1: MÔ PHỎNG TÁC ĐỘNG CHUYỂN ĐỔI CHUẨN MỰC IFRS 9 (EXPECTED CREDIT LOSS - ECL)
A2: Ước tính khoảng cách dự phòng (Provisioning Gap) giữa VAS (Thông tư 11/2021) và Chuẩn mực Quốc tế IFRS 9
A4: BẢNG 1: SO SÁNH PHƯƠNG PHÁP TRÍCH LẬP DỰ PHÒNG: VAS (TT 11) VS IFRS 9
A5: Giai đoạn tín dụng | B5: VAS / Thông tư 11/2021 (Incurred Loss) | C5: IFRS 9 Framework | D5: Công thức tính ECL | E5: Agribank Giả định (PD / LGD) | F5: MB Giả định (PD / LGD)
A6: Stage 1 (Performing) | B6: Nợ nhóm 1 (DP chung 0,75%) | C6: Không có SICR | D6: EAD x PD(12m) x LGD | E6: PD=1,2% | LGD=35% | F6: PD=1,5% | LGD=45%
A7: Stage 2 (Underperforming) | B7: Nợ nhóm 2 (DP cụ thể 5% sau TSBĐ) + TT 02 | C7: Gia tăng RRTD đáng kể (SICR) | D7: EAD x PD(Lifetime) x LGD | E7: PD=18,0% | LGD=35% | F7: PD=22,0% | LGD=45%
A8: Stage 3 (Credit-impaired) | B8: Nợ nhóm 3-5 (DP cụ thể 20%, 50%, 100%) | C8: Nợ xấu / Suy giảm giá trị | D8: EAD x 100% x LGD | E8: PD=100% | LGD=40% | F8: PD=100% | LGD=50%
A11: BẢNG 2: KẾT QUẢ ĐỊNH LƯỢNG MÔ PHỎNG IFRS 9 NĂM 2025 (Tỷ đồng)
A12: Khoản mục phân tích | B12: Dư nợ EAD Agribank | C12: ECL ước tính Agribank | D12: Dư nợ EAD MB | E12: ECL ước tính MB | F12: Phương pháp & Ghi chú
A13: Stage 1: Nợ đủ tiêu chuẩn (Nhóm 1) | B13: 1925576 | C13: 8087 | D13: 1059763 | E13: 7153 | F13: EAD x PD(12m) x LGD
A14: Stage 2: Nợ có SICR (Nhóm 2 + Nợ cơ cấu) | B14: 35169 | C14: 22156 | D14: 11410 | E14: 11296 | F14: EAD x PD(Lifetime) x LGD
A15: Stage 3: Nợ xấu (Nhóm 3–5) | B15: 23124 | C15: 9250 | D15: 14027 | E15: 7014 | F15: EAD x 100% x LGD
A16: TỔNG DỰ PHÒNG ECL THEO IFRS 9 (A) | B16: 1983869 | C16: 39493 | D16: 1085200 | E16: 25463 | F16: Tổng dự phòng 3 giai đoạn
A17: TỔNG DỰ PHÒNG THEO VAS/TT11 HIỆN TẠI (B) | B17: 1976369 | C17: 33367 | D17: 1084000 | E17: 13185 | F17: Số dư quỹ dự phòng BCTC 2025
A18: CHÊNH LỆCH DỰ PHÒNG CẦN BỔ SUNG (GAP = A - B) | B18: 0 | C18: 6126 | D18: 0 | E18: 12278 | F18: Khoảng cách dự phòng trích thiếu
A19: Tỷ lệ thiếu hụt so với dự phòng hiện hành (%) | B19: 0 | C19: 0.184 | D19: 0 | E19: 0.931 | F19: Gap / Dự phòng hiện hành
A20: Vốn chủ sở hữu hiện hành (Equity 2025) | B20: 0 | C20: 125000 | D20: 0 | E20: 110000 | F20: Vốn CSH trên BCTC 2025
A21: Tác động khấu trừ vào Vốn CSH (sau thuế TNDN 20%) | B21: 0 | C21: -4901 | D21: 0 | E21: -9822 | F21: Gap x (1 - 20%)
A22: Tỷ lệ suy giảm Vốn chủ sở hữu (%) | B22: 0 | C22: -0.039 | D22: 0 | E22: -0.089 | F22: Khấu trừ / Vốn CSH
A23: Tỷ lệ CAR hiện hành theo Thông tư 41 (%) | B23: 0 | C23: 0.091 | D23: 0 | E23: 0.11 | F23: CAR công bố / ước tính 2025
A24: Tỷ lệ CAR sau khi áp dụng IFRS 9 (%) | B24: 0 | C24: 0.0885 | D24: 0 | E24: 0.1002 | F24: CAR sau khấu trừ vốn
A25: Mức suy giảm CAR (điểm phần trăm / bps) | B25: 0 | C25: -0.0025 | D25: 0 | E25: -0.0098 | F25: Chênh lệch điểm % CAR
A27: BẢNG 3: PHÂN TÍCH HỌC THUẬT VỀ TÁC ĐỘNG CHUYỂN ĐỔI IFRS 9
A28: 1. Cú sốc trích lập tại Stage 2: | B28: Dưới chuẩn IFRS 9, khi một khoản nợ bị xếp vào Stage 2 (SICR), ngân hàng phải trích lập dự phòng tổn thất trọn vòng đời (Lifetime ECL) thay vì chỉ trích 5% (trừ TSBĐ) như VAS. Điều này tạo ra khoảng cách trích lập khổng lồ tại MB (thiếu hụt tới 12.278 tỷ đồng, tương đương 93,1% quỹ dự phòng hiện hữu) do quy mô dư nợ tài chính tiêu dùng và TPDN lớn.
A29: 2. Tác động bất đối xứng đến CAR: | B29: MB bị sụt giảm CAR lên tới gần 100 bps (từ 11,0% xuống 10,02%) do LGD của danh mục không có TSBĐ cao (45% - 85%). Ngược lại, Agribank chỉ giảm khoảng 25 bps nhờ 89% - 91% dư nợ được bảo đảm bằng bất động sản nông thôn giúp giảm mạnh hệ số LGD (xuống ~35%).
A30: 3. Hàm ý chiến lược: | B30: Việc áp dụng IFRS 9 sẽ là phép thử khắc nghiệt đối với chiến lược tăng trưởng nóng của các NHTMCP đa năng; ngân hàng nào có tỷ trọng cho vay tín chấp và TPDN cao sẽ phải đối mặt với áp lực tiêu hao vốn rất lớn.
