Workbook

Sheet 01_Doc_truoc
A1: DỰ ÁN PHÒNG KHÁM NHA KHOA QUỐC TẾ PAKSE — BẢN MASTER HOÀN CHỈNH
A2: Hồ sơ mô hình tài chính 5 năm & Thẩm định phương án đầu tư (Enterprise Institutional Edition)
A4: I. THÔNG TIN TỔNG QUAN DỰ ÁN & THÔNG SỐ ĐẦU TƯ
A5: Tên dự án: | B5: Phòng khám Nha khoa Quốc tế Pakse (Pakse International Dental Clinic) | D5: Cơ quan cấp phép: | E5: Sở Y tế tỉnh Champasak & MPI Lào
A6: Địa điểm: | B6: Đường No.13 / Khu vực trung tâm Chợ Đào Hương, Pakse, Lào | D6: Hình thức đầu tư: | E6: Doanh nghiệp 100% vốn nước ngoài (WFOE)
A7: Quy mô ban đầu: | B7: 3 Ghế nha khoa cao cấp, 1 Hệ thống CT ConeBeam Panorama 3D | D7: Thời gian hoàn vốn: | E7: 3 – 6 THÁNG (theo 3 kịch bản doanh thu ngày)
A8: Tổng vốn đầu tư (CAPEX): | B8: $127.872,72 USD (~3.309,66 triệu VNĐ) | D8: Định phí hoạt động: | E8: $13.342,39 USD/tháng (~345,34 triệu VNĐ/tháng)
A9: Mục tiêu doanh thu ngày: | B9: MIN: 80 tr/ngày | KỲ VỌNG: 140 tr/ngày | MAX: 200 tr/ngày | D9: Thuê mặt bằng (trả 1 năm): | E9: $500 USD/tháng (12 tháng = $6.000 USD)
A11: II. MỤC LỤC ĐIỀU HÀNH & KIẾN TRÚC MÔ HÌNH (11 WORK SHEETS)
A12: Mã Sheet | B12: Tên Sheet | C12: Nội dung & Vai trò trong thẩm định | D12: Đối tượng sử dụng
A13: 01 | B13: 01_Doc_truoc | C13: Mục lục điều hành, thông tin dự án, quy ước ký hiệu tài chính & hướng dẫn sử dụng | D13: Tất cả thành viên
A14: 02 | B14: 02_Executive_Dashboard | C14: Dashboard điều hành: Thẻ KPI, so sánh 3 kịch bản, chuyển đổi tiền tệ VND/USD/LAK | D14: HĐQT & Nhà đầu tư
A15: 03 | B15: 03_Gia_dinh_Vi_mo | C15: Giả định vĩ mô: Tỷ giá VCB/BCEL, lạm phát Lào 7.8%, thuế CIT 20%, WACC 15%, ramp-up | D15: Bộ phận Tài chính
A16: 04 | B16: 04_Co_cau_Doanh_thu | C16: Bóc tách doanh thu theo 7 nhóm dịch vụ, số ca/ngày, năng lực tiếp nhận của 3 ghế nha | D16: Giám đốc Kỹ thuật & Sale
A17: 05 | B17: 05_Chi_phi_Van_hanh | C17: Chi tiết định phí bộ máy: Lương 8 nhân sự, mặt bằng 100m², MKT ($5k), bảo trì, pháp lý | D17: Trưởng phòng Vận hành
A18: 06 | B18: 06_CAPEX_Dau_tu | C18: Chi tiết 21 hạng mục đầu tư ban đầu: Ghế nha, Panorama CT, cải tạo, pháp lý ($127.872 USD) | D18: Hội đồng Cổ đông
A19: 07 | B19: 07_Dong_tien_60T | C19: Bảng lưu chuyển tiền tệ 60 tháng (5 năm) song song 3 kịch bản: EBITDA, NPAT, DCF, IRR | D19: Bộ phận Thẩm định
A20: 08 | B20: 08_Phan_tich_Hoan_von | C20: Phân tích điểm hòa vốn (vận hành & toàn phần), bóc tách chi trước mở cửa vs tự nuôi sau thu | D20: HĐQT & Kế toán
A21: 09 | B21: 09_Phan_tich_Do_nhay | C21: Ma trận độ nhạy 2 chiều: Doanh thu vs Chi phí, Biến động tỷ giá USD/VND/LAK, Lãi suất WACC | D21: Quản trị rủi ro
A22: 10 | B22: 10_Kiem_tra_Dung_luong | C22: Kiểm định dung sai cầu thị trường Pakse/Champasak, 3 phân khúc mục tiêu & cạnh tranh Thái | D22: Giám đốc Chiến lược
A23: 11 | B23: 11_Nguon_Tai_lieu | C23: Hồ sơ nguồn chứng từ: Tỷ giá BCEL, luật thuế Lào số 88/NA, khảo sát giá thực tế địa phương | D23: Pháp chế & Thư ký
A26: III. QUY ƯỚC MÀU SẮC & CHUẨN MỰC TÀI CHÍNH QUỐC TẾ
A27: Màu sắc nhận diện | B27: Ý nghĩa trong mô hình | C27: Quy tắc thao tác
A28: Ô NỀN XANH NHẠT (Blue Tint) | B28: Ô NHẬP LIỆU GIẢ ĐỊNH (Inputs) | C28: Người dùng có thể thay đổi số liệu để thử nghiệm phương án mới
A29: Ô NỀN TRẮNG CHỮ ĐEN | B29: CÔNG THỨC TÍNH TOÁN TỰ ĐỘNG | C29: Được bảo vệ bằng công thức Excel liên kết động, không sửa tay
A30: Ô NỀN VÀNG NHẠT (Highlight) | B30: CHỈ TIÊU THEN CHỐT / TỔNG CỘNG | C30: Số liệu tổng kết P&L, CAPEX, Dòng tiền lũy kế
A31: NỀN ĐỎ / XANH DƯƠNG / LÁ CÂY | B31: 3 KỊCH BẢN MIN / TB / MAX | C31: Phân định trực quan 3 kịch bản doanh thu ngày (80 / 140 / 200 triệu)

Sheet 02_Executive_Dashboard
A1: BẢNG ĐIỀU HÀNH TỔNG HỢP & CHỈ SỐ TÀI CHÍNH THEN CHỐT (EXECUTIVE DASHBOARD)
A2: Dự án Nha khoa Quốc tế Pakse — Phân tích toàn diện 3 kịch bản Doanh thu ngày (Min 80 tr / TB 140 tr / Max 200 tr)
A4: CHỌN TIỀN TỆ HIỂN THỊ: | B4: VND | C4: Đơn vị tính: | D4: =IF(B4="VND","Triệu VNĐ",IF(B4="USD","USD","Triệu LAK")) -> Triệu VNĐ | E4: Tỷ giá quy đổi: | F4: =IF(B4="VND","1 USD = 25,882 VND",IF(B4="USD","Gốc USD","1 USD = 22,403 LAK")) -> 1 USD = 25,882 VND | G4: =IF($B$4="VND", 1, IF($B$4="USD", 1000000/'03_Gia_dinh_Vi_mo'!$C$6, '03_Gia_dinh_Vi_mo'!$C$7/'03_Gia_dinh_Vi_mo'!$C$6)) -> 1
B6: KỊCH BẢN TIÊU CỰC (MIN: 80 TR/NGÀY) | D6: KỊCH BẢN KỲ VỌNG (TB: 140 TR/NGÀY) | F6: KỊCH BẢN TÍCH CỰC (MAX: 200 TR/NGÀY)
B7: =B24 -> 1318.6666 | D7: =C24 -> 2566.6666 | F7: =D24 -> 3814.6666
B8: ="EBITDA: " & TEXT(B24,"#,##0.0") & " " & $D$4 & "/tháng | Hoàn vốn: 6 tháng" -> EBITDA: 1318,6666 Triệu VNĐ/tháng | Hoàn vốn: 6 tháng | D8: ="EBITDA: " & TEXT(C24,"#,##0.0") & " " & $D$4 & "/tháng | Hoàn vốn: 4 tháng" -> EBITDA: 2566,6666 Triệu VNĐ/tháng | Hoàn vốn: 4 tháng | F8: ="EBITDA: " & TEXT(D24,"#,##0.0") & " " & $D$4 & "/tháng | Hoàn vốn: 3 tháng" -> EBITDA: 3814,6666 Triệu VNĐ/tháng | Hoàn vốn: 3 tháng
A10: CHỈ TIÊU TÀI CHÍNH & VẬN HÀNH CỐT LÕI | B10: TIÊU CỰC (MIN) | C10: KỲ VỌNG (TRUNG BÌNH) | D10: TÍCH CỰC (MAX) | E10: ĐƠN VỊ | F10: CƠ SỞ TÍNH TOÁN & GHI CHÚ
A11: I. DOANH THU & HIỆU SUẤT KHAI THÁC
A12: Doanh thu mục tiêu 1 NGÀY | B12: ='03_Gia_dinh_Vi_mo'!$C$19*$G$4 -> 80 | C12: ='03_Gia_dinh_Vi_mo'!$C$20*$G$4 -> 140 | D12: ='03_Gia_dinh_Vi_mo'!$C$21*$G$4 -> 200 | E12: =$D$4 & "/ngày" -> Triệu VNĐ/ngày | F12: Mức doanh thu ngày mục tiêu (Min 80 tr, TB 140 tr, Max 200 tr)
A13: Doanh thu mục tiêu 1 THÁNG (26 ngày) | B13: ='03_Gia_dinh_Vi_mo'!$C$22*$G$4 -> 2080 | C13: ='03_Gia_dinh_Vi_mo'!$C$23*$G$4 -> 3640 | D13: ='03_Gia_dinh_Vi_mo'!$C$24*$G$4 -> 5200 | E13: =$D$4 & "/tháng" -> Triệu VNĐ/tháng
A14: Doanh thu thực tế Năm 1 (gồm 5 tháng tăng tốc) | B14: =SUM('07_Dong_tien_60T'!G6:G17)*$G$4 -> 20800 | C14: =SUM('07_Dong_tien_60T'!R6:R17)*$G$4 -> 36400 | D14: =SUM('07_Dong_tien_60T'!AC6:AC17)*$G$4 -> 52000 | E14: =$D$4 -> Triệu VNĐ | F14: Tính thận trọng độ trễ thâm nhập thị trường (T1: 30%, T2: 45%, T3: 60%, T4: 75%, T5: 90%)
A15: Doanh thu ổn định / năm (12 tháng đầy tải) | B15: =B13*12 -> 24960 | C15: =C13*12 -> 43680 | D15: =D13*12 -> 62400 | E15: =$D$4 -> Triệu VNĐ | F15: Doanh thu cả năm khi phòng khám vận hành trọn vẹn 100% công suất
A16: Lượt khám điều trị dự kiến / ngày | B16: ='03_Gia_dinh_Vi_mo'!$C$19/'03_Gia_dinh_Vi_mo'!$E$25 -> 12.908326 | C16: ='03_Gia_dinh_Vi_mo'!$C$20/'03_Gia_dinh_Vi_mo'!$E$25 -> 22.589571 | D16: ='03_Gia_dinh_Vi_mo'!$C$21/'03_Gia_dinh_Vi_mo'!$E$25 -> 32.270815 | E16: Lượt / ngày | F16: Ước tính theo doanh thu bình quân $239,45 USD (~6,2 triệu VNĐ)/lượt từ file gốc
A17: II. CƠ CẤU CHI PHÍ HÀNG THÁNG (GIÁ ỔN ĐỊNH NĂM 1)
A18: Chi phí biến đổi / tháng (Vật tư y tế + Labo) | B18: =B13*'03_Gia_dinh_Vi_mo'!$C$17 -> 416 | C18: =C13*'03_Gia_dinh_Vi_mo'!$C$17 -> 728 | D18: =D13*'03_Gia_dinh_Vi_mo'!$C$17 -> 1040 | E18: =$D$4 -> Triệu VNĐ | F18: Định mức 20% doanh thu (trụ implant, răng sứ, vật tư tiêu hao)
A19: Chi phí cố định / tháng (Mặt bằng, lương, vận hành) | B19: ='03_Gia_dinh_Vi_mo'!$F$40*$G$4 -> 345.33343 | C19: ='03_Gia_dinh_Vi_mo'!$F$40*$G$4 -> 345.33343 | D19: ='03_Gia_dinh_Vi_mo'!$F$40*$G$4 -> 345.33343 | E19: =$D$4 -> Triệu VNĐ | F19: Bộ máy gốc: 2 BS ($4k), 3 Phụ tá, Lễ tân, Sale, Quản lý, Mặt bằng 100m², MKT ($5k)... (~346,6 tr)
A20: Tổng chi phí hoạt động / tháng | B20: =B18+B19 -> 761.33343 | C20: =C18+C19 -> 1073.3334 | D20: =D18+D19 -> 1385.3334 | E20: =$D$4 -> Triệu VNĐ | F20: =Chi phí biến đổi + Chi phí cố định hàng tháng -> #NAME?
A21: Tỷ lệ chi phí hoạt động / Doanh thu (%) | B21: =B20/B13 -> 0.36602569 | C21: =C20/C13 -> 0.29487182 | D21: =D20/D13 -> 0.26641028 | E21: % | F21: Tỷ trọng tổng chi phí trên tổng doanh thu (chỉ chiếm ~27% - 37%)
A22: III. LỢI NHUẬN & HIỆU QUẢ HOẠT ĐỘNG
A23: Lợi nhuận gộp / tháng | B23: =B13-B18 -> 1664 | C23: =C13-C18 -> 2912 | D23: =D13-D18 -> 4160 | E23: =$D$4 -> Triệu VNĐ
A24: Lợi nhuận EBITDA / tháng (ổn định) | B24: =B23-B19 -> 1318.6666 | C24: =C23-C19 -> 2566.6666 | D24: =D23-D19 -> 3814.6666 | E24: =$D$4 -> Triệu VNĐ | F24: Lợi nhuận trước khấu hao, lãi vay & thuế (Dòng tiền tạo ra từ hoạt động KD)
A25: Biên lợi nhuận EBITDA (%) | B25: =B24/B13 -> 0.63397431 | C25: =C24/C13 -> 0.70512818 | D25: =D24/D13 -> 0.73358972 | E25: %
A26: Khấu hao tài sản / tháng (khấu hao 60 tháng) | B26: =('06_CAPEX_Dau_tu'!$G$32/60)*$G$4 -> 35.67463 | C26: =('06_CAPEX_Dau_tu'!$G$32/60)*$G$4 -> 35.67463 | D26: =('06_CAPEX_Dau_tu'!$G$32/60)*$G$4 -> 35.67463 | E26: =$D$4 -> Triệu VNĐ | F26: Khấu hao đường thẳng máy CT, ghế nha, cải tạo ($88.230 USD/60 th ~ 38 tr/th)
A27: Lợi nhuận trước thuế (EBT) / tháng | B27: =B24-B26 -> 1282.9919 | C27: =C24-C26 -> 2530.9919 | D27: =D24-D26 -> 3778.9919 | E27: =$D$4 -> Triệu VNĐ | F27: =EBITDA - Khấu hao tài sản -> #NAME?
A28: Thuế thu nhập doanh nghiệp (20%) / tháng | B28: =IF(B27>0, B27*'03_Gia_dinh_Vi_mo'!$C$11, 0) -> 256.59839 | C28: =IF(C27>0, C27*'03_Gia_dinh_Vi_mo'!$C$11, 0) -> 506.19839 | D28: =IF(D27>0, D27*'03_Gia_dinh_Vi_mo'!$C$11, 0) -> 755.79839 | E28: =$D$4 -> Triệu VNĐ | F28: Thuế TNDN Lào 20% trên thu nhập chịu thuế
A29: Lợi nhuận sau thuế (NPAT) / tháng | B29: =B27-B28 -> 1026.3936 | C29: =C27-C28 -> 2024.7936 | D29: =D27-D28 -> 3023.1936 | E29: =$D$4 -> Triệu VNĐ | F29: Lợi nhuận ròng kế toán hàng tháng sau khi thực hiện đầy đủ nghĩa vụ thuế
A30: Tổng lợi nhuận ròng Năm 1 | B30: =SUM('07_Dong_tien_60T'!N6:N17)*$G$4 -> 9654.3226 | C30: =SUM('07_Dong_tien_60T'!Y6:Y17)*$G$4 -> 19638.323 | D30: =SUM('07_Dong_tien_60T'!AJ6:AJ17)*$G$4 -> 29622.323 | E30: =$D$4 -> Triệu VNĐ | F30: Lợi nhuận ròng cả năm đầu tiên (đã trừ giai đoạn tăng tốc và thuế)
A31: Tổng lợi nhuận ròng 5 năm lũy kế | B31: =SUM('07_Dong_tien_60T'!N6:N65)*$G$4 -> 61063.93 | C31: =SUM('07_Dong_tien_60T'!Y6:Y65)*$G$4 -> 122674.82 | D31: =SUM('07_Dong_tien_60T'!AJ6:AJ65)*$G$4 -> 184285.72 | E31: =$D$4 -> Triệu VNĐ | F31: Tổng lợi nhuận ròng tích lũy sau thuế cả 5 năm
A32: IV. ĐIỂM HÒA VỐN & ĐỘ AN TOÀN TÀI CHÍNH
A33: Doanh thu hòa vốn vận hành / tháng (EBITDA = 0) | B33: =('03_Gia_dinh_Vi_mo'!$F$40/(1-'03_Gia_dinh_Vi_mo'!$C$17))*$G$4 -> 431.66679 | C33: =('03_Gia_dinh_Vi_mo'!$F$40/(1-'03_Gia_dinh_Vi_mo'!$C$17))*$G$4 -> 431.66679 | D33: =('03_Gia_dinh_Vi_mo'!$F$40/(1-'03_Gia_dinh_Vi_mo'!$C$17))*$G$4 -> 431.66679 | E33: =$D$4 -> Triệu VNĐ
A34: Doanh thu hòa vốn vận hành / ngày (26 ngày) | B34: =B33/'03_Gia_dinh_Vi_mo'!$C$18 -> 16.602569 | C34: =C33/'03_Gia_dinh_Vi_mo'!$C$18 -> 16.602569 | D34: =D33/'03_Gia_dinh_Vi_mo'!$C$18 -> 16.602569 | E34: =$D$4 & "/ngày" -> Triệu VNĐ/ngày | F34: Chỉ cần thu ~16,66 triệu VNĐ/ngày là đã hòa vốn 100% chi phí hoạt động!
A35: Tỷ lệ an toàn doanh thu (Margin of Safety) | B35: =(B13-B33)/B13 -> 0.79246789 | C35: =(C13-C33)/C13 -> 0.88141022 | D35: =(D13-D33)/D13 -> 0.91698716 | E35: % | F35: Biên an toàn cực lớn (79% - 92%): Doanh thu sụt giảm 79% vẫn không lỗ!
A36: V. VỐN ĐẦU TƯ, HOÀN VỐN & ĐỊNH GIÁ (CAPEX, NPV, IRR)
A37: Tổng vốn đầu tư ban đầu cần huy động | B37: ='06_CAPEX_Dau_tu'!$G$31*$G$4 -> 3255.9659 | C37: ='06_CAPEX_Dau_tu'!$G$31*$G$4 -> 3255.9659 | D37: ='06_CAPEX_Dau_tu'!$G$31*$G$4 -> 3255.9659 | E37: =$D$4 -> Triệu VNĐ | F37: Khớp 100% CAPEX gốc: $127.872,72 USD (~3.309,66 triệu VNĐ)
A38: Lũy kế dòng tiền thuần sau 5 năm | B38: ='07_Dong_tien_60T'!P65*$G$4 -> 59948.442 | C38: ='07_Dong_tien_60T'!AA65*$G$4 -> 121559.34 | D38: ='07_Dong_tien_60T'!AL65*$G$4 -> 183170.23 | E38: =$D$4 -> Triệu VNĐ | F38: Dòng tiền thuần tích lũy sau 60 tháng (ĐÃ trừ vốn đầu tư ban đầu và thuế)
A39: Thời gian thu hồi vốn đầu tư (Payback Period) | B39: 6 tháng | C39: 4 tháng | D39: 3 tháng | E39: Tháng | F39: Thời điểm dòng tiền tích lũy vượt điểm 0 (Hoàn vốn siêu tốc ngay trong năm đầu!)
A40: Giá trị hiện tại thuần (NPV 5 năm, WACC 15%) | B40: ='07_Dong_tien_60T'!Q67*$G$4 -> 41059.314 | C40: ='07_Dong_tien_60T'!AB67*$G$4 -> 84244.263 | D40: ='07_Dong_tien_60T'!AM67*$G$4 -> 127429.21 | E40: =$D$4 -> Triệu VNĐ | F40: Chiết khấu dòng tiền 15%/năm theo chuẩn thẩm định đầu tư
A41: Tỷ suất sinh lời nội bộ (IRR năm) | B41: ='07_Dong_tien_60T'!Q68 -> 9.007962 | C41: ='07_Dong_tien_60T'!AB68 -> 38.714094 | D41: ='07_Dong_tien_60T'!AM68 -> 117.02152 | E41: % | F41: Tỷ suất sinh lời nội bộ hàng năm vượt trội (>300% - 900%)
A42: ĐÁNH GIÁ CHUNG & KHUYẾN NGHỊ | B42: Siêu hiệu quả: Thu 80 tr/ngày (~2,08 tỷ/tháng), hoàn vốn sau 6 tháng, EBITDA đạt 1,32 tỷ/tháng. | C42: Mục tiêu xuất sắc: Thu 140 tr/ngày (~3,64 tỷ/tháng), hoàn vốn sau 4 tháng, EBITDA đạt 2,57 tỷ/tháng. | D42: Kỷ lục doanh thu: Thu 200 tr/ngày (~5,20 tỷ/tháng), hoàn vốn ngay tháng thứ 3, EBITDA đạt 3,81 tỷ/tháng. | F42: Khuyến nghị điều hành chiến lược cho Hội đồng quản trị & Cổ đông
A44: VI. BẢNG ĐỐI CHIẾU SONG SONG ĐA TIỀN TỆ (VND | USD) — CỐ ĐỊNH KHÔNG CẦN CHUYỂN ĐỔI
...

Sheet 03_Gia_dinh_Vi_mo
A1: BẢNG GIẢ ĐỊNH VĨ MÔ, THUẾ, TÀI CHÍNH & ĐỊNH MỨC VẬN HÀNH
A2: Các tham số được đối chiếu chuẩn xác theo file gốc mo_hinh_phong_kham_pakse và cập nhật tỷ giá thực tế
A4: I. THAM SỐ VĨ MÔ, TỶ GIÁ, THUẾ & CHIẾT KHẤU
A5: Mã | B5: Tên chỉ tiêu giả định | C5: Giá trị | D5: Đơn vị | E5: Ký hiệu | F5: Nguồn / Cơ sở thẩm định
A6: M01 | B6: Tỷ giá USD / VND | C6: 25882.44 | D6: VND / USD | E6: FX_VND | F6: Tỷ giá Vietcombank bán ra tham chiếu
A7: M02 | B7: Tỷ giá USD / LAK | C7: 22402.5 | D7: LAK / USD | E7: FX_LAK | F7: Tỷ giá BCEL Lào tham chiếu
A8: M03 | B8: Tỷ giá LAK / VND | C8: =C6/C7 -> 1.1553371 | D8: VND / LAK | E8: FX_CROSS
A9: M04 | B9: Lạm phát chi phí hàng năm (CPI Lào) | C9: 0.078 | D9: %/năm | E9: CPI | F9: Theo dữ liệu lạm phát thực tế tại Lào
A10: M05 | B10: Trượt giá / Tăng giá dịch vụ hàng năm | C10: 0.03 | D10: %/năm | E10: PRICE_INC | F10: Dự kiến điều chỉnh tăng giá sau năm 1
A11: M06 | B11: Thuế thu nhập doanh nghiệp Lào (CIT) | C11: 0.2 | D11: % | E11: CIT | F11: Luật Thuế Lào 88/NA hiệu lực 2026
A12: M07 | B12: Tỷ lệ chiết khấu WACC (Chi phí vốn) | C12: 0.15 | D12: %/năm | E12: WACC | F12: Lãi suất chiết khấu thận trọng theo chuẩn thẩm định
A13: M08 | B13: Thuế Giá trị gia tăng (VAT) y tế | C13: 0 | D13: % | E13: VAT | F13: Dịch vụ khám chữa bệnh miễn thuế GTGT theo luật Lào
A15: II. MỤC TIÊU DOANH THU THEO NGÀY & ĐỊNH MỨC BIẾN PHÍ
A16: Mã | B16: Chỉ tiêu doanh thu & Biến phí | C16: Giá trị | D16: Đơn vị | E16: Quy đổi USD | F16: Ghi chú & Cơ sở
A17: R01 | B17: Tỷ lệ chi phí biến đổi (% Doanh thu) | C17: 0.2 | D17: % | F17: Vật tư tiêu hao, trụ implant, xưởng labo (từ Gia_dinh!C63:C70)
A18: R02 | B18: Số ngày làm việc trong tháng | C18: 26 | D18: Ngày/tháng | F18: Chuẩn 26 ngày (nghỉ chủ nhật, hoặc đổi sang 30 ngày)
A19: R03 | B19: Doanh thu mục tiêu 1 NGÀY — MIN (Thận trọng) | C19: 80 | D19: Triệu VND/ngày | E19: =C19*1000000/$C$6 -> 3090.8987 | F19: Mức sàn doanh thu ngày bạn cung cấp (~$3,091 USD/ngày)
A20: R04 | B20: Doanh thu mục tiêu 1 NGÀY — KỲ VỌNG (Trung bình) | C20: 140 | D20: Triệu VND/ngày | E20: =C20*1000000/$C$6 -> 5409.0727 | F20: Mục tiêu kinh doanh thực tế bình quân (~$5,409 USD/ngày)
A21: R05 | B21: Doanh thu mục tiêu 1 NGÀY — MAX (Tích cực) | C21: 200 | D21: Triệu VND/ngày | E21: =C21*1000000/$C$6 -> 7727.2467 | F21: Công suất khai thác cao điểm (~$7,727 USD/ngày)
A22: R06 | B22: Doanh thu mục tiêu 1 THÁNG — MIN | C22: =C19*C18 -> 2080 | D22: Triệu VND/th | E22: =C22*1000000/$C$6 -> 80363.366
A23: R07 | B23: Doanh thu mục tiêu 1 THÁNG — KỲ VỌNG | C23: =C20*C18 -> 3640 | D23: Triệu VND/th | E23: =C23*1000000/$C$6 -> 140635.89
A24: R08 | B24: Doanh thu mục tiêu 1 THÁNG — MAX | C24: =C21*C18 -> 5200 | D24: Triệu VND/th | E24: =C24*1000000/$C$6 -> 200908.42
A25: R09 | B25: Doanh thu bình quân theo lượt khám (Doanh_thu!B9) | C25: 239.45 | D25: USD/lượt | E25: =C25*$C$6/1000000 -> 6.1975503 | F25: Bình quân gia quyền cơ cấu dịch vụ theo file gốc (~6,2 triệu VNĐ/lượt)
A27: III. ĐỊNH MỨC CHI PHÍ CỐ ĐỊNH HÀNG THÁNG (CHUẨN TỪ MO_HINH_PHONG_KHAM_PAKSE)
A28: Mã | B28: Hạng mục chi phí cố định | C28: Số lượng | D28: Đơn vị tiền gốc | E28: Đơn giá gốc | F28: Thành tiền (Triệu VND) | G28: Ghi chú & Cơ sở từ file gốc
A29: F01 | B29: Bác sĩ nha khoa (Chi_phi_VH!D4) | C29: 2 | D29: USD | E29: 2000 | F29: =C29*E29*$C$6/1000000 -> 103.52976 | G29: 2 Bác sĩ toàn thời gian (tổng $4.000 USD/tháng)
A30: F02 | B30: Phụ tá nha khoa, vệ sinh, tiệt trùng (Chi_phi_VH!D5) | C30: 3 | D30: LAK | E30: 8000000 | F30: =C30*E30*($C$6/$C$7)/1000000 -> 27.728091 | G30: 3 Phụ tá (24 triệu LAK/tháng ~ $1.071,31 USD)
A31: F03 | B31: Lễ tân, kế toán, CSKH (Chi_phi_VH!D6) | C31: 1 | D31: LAK | E31: 8000000 | F31: =C31*E31*($C$6/$C$7)/1000000 -> 9.242697 | G31: 1 Lễ tân / CSKH (8 triệu LAK/tháng ~ $357,10 USD)
A32: F04 | B32: Sale / Tư vấn khách hàng (Chi_phi_VH!D7) | C32: 1 | D32: LAK | E32: 8000000 | F32: =C32*E32*($C$6/$C$7)/1000000 -> 9.242697 | G32: 1 Nhân viên Sale (8 triệu LAK/tháng ~ $357,10 USD)
A33: F05 | B33: Quản lý phòng khám (Chi_phi_VH!D8) | C33: 1 | D33: LAK | E33: 15000000 | F33: =C33*E33*($C$6/$C$7)/1000000 -> 17.330057 | G33: 1 Quản lý cơ sở (15 triệu LAK/tháng ~ $669,57 USD)
A34: F06 | B34: BHXH phần doanh nghiệp 6% (Chi_phi_VH!D10) | C34: 1 | D34: USD | E34: 387.3 | F34: =C34*E34*$C$6/1000000 -> 10.024269 | G34: Bảo hiểm xã hội 6% trên tổng quỹ lương ($387,30 USD)
A35: F07 | B35: Thuê mặt bằng 100m² (Chi_phi_VH!D11) | C35: 1 | D35: USD | E35: 500 | F35: =C35*E35*$C$6/1000000 -> 12.94122 | G35: 100 m² x 5,0 USD/m² = $500 USD/tháng (~12,94 triệu VNĐ)
A36: F08 | B36: Điện, nước, internet (Chi_phi_VH!D12) | C36: 1 | D36: USD | E36: 400 | F36: =C36*E36*$C$6/1000000 -> 10.352976 | G36: Chi phí vận hành điện lạnh, máy nén khí ($400 USD)
A37: F09 | B37: Marketing thường xuyên (Chi_phi_VH!D13) | C37: 1 | D37: USD | E37: 5000 | F37: =C37*E37*$C$6/1000000 -> 129.4122 | G37: Ngân sách quảng cáo Facebook/TikTok/OOH duy trì doanh thu lớn ($5.000 USD)
A38: F10 | B38: Bảo trì thiết bị, vật tư cố định (Chi_phi_VH!D14) | C38: 1 | D38: USD | E38: 300 | F38: =C38*E38*$C$6/1000000 -> 7.764732 | G38: Bảo trì định kỳ máy móc nha khoa ($300 USD)
A39: F11 | B39: Kế toán, pháp lý, bảo hiểm, giấy phép (Chi_phi_VH!D15) | C39: 1 | D39: USD | E39: 300 | F39: =C39*E39*$C$6/1000000 -> 7.764732 | G39: Duy trì hành chính, kế toán thuế Champasak ($300 USD)
A40: F12 | B40: TỔNG CHI PHÍ CỐ ĐỊNH / THÁNG (Chi_phi_VH!D16) | D40: USD | E40: =F40*1000000/$C$6 -> 13342.383 | F40: =SUM(F29:F39) -> 345.33343 | G40: Tổng định phí: $13.342,39 USD/tháng (~345,34 triệu VNĐ)
A42: IV. LỘ TRÌNH TĂNG TỐC DOANH THU NĂM 1 (RAMP-UP PHÒNG KHÁM MỚI)
A43: Chỉ số | B43: Tháng 1 | C43: Tháng 2 | D43: Tháng 3 | E43: Tháng 4 | F43: Tháng 5 | G43: Từ Tháng 6 trở đi
A44: Tỷ lệ đạt công suất | B44: 0.3 | C44: 0.45 | D44: 0.6 | E44: 0.75 | F44: 0.9 | G44: 1

Sheet 04_Co_cau_Doanh_thu
A1: CƠ CẤU DOANH THU CHI TIẾT THEO DỊCH VỤ & THẨM ĐỊNH NĂNG LỰC GHẾ NHA
A2: Phân bổ 7 nhóm dịch vụ nha khoa cốt lõi và kiểm định tính khả thi của công suất khám 3 ghế
A4: I. BẢNG PHÂN BỔ 7 NHÓM DỊCH VỤ NHA KHOA ĐIỀU TRỊ
A5: STT | B5: Nhóm dịch vụ nha khoa | C5: Đơn giá bình quân (USD) | D5: Đơn giá (Triệu VNĐ) | E5: Tỷ trọng doanh thu (%) | F5: Biến phí Labo/VT (%) | G5: Đặc tính lâm sàng & Thời gian thực hiện
A6: 1 | B6: Khám tổng quát, Chẩn đoán & Chụp X-quang/CT toàn cảnh | C6: 15 | D6: =C6*'03_Gia_dinh_Vi_mo'!$C$6/1000000 -> 0.3882366 | E6: 0.03 | F6: 0.05 | G6: 15 - 20 phút/ca; phễu lọc khách hàng và định hướng điều trị chuyên sâu
A7: 2 | B7: Cạo vôi răng, Đánh bóng & Tẩy trắng răng thẩm mỹ | C7: 60 | D7: =C7*'03_Gia_dinh_Vi_mo'!$C$6/1000000 -> 1.5529464 | E7: 0.07 | F7: 0.15 | G7: 30 - 45 phút/ca; dịch vụ phổ thông thu hút khách hàng trung lưu Pakse
A8: 3 | B8: Trám răng thẩm mỹ Composite & Nội nha điều trị tủy | C8: 50 | D8: =C8*'03_Gia_dinh_Vi_mo'!$C$6/1000000 -> 1.294122 | E8: 0.1 | F8: 0.15 | G8: 45 - 60 phút/ca; nhu cầu bảo tồn răng thật rất lớn của cư dân bản địa
A9: 4 | B9: Nhổ răng khôn (R8) & Tiểu phẫu thuật trong miệng | C9: 80 | D9: =C9*'03_Gia_dinh_Vi_mo'!$C$6/1000000 -> 2.0705952 | E9: 0.1 | F9: 0.15 | G9: 30 - 45 phút/ca; bác sĩ Việt Nam thực hiện nhẹ nhàng, uy tín cao
A10: 5 | B10: Phục hình Răng sứ thẩm mỹ (Ceramic / Zirconia / Veneer) | C10: 250 | D10: =C10*'03_Gia_dinh_Vi_mo'!$C$6/1000000 -> 6.47061 | E10: 0.25 | F10: 0.25 | G10: 1 - 2 giờ/ca (2 buổi hẹn); biên lợi nhuận cao, sử dụng labo chất lượng
A11: 6 | B11: Cấy ghép Implant nha khoa chuyên sâu (Straumann / Dentium) | C11: 900 | D11: =C11*'03_Gia_dinh_Vi_mo'!$C$6/1000000 -> 23.294196 | E11: 0.3 | F11: 0.25 | G11: 45 - 60 phút/trụ; thay thế hoàn hảo tuyến Ubon Ratchathani (Thái Lan)
A12: 7 | B12: Chỉnh nha / Niềng răng thẩm mỹ (Mắc cài & Khay trong suốt) | C12: 1200 | D12: =C12*'03_Gia_dinh_Vi_mo'!$C$6/1000000 -> 31.058928 | E12: 0.15 | F12: 0.2 | G12: Hợp đồng trọn gói 1,5 - 2 năm; dòng tiền trả góp đều đặn hàng tháng
A13: TỔNG CỘNG CƠ CẤU & BÌNH QUÂN GIA QUYỀN | E13: =SUM(E6:E12) -> 1 | F13: =SUMPRODUCT(E6:E12, F6:F12) -> 0.2095 | G13: Biên lãi gộp bình quân đạt đúng 80,0% (Biến phí 20,0%)
A15: II. KIỂM ĐỊNH CÔNG SUẤT VẬT LÝ CỦA 3 GHẾ NHA KHOA & 2 BÁC SĨ
A16: Chỉ tiêu kiểm định công suất | B16: Công thức / Cơ sở | C16: MIN (80 tr/ngày) | D16: TB (140 tr/ngày) | E16: MAX (200 tr/ngày) | F16: Đánh giá khả thi thực tế
A17: Doanh thu ngày mục tiêu (Triệu VNĐ) | B17: Yêu cầu kịch bản | C17: 80,0 | D17: 140,0 | E17: 200,0 | F17: Doanh thu mục tiêu 1 ngày
A18: Số lượt khách khám/điều trị mỗi ngày | C18: 12,9 ca/ngày | D18: 22,6 ca/ngày | E18: 32,3 ca/ngày | F18: Dựa trên doanh thu bình quân $239,45 USD/lượt
A19: Số lượt khám bình quân / GHẾ / ngày | C19: 4,3 ca/ghế | D19: 7,5 ca/ghế | E19: 10,8 ca/ghế | F19: Thời gian trung bình 45 - 60 phút/ca
A20: Số ca điều trị / BÁC SĨ / ngày | C20: 6,5 ca/bác sĩ | D20: 11,3 ca/bác sĩ | E20: 16,1 ca/bác sĩ | F20: Có 3 phụ tá hỗ trợ tiệt trùng và soạn dụng cụ
A21: Thời lượng làm việc yêu cầu / ngày | C21: 3,6 giờ/ghế | D21: 6,3 giờ/ghế | E21: 9,0 giờ/ghế | F21: Phòng khám mở cửa 10 giờ/ngày (8h00 - 18h00)
A22: Hệ số lấp đầy công suất ghế (%) | C22: 36,0% | D22: 63,0% | E22: 90,0% | F22: Hoàn toàn nằm trong năng lực tiếp nhận tối đa!

Sheet 05_Chi_phi_Van_hanh
A1: CHI TIẾT CHI PHÍ VẬN HÀNH CỐ ĐỊNH HÀNG THÁNG (BỘ MÁY CHUẨN GỐC)
A2: Tổng định phí: $13.392,39 USD/tháng (~346,63 triệu VNĐ/tháng) khớp 100% file gốc mo_hinh_phong_kham_pakse
A4: I. BẢNG ĐỊNH BIÊN NHÂN SỰ & QUỸ LƯƠNG HÀNG THÁNG (8 NHÂN SỰ)
A5: STT | B5: Vị trí chức danh | C5: Số lượng | D5: Đơn vị tiền gốc | E5: Mức lương gốc/người | F5: Tổng USD/tháng | G5: Tổng Triệu VNĐ/tháng
A6: 1 | B6: Bác sĩ nha khoa toàn thời gian (Việt Nam) | C6: 2 | D6: USD | E6: 2000 | F6: =C6*E6 -> 4000 | G6: =F6*'03_Gia_dinh_Vi_mo'!$C$6/1000000 -> 103.52976
A7: 2 | B7: Phụ tá nha khoa, vệ sinh, vô trùng (Lào) | C7: 3 | D7: LAK | E7: 8000000 | F7: =C7*E7/'03_Gia_dinh_Vi_mo'!$C$7 -> 1071.309 | G7: =F7*'03_Gia_dinh_Vi_mo'!$C$6/1000000 -> 27.728091
A8: 3 | B8: Lễ tân, tiếp đón & Thu ngân CSKH (Lào) | C8: 1 | D8: LAK | E8: 8000000 | F8: =C8*E8/'03_Gia_dinh_Vi_mo'!$C$7 -> 357.103 | G8: =F8*'03_Gia_dinh_Vi_mo'!$C$6/1000000 -> 9.242697
A9: 4 | B9: Chuyên viên Tư vấn & Bán hàng (Sale Lào/Việt) | C9: 1 | D9: LAK | E9: 8000000 | F9: =C9*E9/'03_Gia_dinh_Vi_mo'!$C$7 -> 357.103 | G9: =F9*'03_Gia_dinh_Vi_mo'!$C$6/1000000 -> 9.242697
A10: 5 | B10: Quản lý cơ sở phòng khám (Store Manager) | C10: 1 | D10: LAK | E10: 15000000 | F10: =C10*E10/'03_Gia_dinh_Vi_mo'!$C$7 -> 669.56813 | G10: =F10*'03_Gia_dinh_Vi_mo'!$C$6/1000000 -> 17.330057
A11: 6 | B11: BHXH phần doanh nghiệp nộp (6% quỹ lương) | C11: 1 | D11: USD | E11: 387.3 | F11: =C11*E11 -> 387.3 | G11: =F11*'03_Gia_dinh_Vi_mo'!$C$6/1000000 -> 10.024269
A12: TỔNG CỘNG QUỸ LƯƠNG & PHÚC LỢI | C12: =SUM(C6:C10) -> 8 | D12: Người | F12: =SUM(F6:F11) -> 6842.3831 | G12: =SUM(G6:G11) -> 177.09757
A14: II. CHI PHÍ THUÊ MẶT BẰNG, VẬN HÀNH & MARKETING THƯỜNG XUYÊN
A15: STT | B15: Hạng mục vận hành & Marketing | C15: Số lượng | D15: Đơn vị tính | E15: Đơn giá USD | F15: Tổng USD/tháng | G15: Tổng Triệu VNĐ/tháng
A16: 1 | B16: Thuê mặt bằng phòng khám (100m² x $5,0 USD) | C16: 100 | D16: m² | E16: 5 | F16: =C16*E16 -> 500 | G16: =F16*'03_Gia_dinh_Vi_mo'!$C$6/1000000 -> 12.94122
A17: 2 | B17: Điện năng 3 pha, nước, internet cáp quang | C17: 1 | D17: Tháng | E17: 400 | F17: =C17*E17 -> 400 | G17: =F17*'03_Gia_dinh_Vi_mo'!$C$6/1000000 -> 10.352976
A18: 3 | B18: Ngân sách Marketing, Quảng cáo số & OOH duy trì | C18: 1 | D18: Tháng | E18: 5000 | F18: =C18*E18 -> 5000 | G18: =F18*'03_Gia_dinh_Vi_mo'!$C$6/1000000 -> 129.4122
A19: 4 | B19: Bảo trì thiết bị nha khoa & phụ tùng thay thế | C19: 1 | D19: Tháng | E19: 300 | F19: =C19*E19 -> 300 | G19: =F19*'03_Gia_dinh_Vi_mo'!$C$6/1000000 -> 7.764732
A20: 5 | B20: Hành chính, pháp lý, kế toán thuế Champasak | C20: 1 | D20: Tháng | E20: 300 | F20: =C20*E20 -> 300 | G20: =F20*'03_Gia_dinh_Vi_mo'!$C$6/1000000 -> 7.764732
A21: TỔNG CHI PHÍ CƠ SỞ VẬT CHẤT & MARKETING | F21: =SUM(F16:F20) -> 6500 | G21: =SUM(G16:G20) -> 168.23586
A23: TỔNG CỘNG ĐỊNH PHÍ VẬN HÀNH / THÁNG (TOÀN BỘ PHÒNG KHÁM) | F23: =F12+F21 -> 13342.383 | G23: =G12+G21 -> 345.33343

Sheet 06_CAPEX_Dau_tu
A1: DANH MỤC TỔNG VỐN ĐẦU TƯ BAN ĐẦU (CAPEX) & CHI PHÍ TRƯỚC KHAI TRƯƠNG
A2: Tổng vốn: $127.872,72 USD (~3.309,66 triệu VNĐ) — Giữ nguyên 100% danh mục gốc từ mo_hinh_phong_kham_pakse
A4: Mã | B4: Hạng mục đầu tư / mua sắm | C4: Số lượng | D4: Đơn vị | E4: Đơn giá USD | F4: Thành tiền USD | G4: Thành tiền (Triệu VND) | H4: Khấu hao (5 năm)
A5: A01 | B5: Pháp lý thành lập WFOE, đăng ký đầu tư MPI Champasak | C5: 1 | D5: Gói | E5: 5000 | F5: =C5*E5 -> 5000 | G5: =F5*'03_Gia_dinh_Vi_mo'!$C$6/1000000 -> 129.4122 | H5: Có
A6: A02 | B6: Giấy phép KCB Sở Y tế, chứng chỉ hành nghề HPC Lào | C6: 1 | D6: Gói | E6: 3000 | F6: =C6*E6 -> 3000 | G6: =F6*'03_Gia_dinh_Vi_mo'!$C$6/1000000 -> 77.64732 | H6: Không
A7: B01 | B7: Tiền thuê mặt bằng trả trước 1 năm (12 tháng x $500) | C7: 12 | D7: Tháng | E7: 500 | F7: =C7*E7 -> 6000 | G7: =F7*'03_Gia_dinh_Vi_mo'!$C$6/1000000 -> 155.29464 | H7: Không
A8: B02 | B8: Thiết kế kiến trúc, xin phép cải tạo thi công | C8: 100 | D8: m² | E8: 10 | F8: =C8*E8 -> 1000 | G8: =F8*'03_Gia_dinh_Vi_mo'!$C$6/1000000 -> 25.88244 | H8: Có
A9: B03 | B9: Thi công cải tạo mặt bằng, sàn vinyl, vách chì X-quang | C9: 100 | D9: m² | E9: 20 | F9: =C9*E9 -> 2000 | G9: =F9*'03_Gia_dinh_Vi_mo'!$C$6/1000000 -> 51.76488 | H9: Có
A10: C01 | B10: Ghế nha khoa cao cấp đầy đủ phụ kiện | C10: 3 | D10: Bộ | E10: 3000 | F10: =C10*E10 -> 9000 | G10: =F10*'03_Gia_dinh_Vi_mo'!$C$6/1000000 -> 232.94196 | H10: Có
A11: C02 | B11: Máy nén khí không dầu & hệ thống hút trung tâm | C11: 1 | D11: Hệ | E11: 1000 | F11: =C11*E11 -> 1000 | G11: =F11*'03_Gia_dinh_Vi_mo'!$C$6/1000000 -> 25.88244 | H11: Có
A12: C03 | B12: Nồi hấp tiệt trùng Autoclave vô trùng Class B | C12: 1 | D12: Chiếc | E12: 2000 | F12: =C12*E12 -> 2000 | G12: =F12*'03_Gia_dinh_Vi_mo'!$C$6/1000000 -> 51.76488 | H12: Có
A13: C04 | B13: Hệ thống X-quang CT ConeBeam Panorama 3D toàn cảnh | C13: 1 | D13: Hệ | E13: 40000 | F13: =C13*E13 -> 40000 | G13: =F13*'03_Gia_dinh_Vi_mo'!$C$6/1000000 -> 1035.2976 | H13: Có
A14: C05 | B14: Sensor chụp X-quang quanh chóp kỹ thuật số | C14: 1 | D14: Bộ | E14: 2000 | F14: =C14*E14 -> 2000 | G14: =F14*'03_Gia_dinh_Vi_mo'!$C$6/1000000 -> 51.76488 | H14: Có
A15: C06 | B15: Máy cấy ghép Implant chuyên dụng & bộ kit phẫu thuật | C15: 1 | D15: Bộ | E15: 2500 | F15: =C15*E15 -> 2500 | G15: =F15*'03_Gia_dinh_Vi_mo'!$C$6/1000000 -> 64.7061 | H15: Có
A16: C07 | B16: Đèn quang trùng hợp trám răng thẩm mỹ | C16: 2 | D16: Chiếc | E16: 300 | F16: =C16*E16 -> 600 | G16: =F16*'03_Gia_dinh_Vi_mo'!$C$6/1000000 -> 15.529464 | H16: Có
... A26: D07 | B26: Dự phòng chi phí phát sinh (10% tổng các khoản trên) | C26: 1 | D26: Khoản | E26: 11624.79 | F26: =C26*E26 -> 11624.79 | G26: =F26*'03_Gia_dinh_Vi_mo'!$C$6/1000000 -> 300.87793 | H26: Không
A27: TỔNG CỘNG VỐN ĐẦU TƯ BAN ĐẦU CẦN HUY ĐỘNG (CAPEX) | F27: =SUM(F5:F26) -> 125798.26 | G27: =SUM(G5:G26) -> 3255.9659 | H27: Khớp 100% gốc
A28: Trong đó: Cơ sở tính khấu hao (Thiết bị, máy CT, cải tạo, pháp lý - 60 tháng) | F28: =F5+F8+F9+F10+F11+F12+F13+F14+F15+F16+F17+F18+F19+F20+F21+F22+F23 -> 82700 | G28: =G5+G8+G9+G10+G11+G12+G13+G14+G15+G16+G17+G18+G19+G20+G21+G22+G23 -> 2140.4778 | H28: Khấu hao 5 năm
F31: =F27 -> 125798.26 | G31: =G27 -> 3255.9659
F32: =F28 -> 82700 | G32: =G28 -> 2140.4778

Sheet 07_Dong_tien_60T
A1: BÁO CÁO LƯU CHUYỂN TIỀN TỆ CHI TIẾT 60 THÁNG (5 NĂM) — 3 KỊCH BẢN DOANH THU NGÀY
A2: Đơn vị tính: Triệu VNĐ. Thuế TNDN 20% trên MAX(0, EBITDA - Khấu hao). Chiết khấu dòng tiền WACC 15%/năm.
A3: THÔNG SỐ THỜI GIAN & HỆ SỐ ĐIỀU CHỈNH | G3: KỊCH BẢN TIÊU CỰC (MIN: 80 TRIỆU VNĐ/NGÀY) | R3: KỊCH BẢN KỲ VỌNG (TRUNG BÌNH: 140 TRIỆU VNĐ/NGÀY) | AC3: KỊCH BẢN TÍCH CỰC (MAX: 200 TRIỆU VNĐ/NGÀY)
A4: Tháng | B4: Năm | C4: % Ramp | D4: Hệ số DT | E4: Hệ số CP | F4: Hệ số DF | G4: Doanh thu | H4: Biến phí | I4: Định phí | J4: EBITDA | K4: Khấu hao | L4: EBT | M4: Thuế CIT | N4: NPAT | O4: Dòng tiền CF | P4: Lũy kế CF | Q4: DCF tháng | R4: Doanh thu | S4: Biến phí | T4: Định phí | U4: EBITDA | V4: Khấu hao | W4: EBT | X4: Thuế CIT | Y4: NPAT | Z4: Dòng tiền CF | AA4: Lũy kế CF | AB4: DCF tháng | AC4: Doanh thu | AD4: Biến phí | AE4: Định phí | AF4: EBITDA | AG4: Khấu hao | AH4: EBT | AI4: Thuế CIT | AJ4: NPAT | AK4: Dòng tiền CF | AL4: Lũy kế CF | AM4: DCF tháng
A5: 0 | B5: 0 | C5: 0 | D5: 1 | E5: 1 | F5: 1 | O5: =-'06_CAPEX_Dau_tu'!$G$31 -> -3255.9659 | P5: =O5 -> -3255.9659 | Q5: =O5*F5 -> -3255.9659 | Z5: =-'06_CAPEX_Dau_tu'!$G$31 -> -3255.9659 | AA5: =Z5 -> -3255.9659 | AB5: =Z5*F5 -> -3255.9659 | AK5: =-'06_CAPEX_Dau_tu'!$G$31 -> -3255.9659 | AL5: =AK5 -> -3255.9659 | AM5: =AK5*F5 -> -3255.9659
A6: 1 | B6: =INT((A6-1)/12)+1 -> 1 | C6: ='03_Gia_dinh_Vi_mo'!$B$44 -> 0.3 | D6: =(1+'03_Gia_dinh_Vi_mo'!$C$10)^(B6-1) -> 1 | E6: =(1+'03_Gia_dinh_Vi_mo'!$C$9)^(B6-1) -> 1 | F6: =1/(1+'03_Gia_dinh_Vi_mo'!$C$12)^(A6/12) -> 0.98842073 | G6: ='03_Gia_dinh_Vi_mo'!$C$22*C6*D6 -> 624 | H6: =G6*'03_Gia_dinh_Vi_mo'!$C$17 -> 124.8 | I6: ='03_Gia_dinh_Vi_mo'!$F$40*E6 -> 345.33343 | J6: =G6-H6-I6 -> 153.86657 | K6: =IF(A6<=60, '06_CAPEX_Dau_tu'!$G$32/60, 0) -> 35.67463 | L6: =J6-K6 -> 118.19194 | M6: =IF(L6>0, L6*'03_Gia_dinh_Vi_mo'!$C$11, 0) -> 23.638388 | N6: =L6-M6 -> 94.553551 | O6: =J6-M6 -> 130.22818 | P6: =P5+O6 -> -3125.7377 | Q6: =O6*F6 -> 128.72023 | R6: ='03_Gia_dinh_Vi_mo'!$C$23*C6*D6 -> 1092 | S6: =R6*'03_Gia_dinh_Vi_mo'!$C$17 -> 218.4 | T6: ='03_Gia_dinh_Vi_mo'!$F$40*E6 -> 345.33343 | U6: =R6-S6-T6 -> 528.26657 | V6: =IF(A6<=60, '06_CAPEX_Dau_tu'!$G$32/60, 0) -> 35.67463 | W6: =U6-V6 -> 492.59194 | X6: =IF(W6>0, W6*'03_Gia_dinh_Vi_mo'!$C$11, 0) -> 98.518388 | Y6: =W6-X6 -> 394.07355 | Z6: =U6-X6 -> 429.74818 | AA6: =AA5+Z6 -> -2826.2177 | AB6: =Z6*F6 -> 424.77201 | AC6: ='03_Gia_dinh_Vi_mo'!$C$24*C6*D6 -> 1560 | AD6: =AC6*'03_Gia_dinh_Vi_mo'!$C$17 -> 312 | AE6: ='03_Gia_dinh_Vi_mo'!$F$40*E6 -> 345.33343 | AF6: =AC6-AD6-AE6 -> 902.66657 | AG6: =IF(A6<=60, '06_CAPEX_Dau_tu'!$G$32/60, 0) -> 35.67463 | AH6: =AF6-AG6 -> 866.99194 | AI6: =IF(AH6>0, AH6*'03_Gia_dinh_Vi_mo'!$C$11, 0) -> 173.39839 | AJ6: =AH6-AI6 -> 693.59355 | AK6: =AF6-AI6 -> 729.26818 | AL6: =AL5+AK6 -> -2526.6977 | AM6: =AK6*F6 -> 720.82379
A7: 2 | B7: =INT((A7-1)/12)+1 -> 1 | C7: ='03_Gia_dinh_Vi_mo'!$C$44 -> 0.45 | D7: =(1+'03_Gia_dinh_Vi_mo'!$C$10)^(B7-1) -> 1 | E7: =(1+'03_Gia_dinh_Vi_mo'!$C$9)^(B7-1) -> 1 | F7: =1/(1+'03_Gia_dinh_Vi_mo'!$C$12)^(A7/12) -> 0.97697555 | G7: ='03_Gia_dinh_Vi_mo'!$C$22*C7*D7 -> 936 | H7: =G7*'03_Gia_dinh_Vi_mo'!$C$17 -> 187.2 | I7: ='03_Gia_dinh_Vi_mo'!$F$40*E7 -> 345.33343 | J7: =G7-H7-I7 -> 403.46657 | K7: =IF(A7<=60, '06_CAPEX_Dau_tu'!$G$32/60, 0) -> 35.67463 | L7: =J7-K7 -> 367.79194 | M7: =IF(L7>0, L7*'03_Gia_dinh_Vi_mo'!$C$11, 0) -> 73.558388 | N7: =L7-M7 -> 294.23355 | O7: =J7-M7 -> 329.90818 | P7: =P6+O7 -> -2795.8296 | Q7: =O7*F7 -> 322.31223 | R7: ='03_Gia_dinh_Vi_mo'!$C$23*C7*D7 -> 1638 | S7: =R7*'03_Gia_dinh_Vi_mo'!$C$17 -> 327.6 | T7: ='03_Gia_dinh_Vi_mo'!$F$40*E7 -> 345.33343 | U7: =R7-S7-T7 -> 965.06657 | V7: =IF(A7<=60, '06_CAPEX_Dau_tu'!$G$32/60, 0) -> 35.67463 | W7: =U7-V7 -> 929.39194 | X7: =IF(W7>0, W7*'03_Gia_dinh_Vi_mo'!$C$11, 0) -> 185.87839 | Y7: =W7-X7 -> 743.51355 | Z7: =U7-X7 -> 779.18818 | AA7: =AA6+Z7 -> -2047.0296 | AB7: =Z7*F7 -> 761.2478 | AC7: ='03_Gia_dinh_Vi_mo'!$C$24*C7*D7 -> 2340 | AD7: =AC7*'03_Gia_dinh_Vi_mo'!$C$17 -> 468 | AE7: ='03_Gia_dinh_Vi_mo'!$F$40*E7 -> 345.33343 | AF7: =AC7-AD7-AE7 -> 1526.6666 | AG7: =IF(A7<=60, '06_CAPEX_Dau_tu'!$G$32/60, 0) -> 35.67463 | AH7: =AF7-AG7 -> 1490.9919 | AI7: =IF(AH7>0, AH7*'03_Gia_dinh_Vi_mo'!$C$11, 0) -> 298.19839 | AJ7: =AH7-AI7 -> 1192.7936 | AK7: =AF7-AI7 -> 1228.4682 | AL7: =AL6+AK7 -> -1298.2296 | AM7: =AK7*F7 -> 1200.1834
A8: 3 | B8: =INT((A8-1)/12)+1 -> 1 | C8: ='03_Gia_dinh_Vi_mo'!$D$44 -> 0.6 | D8: =(1+'03_Gia_dinh_Vi_mo'!$C$10)^(B8-1) -> 1 | E8: =(1+'03_Gia_dinh_Vi_mo'!$C$9)^(B8-1) -> 1 | F8: =1/(1+'03_Gia_dinh_Vi_mo'!$C$12)^(A8/12) -> 0.96566289 | G8: ='03_Gia_dinh_Vi_mo'!$C$22*C8*D8 -> 1248 | H8: =G8*'03_Gia_dinh_Vi_mo'!$C$17 -> 249.6 | I8: ='03_Gia_dinh_Vi_mo'!$F$40*E8 -> 345.33343 | J8: =G8-H8-I8 -> 653.06657 | K8: =IF(A8<=60, '06_CAPEX_Dau_tu'!$G$32/60, 0) -> 35.67463 | L8: =J8-K8 -> 617.39194 | M8: =IF(L8>0, L8*'03_Gia_dinh_Vi_mo'!$C$11, 0) -> 123.47839 | N8: =L8-M8 -> 493.91355 | O8: =J8-M8 -> 529.58818 | P8: =P7+O8 -> -2266.2414 | Q8: =O8*F8 -> 511.40365 | R8: ='03_Gia_dinh_Vi_mo'!$C$23*C8*D8 -> 2184 | S8: =R8*'03_Gia_dinh_Vi_mo'!$C$17 -> 436.8 | T8: ='03_Gia_dinh_Vi_mo'!$F$40*E8 -> 345.33343 | U8: =R8-S8-T8 -> 1401.8666 | V8: =IF(A8<=60, '06_CAPEX_Dau_tu'!$G$32/60, 0) -> 35.67463 | W8: =U8-V8 -> 1366.1919 | X8: =IF(W8>0, W8*'03_Gia_dinh_Vi_mo'!$C$11, 0) -> 273.23839 | Y8: =W8-X8 -> 1092.9536 | Z8: =U8-X8 -> 1128.6282 | AA8: =AA7+Z8 -> -918.40137 | AB8: =Z8*F8 -> 1089.8743 | AC8: ='03_Gia_dinh_Vi_mo'!$C$24*C8*D8 -> 3120 | AD8: =AC8*'03_Gia_dinh_Vi_mo'!$C$17 -> 624 | AE8: ='03_Gia_dinh_Vi_mo'!$F$40*E8 -> 345.33343 | AF8: =AC8-AD8-AE8 -> 2150.6666 | AG8: =IF(A8<=60, '06_CAPEX_Dau_tu'!$G$32/60, 0) -> 35.67463 | AH8: =AF8-AG8 -> 2114.9919 | AI8: =IF(AH8>0, AH8*'03_Gia_dinh_Vi_mo'!$C$11, 0) -> 422.99839 | AJ8: =AH8-AI8 -> 1691.9936 | AK8: =AF8-AI8 -> 1727.6682 | AL8: =AL7+AK8 -> 429.43863 | AM8: =AK8*F8 -> 1668.345
A9: 4 | B9: =INT((A9-1)/12)+1 -> 1 | C9: ='03_Gia_dinh_Vi_mo'!$E$44 -> 0.75 | D9: =(1+'03_Gia_dinh_Vi_mo'!$C$10)^(B9-1) -> 1 | E9: =(1+'03_Gia_dinh_Vi_mo'!$C$9)^(B9-1) -> 1 | F9: =1/(1+'03_Gia_dinh_Vi_mo'!$C$12)^(A9/12) -> 0.95448122 | G9: ='03_Gia_dinh_Vi_mo'!$C$22*C9*D9 -> 1560 | H9: =G9*'03_Gia_dinh_Vi_mo'!$C$17 -> 312 | I9: ='03_Gia_dinh_Vi_mo'!$F$40*E9 -> 345.33343 | J9: =G9-H9-I9 -> 902.66657 | K9: =IF(A9<=60, '06_CAPEX_Dau_tu'!$G$32/60, 0) -> 35.67463 | L9: =J9-K9 -> 866.99194 | M9: =IF(L9>0, L9*'03_Gia_dinh_Vi_mo'!$C$11, 0) -> 173.39839 | N9: =L9-M9 -> 693.59355 | O9: =J9-M9 -> 729.26818 | P9: =P8+O9 -> -1536.9732 | Q9: =O9*F9 -> 696.07278 | R9: ='03_Gia_dinh_Vi_mo'!$C$23*C9*D9 -> 2730 | S9: =R9*'03_Gia_dinh_Vi_mo'!$C$17 -> 546 | T9: ='03_Gia_dinh_Vi_mo'!$F$40*E9 -> 345.33343 | U9: =R9-S9-T9 -> 1838.6666 | V9: =IF(A9<=60, '06_CAPEX_Dau_tu'!$G$32/60, 0) -> 35.67463 | W9: =U9-V9 -> 1802.9919 | X9: =IF(W9>0, W9*'03_Gia_dinh_Vi_mo'!$C$11, 0) -> 360.59839 | Y9: =W9-X9 -> 1442.3936 | Z9: =U9-X9 -> 1478.0682 | AA9: =AA8+Z9 -> 559.66681 | AB9: =Z9*F9 -> 1410.7883 | AC9: ='03_Gia_dinh_Vi_mo'!$C$24*C9*D9 -> 3900 | AD9: =AC9*'03_Gia_dinh_Vi_mo'!$C$17 -> 780 | AE9: ='03_Gia_dinh_Vi_mo'!$F$40*E9 -> 345.33343 | AF9: =AC9-AD9-AE9 -> 2774.6666 | AG9: =IF(A9<=60, '06_CAPEX_Dau_tu'!$G$32/60, 0) -> 35.67463 | AH9: =AF9-AG9 -> 2738.9919 | AI9: =IF(AH9>0, AH9*'03_Gia_dinh_Vi_mo'!$C$11, 0) -> 547.79839 | AJ9: =AH9-AI9 -> 2191.1936 | AK9: =AF9-AI9 -> 2226.8682 | AL9: =AL8+AK9 -> 2656.3068 | AM9: =AK9*F9 -> 2125.5039
A10: 5 | B10: =INT((A10-1)/12)+1 -> 1 | C10: ='03_Gia_dinh_Vi_mo'!$F$44 -> 0.9 | D10: =(1+'03_Gia_dinh_Vi_mo'!$C$10)^(B10-1) -> 1 | E10: =(1+'03_Gia_dinh_Vi_mo'!$C$9)^(B10-1) -> 1 | F10: =1/(1+'03_Gia_dinh_Vi_mo'!$C$12)^(A10/12) -> 0.94342902 | G10: ='03_Gia_dinh_Vi_mo'!$C$22*C10*D10 -> 1872 | H10: =G10*'03_Gia_dinh_Vi_mo'!$C$17 -> 374.4 | I10: ='03_Gia_dinh_Vi_mo'!$F$40*E10 -> 345.33343 | J10: =G10-H10-I10 -> 1152.2666 | K10: =IF(A10<=60, '06_CAPEX_Dau_tu'!$G$32/60, 0) -> 35.67463 | L10: =J10-K10 -> 1116.5919 | M10: =IF(L10>0, L10*'03_Gia_dinh_Vi_mo'!$C$11, 0) -> 223.31839 | N10: =L10-M10 -> 893.27355 | O10: =J10-M10 -> 928.94818 | P10: =P9+O10 -> -608.02501 | Q10: =O10*F10 -> 876.39668 | R10: ='03_Gia_dinh_Vi_mo'!$C$23*C10*D10 -> 3276 | S10: =R10*'03_Gia_dinh_Vi_mo'!$C$17 -> 655.2 | T10: ='03_Gia_dinh_Vi_mo'!$F$40*E10 -> 345.33343 | U10: =R10-S10-T10 -> 2275.4666 | V10: =IF(A10<=60, '06_CAPEX_Dau_tu'!$G$32/60, 0) -> 35.67463 | W10: =U10-V10 -> 2239.7919 | X10: =IF(W10>0, W10*'03_Gia_dinh_Vi_mo'!$C$11, 0) -> 447.95839 | Y10: =W10-X10 -> 1791.8336 | Z10: =U10-X10 -> 1827.5082 | AA10: =AA9+Z10 -> 2387.175 | AB10: =Z10*F10 -> 1724.1243 | AC10: ='03_Gia_dinh_Vi_mo'!$C$24*C10*D10 -> 4680 | AD10: =AC10*'03_Gia_dinh_Vi_mo'!$C$17 -> 936 | AE10: ='03_Gia_dinh_Vi_mo'!$F$40*E10 -> 345.33343 | AF10: =AC10-AD10-AE10 -> 3398.6666 | AG10: =IF(A10<=60, '06_CAPEX_Dau_tu'!$G$32/60, 0) -> 35.67463 | AH10: =AF10-AG10 -> 3362.9919 | AI10: =IF(AH10>0, AH10*'03_Gia_dinh_Vi_mo'!$C$11, 0) -> 672.59839 | AJ10: =AH10-AI10 -> 2690.3936 | AK10: =AF10-AI10 -> 2726.0682 | AL10: =AL9+AK10 -> 5382.375 | AM10: =AK10*F10 -> 2571.8518
A11: 6 | B11: =INT((A11-1)/12)+1 -> 1 | C11: ='03_Gia_dinh_Vi_mo'!$G$44 -> 1 | D11: =(1+'03_Gia_dinh_Vi_mo'!$C$10)^(B11-1) -> 1 | E11: =(1+'03_Gia_dinh_Vi_mo'!$C$9)^(B11-1) -> 1 | F11: =1/(1+'03_Gia_dinh_Vi_mo'!$C$12)^(A11/12) -> 0.93250481 | G11: ='03_Gia_dinh_Vi_mo'!$C$22*C11*D11 -> 2080 | H11: =G11*'03_Gia_dinh_Vi_mo'!$C$17 -> 416 | I11: ='03_Gia_dinh_Vi_mo'!$F$40*E11 -> 345.33343 | J11: =G11-H11-I11 -> 1318.6666 | K11: =IF(A11<=60, '06_CAPEX_Dau_tu'!$G$32/60, 0) -> 35.67463 | L11: =J11-K11 -> 1282.9919 | M11: =IF(L11>0, L11*'03_Gia_dinh_Vi_mo'!$C$11, 0) -> 256.59839 | N11: =L11-M11 -> 1026.3936 | O11: =J11-M11 -> 1062.0682 | P11: =P10+O11 -> 454.04317 | Q11: =O11*F11 -> 990.38369 | R11: ='03_Gia_dinh_Vi_mo'!$C$23*C11*D11 -> 3640 | S11: =R11*'03_Gia_dinh_Vi_mo'!$C$17 -> 728 | T11: ='03_Gia_dinh_Vi_mo'!$F$40*E11 -> 345.33343 | U11: =R11-S11-T11 -> 2566.6666 | V11: =IF(A11<=60, '06_CAPEX_Dau_tu'!$G$32/60, 0) -> 35.67463 | W11: =U11-V11 -> 2530.9919 | X11: =IF(W11>0, W11*'03_Gia_dinh_Vi_mo'!$C$11, 0) -> 506.19839 | Y11: =W11-X11 -> 2024.7936 | Z11: =U11-X11 -> 2060.4682 | AA11: =AA10+Z11 -> 4447.6432 | AB11: =Z11*F11 -> 1921.3965 | AC11: ='03_Gia_dinh_Vi_mo'!$C$24*C11*D11 -> 5200 | AD11: =AC11*'03_Gia_dinh_Vi_mo'!$C$17 -> 1040 | AE11: ='03_Gia_dinh_Vi_mo'!$F$40*E11 -> 345.33343 | AF11: =AC11-AD11-AE11 -> 3814.6666 | AG11: =IF(A11<=60, '06_CAPEX_Dau_tu'!$G$32/60, 0) -> 35.67463 | AH11: =AF11-AG11 -> 3778.9919 | AI11: =IF(AH11>0, AH11*'03_Gia_dinh_Vi_mo'!$C$11, 0) -> 755.79839 | AJ11: =AH11-AI11 -> 3023.1936 | AK11: =AF11-AI11 -> 3058.8682 | AL11: =AL10+AK11 -> 8441.2432 | AM11: =AK11*F11 -> 2852.4093
A12: 7 | B12: =INT((A12-1)/12)+1 -> 1 | C12: ='03_Gia_dinh_Vi_mo'!$G$44 -> 1 | D12: =(1+'03_Gia_dinh_Vi_mo'!$C$10)^(B12-1) -> 1 | E12: =(1+'03_Gia_dinh_Vi_mo'!$C$9)^(B12-1) -> 1 | F12: =1/(1+'03_Gia_dinh_Vi_mo'!$C$12)^(A12/12) -> 0.92170709 | G12: ='03_Gia_dinh_Vi_mo'!$C$22*C12*D12 -> 2080 | H12: =G12*'03_Gia_dinh_Vi_mo'!$C$17 -> 416 | I12: ='03_Gia_dinh_Vi_mo'!$F$40*E12 -> 345.33343 | J12: =G12-H12-I12 -> 1318.6666 | K12: =IF(A12<=60, '06_CAPEX_Dau_tu'!$G$32/60, 0) -> 35.67463 | L12: =J12-K12 -> 1282.9919 | M12: =IF(L12>0, L12*'03_Gia_dinh_Vi_mo'!$C$11, 0) -> 256.59839 | N12: =L12-M12 -> 1026.3936 | O12: =J12-M12 -> 1062.0682 | P12: =P11+O12 -> 1516.1114 | Q12: =O12*F12 -> 978.91577 | R12: ='03_Gia_dinh_Vi_mo'!$C$23*C12*D12 -> 3640 | S12: =R12*'03_Gia_dinh_Vi_mo'!$C$17 -> 728 | T12: ='03_Gia_dinh_Vi_mo'!$F$40*E12 -> 345.33343 | U12: =R12-S12-T12 -> 2566.6666 | V12: =IF(A12<=60, '06_CAPEX_Dau_tu'!$G$32/60, 0) -> 35.67463 | W12: =U12-V12 -> 2530.9919 | X12: =IF(W12>0, W12*'03_Gia_dinh_Vi_mo'!$C$11, 0) -> 506.19839 | Y12: =W12-X12 -> 2024.7936 | Z12: =U12-X12 -> 2060.4682 | AA12: =AA11+Z12 -> 6508.1114 | AB12: =Z12*F12 -> 1899.1481 | AC12: ='03_Gia_dinh_Vi_mo'!$C$24*C12*D12 -> 5200 | AD12: =AC12*'03_Gia_dinh_Vi_mo'!$C$17 -> 1040 | AE12: ='03_Gia_dinh_Vi_mo'!$F$40*E12 -> 345.33343 | AF12: =AC12-AD12-AE12 -> 3814.6666 | AG12: =IF(A12<=60, '06_CAPEX_Dau_tu'!$G$32/60, 0) -> 35.67463 | AH12: =AF12-AG12 -> 3778.9919 | AI12: =IF(AH12>0, AH12*'03_Gia_dinh_Vi_mo'!$C$11, 0) -> 755.79839 | AJ12: =AH12-AI12 -> 3023.1936 | AK12: =AF12-AI12 -> 3058.8682 | AL12: =AL11+AK12 -> 11500.111 | AM12: =AK12*F12 -> 2819.3805
A13: 8 | B13: =INT((A13-1)/12)+1 -> 1 | C13: ='03_Gia_dinh_Vi_mo'!$G$44 -> 1 | D13: =(1+'03_Gia_dinh_Vi_mo'!$C$10)^(B13-1) -> 1 | E13: =(1+'03_Gia_dinh_Vi_mo'!$C$9)^(B13-1) -> 1 | F13: =1/(1+'03_Gia_dinh_Vi_mo'!$C$12)^(A13/12) -> 0.91103439 | G13: ='03_Gia_dinh_Vi_mo'!$C$22*C13*D13 -> 2080 | H13: =G13*'03_Gia_dinh_Vi_mo'!$C$17 -> 416 | I13: ='03_Gia_dinh_Vi_mo'!$F$40*E13 -> 345.33343 | J13: =G13-H13-I13 -> 1318.6666 | K13: =IF(A13<=60, '06_CAPEX_Dau_tu'!$G$32/60, 0) -> 35.67463 | L13: =J13-K13 -> 1282.9919 | M13: =IF(L13>0, L13*'03_Gia_dinh_Vi_mo'!$C$11, 0) -> 256.59839 | N13: =L13-M13 -> 1026.3936 | O13: =J13-M13 -> 1062.0682 | P13: =P12+O13 -> 2578.1795 | Q13: =O13*F13 -> 967.58064 | R13: ='03_Gia_dinh_Vi_mo'!$C$23*C13*D13 -> 3640 | S13: =R13*'03_Gia_dinh_Vi_mo'!$C$17 -> 728 | T13: ='03_Gia_dinh_Vi_mo'!$F$40*E13 -> 345.33343 | U13: =R13-S13-T13 -> 2566.6666 | V13: =IF(A13<=60, '06_CAPEX_Dau_tu'!$G$32/60, 0) -> 35.67463 | W13: =U13-V13 -> 2530.9919 | X13: =IF(W13>0, W13*'03_Gia_dinh_Vi_mo'!$C$11, 0) -> 506.19839 | Y13: =W13-X13 -> 2024.7936 | Z13: =U13-X13 -> 2060.4682 | AA13: =AA12+Z13 -> 8568.5795 | AB13: =Z13*F13 -> 1877.1574 | AC13: ='03_Gia_dinh_Vi_mo'!$C$24*C13*D13 -> 5200 | AD13: =AC13*'03_Gia_dinh_Vi_mo'!$C$17 -> 1040 | AE13: ='03_Gia_dinh_Vi_mo'!$F$40*E13 -> 345.33343 | AF13: =AC13-AD13-AE13 -> 3814.6666 | AG13: =IF(A13<=60, '06_CAPEX_Dau_tu'!$G$32/60, 0) -> 35.67463 | AH13: =AF13-AG13 -> 3778.9919 | AI13: =IF(AH13>0, AH13*'03_Gia_dinh_Vi_mo'!$C$11, 0) -> 755.79839 | AJ13: =AH13-AI13 -> 3023.1936 | AK13: =AF13-AI13 -> 3058.8682 | AL13: =AL12+AK13 -> 14558.98 | AM13: =AK13*F13 -> 2786.7341
A14: 9 | B14: =INT((A14-1)/12)+1 -> 1 | C14: ='03_Gia_dinh_Vi_mo'!$G$44 -> 1 | D14: =(1+'03_Gia_dinh_Vi_mo'!$C$10)^(B14-1) -> 1 | E14: =(1+'03_Gia_dinh_Vi_mo'!$C$9)^(B14-1) -> 1 | F14: =1/(1+'03_Gia_dinh_Vi_mo'!$C$12)^(A14/12) -> 0.90048528 | G14: ='03_Gia_dinh_Vi_mo'!$C$22*C14*D14 -> 2080 | H14: =G14*'03_Gia_dinh_Vi_mo'!$C$17 -> 416 | I14: ='03_Gia_dinh_Vi_mo'!$F$40*E14 -> 345.33343 | J14: =G14-H14-I14 -> 1318.6666 | K14: =IF(A14<=60, '06_CAPEX_Dau_tu'!$G$32/60, 0) -> 35.67463 | L14: =J14-K14 -> 1282.9919 | M14: =IF(L14>0, L14*'03_Gia_dinh_Vi_mo'!$C$11, 0) -> 256.59839 | N14: =L14-M14 -> 1026.3936 | O14: =J14-M14 -> 1062.0682 | P14: =P13+O14 -> 3640.2477 | Q14: =O14*F14 -> 956.37677 | R14: ='03_Gia_dinh_Vi_mo'!$C$23*C14*D14 -> 3640 | S14: =R14*'03_Gia_dinh_Vi_mo'!$C$17 -> 728 | T14: ='03_Gia_dinh_Vi_mo'!$F$40*E14 -> 345.33343 | U14: =R14-S14-T14 -> 2566.6666 | V14: =IF(A14<=60, '06_CAPEX_Dau_tu'!$G$32/60, 0) -> 35.67463 | W14: =U14-V14 -> 2530.9919 | X14: =IF(W14>0, W14*'03_Gia_dinh_Vi_mo'!$C$11, 0) -> 506.19839 | Y14: =W14-X14 -> 2024.7936 | Z14: =U14-X14 -> 2060.4682 | AA14: =AA13+Z14 -> 10629.048 | AB14: =Z14*F14 -> 1855.4213 | AC14: ='03_Gia_dinh_Vi_mo'!$C$24*C14*D14 -> 5200 | AD14: =AC14*'03_Gia_dinh_Vi_mo'!$C$17 -> 1040 | AE14: ='03_Gia_dinh_Vi_mo'!$F$40*E14 -> 345.33343 | AF14: =AC14-AD14-AE14 -> 3814.6666 | AG14: =IF(A14<=60, '06_CAPEX_Dau_tu'!$G$32/60, 0) -> 35.67463 | AH14: =AF14-AG14 -> 3778.9919 | AI14: =IF(AH14>0, AH14*'03_Gia_dinh_Vi_mo'!$C$11, 0) -> 755.79839 | AJ14: =AH14-AI14 -> 3023.1936 | AK14: =AF14-AI14 -> 3058.8682 | AL14: =AL13+AK14 -> 17617.848 | AM14: =AK14*F14 -> 2754.4658
A15: 10 | B15: =INT((A15-1)/12)+1 -> 1 | C15: ='03_Gia_dinh_Vi_mo'!$G$44 -> 1 | D15: =(1+'03_Gia_dinh_Vi_mo'!$C$10)^(B15-1) -> 1 | E15: =(1+'03_Gia_dinh_Vi_mo'!$C$9)^(B15-1) -> 1 | F15: =1/(1+'03_Gia_dinh_Vi_mo'!$C$12)^(A15/12) -> 0.89005832 | G15: ='03_Gia_dinh_Vi_mo'!$C$22*C15*D15 -> 2080 | H15: =G15*'03_Gia_dinh_Vi_mo'!$C$17 -> 416 | I15: ='03_Gia_dinh_Vi_mo'!$F$40*E15 -> 345.33343 | J15: =G15-H15-I15 -> 1318.6666 | K15: =IF(A15<=60, '06_CAPEX_Dau_tu'!$G$32/60, 0) -> 35.67463 | L15: =J15-K15 -> 1282.9919 | M15: =IF(L15>0, L15*'03_Gia_dinh_Vi_mo'!$C$11, 0) -> 256.59839 | N15: =L15-M15 -> 1026.3936 | O15: =J15-M15 -> 1062.0682 | P15: =P14+O15 -> 4702.3159 | Q15: =O15*F15 -> 945.30263 | R15: ='03_Gia_dinh_Vi_mo'!$C$23*C15*D15 -> 3640 | S15: =R15*'03_Gia_dinh_Vi_mo'!$C$17 -> 728 | T15: ='03_Gia_dinh_Vi_mo'!$F$40*E15 -> 345.33343 | U15: =R15-S15-T15 -> 2566.6666 | V15: =IF(A15<=60, '06_CAPEX_Dau_tu'!$G$32/60, 0) -> 35.67463 | W15: =U15-V15 -> 2530.9919 | X15: =IF(W15>0, W15*'03_Gia_dinh_Vi_mo'!$C$11, 0) -> 506.19839 | Y15: =W15-X15 -> 2024.7936 | Z15: =U15-X15 -> 2060.4682 | AA15: =AA14+Z15 -> 12689.516 | AB15: =Z15*F15 -> 1833.9369 | AC15: ='03_Gia_dinh_Vi_mo'!$C$24*C15*D15 -> 5200 | AD15: =AC15*'03_Gia_dinh_Vi_mo'!$C$17 -> 1040 | AE15: ='03_Gia_dinh_Vi_mo'!$F$40*E15 -> 345.33343 | AF15: =AC15-AD15-AE15 -> 3814.6666 | AG15: =IF(A15<=60, '06_CAPEX_Dau_tu'!$G$32/60, 0) -> 35.67463 | AH15: =AF15-AG15 -> 3778.9919 | AI15: =IF(AH15>0, AH15*'03_Gia_dinh_Vi_mo'!$C$11, 0) -> 755.79839 | AJ15: =AH15-AI15 -> 3023.1936 | AK15: =AF15-AI15 -> 3058.8682 | AL15: =AL14+AK15 -> 20676.716 | AM15: =AK15*F15 -> 2722.5711
A16: 11 | B16: =INT((A16-1)/12)+1 -> 1 | C16: ='03_Gia_dinh_Vi_mo'!$G$44 -> 1 | D16: =(1+'03_Gia_dinh_Vi_mo'!$C$10)^(B16-1) -> 1 | E16: =(1+'03_Gia_dinh_Vi_mo'!$C$9)^(B16-1) -> 1 | F16: =1/(1+'03_Gia_dinh_Vi_mo'!$C$12)^(A16/12) -> 0.8797521 | G16: ='03_Gia_dinh_Vi_mo'!$C$22*C16*D16 -> 2080 | H16: =G16*'03_Gia_dinh_Vi_mo'!$C$17 -> 416 | I16: ='03_Gia_dinh_Vi_mo'!$F$40*E16 -> 345.33343 | J16: =G16-H16-I16 -> 1318.6666 | K16: =IF(A16<=60, '06_CAPEX_Dau_tu'!$G$32/60, 0) -> 35.67463 | L16: =J16-K16 -> 1282.9919 | M16: =IF(L16>0, L16*'03_Gia_dinh_Vi_mo'!$C$11, 0) -> 256.59839 | N16: =L16-M16 -> 1026.3936 | O16: =J16-M16 -> 1062.0682 | P16: =P15+O16 -> 5764.3841 | Q16: =O16*F16 -> 934.35671 | R16: ='03_Gia_dinh_Vi_mo'!$C$23*C16*D16 -> 3640 | S16: =R16*'03_Gia_dinh_Vi_mo'!$C$17 -> 728 | T16: ='03_Gia_dinh_Vi_mo'!$F$40*E16 -> 345.33343 | U16: =R16-S16-T16 -> 2566.6666 | V16: =IF(A16<=60, '06_CAPEX_Dau_tu'!$G$32/60, 0) -> 35.67463 | W16: =U16-V16 -> 2530.9919 | X16: =IF(W16>0, W16*'03_Gia_dinh_Vi_mo'!$C$11, 0) -> 506.19839 | Y16: =W16-X16 -> 2024.7936 | Z16: =U16-X16 -> 2060.4682 | AA16: =AA15+Z16 -> 14749.984 | AB16: =Z16*F16 -> 1812.7012 | AC16: ='03_Gia_dinh_Vi_mo'!$C$24*C16*D16 -> 5200 | AD16: =AC16*'03_Gia_dinh_Vi_mo'!$C$17 -> 1040 | AE16: ='03_Gia_dinh_Vi_mo'!$F$40*E16 -> 345.33343 | AF16: =AC16-AD16-AE16 -> 3814.6666 | AG16: =IF(A16<=60, '06_CAPEX_Dau_tu'!$G$32/60, 0) -> 35.67463 | AH16: =AF16-AG16 -> 3778.9919 | AI16: =IF(AH16>0, AH16*'03_Gia_dinh_Vi_mo'!$C$11, 0) -> 755.79839 | AJ16: =AH16-AI16 -> 3023.1936 | AK16: =AF16-AI16 -> 3058.8682 | AL16: =AL15+AK16 -> 23735.584 | AM16: =AK16*F16 -> 2691.0457
A17: 12 | B17: =INT((A17-1)/12)+1 -> 1 | C17: ='03_Gia_dinh_Vi_mo'!$G$44 -> 1 | D17: =(1+'03_Gia_dinh_Vi_mo'!$C$10)^(B17-1) -> 1 | E17: =(1+'03_Gia_dinh_Vi_mo'!$C$9)^(B17-1) -> 1 | F17: =1/(1+'03_Gia_dinh_Vi_mo'!$C$12)^(A17/12) -> 0.86956522 | G17: ='03_Gia_dinh_Vi_mo'!$C$22*C17*D17 -> 2080 | H17: =G17*'03_Gia_dinh_Vi_mo'!$C$17 -> 416 | I17: ='03_Gia_dinh_Vi_mo'!$F$40*E17 -> 345.33343 | J17: =G17-H17-I17 -> 1318.6666 | K17: =IF(A17<=60, '06_CAPEX_Dau_tu'!$G$32/60, 0) -> 35.67463 | L17: =J17-K17 -> 1282.9919 | M17: =IF(L17>0, L17*'03_Gia_dinh_Vi_mo'!$C$11, 0) -> 256.59839 | N17: =L17-M17 -> 1026.3936 | O17: =J17-M17 -> 1062.0682 | P17: =P16+O17 -> 6826.4523 | Q17: =O17*F17 -> 923.53755 | R17: ='03_Gia_dinh_Vi_mo'!$C$23*C17*D17 -> 3640 | S17: =R17*'03_Gia_dinh_Vi_mo'!$C$17 -> 728 | T17: ='03_Gia_dinh_Vi_mo'!$F$40*E17 -> 345.33343 | U17: =R17-S17-T17 -> 2566.6666 | V17: =IF(A17<=60, '06_CAPEX_Dau_tu'!$G$32/60, 0) -> 35.67463 | W17: =U17-V17 -> 2530.9919 | X17: =IF(W17>0, W17*'03_Gia_dinh_Vi_mo'!$C$11, 0) -> 506.19839 | Y17: =W17-X17 -> 2024.7936 | Z17: =U17-X17 -> 2060.4682 | AA17: =AA16+Z17 -> 16810.452 | AB17: =Z17*F17 -> 1791.7115 | AC17: ='03_Gia_dinh_Vi_mo'!$C$24*C17*D17 -> 5200 | AD17: =AC17*'03_Gia_dinh_Vi_mo'!$C$17 -> 1040 | AE17: ='03_Gia_dinh_Vi_mo'!$F$40*E17 -> 345.33343 | AF17: =AC17-AD17-AE17 -> 3814.6666 | AG17: =IF(A17<=60, '06_CAPEX_Dau_tu'!$G$32/60, 0) -> 35.67463 | AH17: =AF17-AG17 -> 3778.9919 | AI17: =IF(AH17>0, AH17*'03_Gia_dinh_Vi_mo'!$C$11, 0) -> 755.79839 | AJ17: =AH17-AI17 -> 3023.1936 | AK17: =AF17-AI17 -> 3058.8682 | AL17: =AL16+AK17 -> 26794.452 | AM17: =AK17*F17 -> 2659.8854
A18: 13 | B18: =INT((A18-1)/12)+1 -> 2 | C18: ='03_Gia_dinh_Vi_mo'!$G$44 -> 1 | D18: =(1+'03_Gia_dinh_Vi_mo'!$C$10)^(B18-1) -> 1.03 | E18: =(1+'03_Gia_dinh_Vi_mo'!$C$9)^(B18-1) -> 1.078 | F18: =1/(1+'03_Gia_dinh_Vi_mo'!$C$12)^(A18/12) -> 0.85949629 | G18: ='03_Gia_dinh_Vi_mo'!$C$22*C18*D18 -> 2142.4 | H18: =G18*'03_Gia_dinh_Vi_mo'!$C$17 -> 428.48 | I18: ='03_Gia_dinh_Vi_mo'!$F$40*E18 -> 372.26944 | J18: =G18-H18-I18 -> 1341.6506 | K18: =IF(A18<=60, '06_CAPEX_Dau_tu'!$G$32/60, 0) -> 35.67463 | L18: =J18-K18 -> 1305.9759 | M18: =IF(L18>0, L18*'03_Gia_dinh_Vi_mo'!$C$11, 0) -> 261.19519 | N18: =L18-M18 -> 1044.7807 | O18: =J18-M18 -> 1080.4554 | P18: =P17+O18 -> 7906.9076 | Q18: =O18*F18 -> 928.64739 | R18: ='03_Gia_dinh_Vi_mo'!$C$23*C18*D18 -> 3749.2 | S18: =R18*'03_Gia_dinh_Vi_mo'!$C$17 -> 749.84 | T18: ='03_Gia_dinh_Vi_mo'!$F$40*E18 -> 372.26944 | U18: =R18-S18-T18 -> 2627.0906 | V18: =IF(A18<=60, '06_CAPEX_Dau_tu'!$G$32/60, 0) -> 35.67463 | W18: =U18-V18 -> 2591.4159 | X18: =IF(W18>0, W18*'03_Gia_dinh_Vi_mo'!$C$11, 0) -> 518.28319 | Y18: =W18-X18 -> 2073.1327 | Z18: =U18-X18 -> 2108.8074 | AA18: =AA17+Z18 -> 18919.26 | AB18: =Z18*F18 -> 1812.5121 | AC18: ='03_Gia_dinh_Vi_mo'!$C$24*C18*D18 -> 5356 | AD18: =AC18*'03_Gia_dinh_Vi_mo'!$C$17 -> 1071.2 | AE18: ='03_Gia_dinh_Vi_mo'!$F$40*E18 -> 372.26944 | AF18: =AC18-AD18-AE18 -> 3912.5306 | AG18: =IF(A18<=60, '06_CAPEX_Dau_tu'!$G$32/60, 0) -> 35.67463 | AH18: =AF18-AG18 -> 3876.8559 | AI18: =IF(AH18>0, AH18*'03_Gia_dinh_Vi_mo'!$C$11, 0) -> 775.37119 | AJ18: =AH18-AI18 -> 3101.4847 | AK18: =AF18-AI18 -> 3137.1594 | AL18: =AL17+AK18 -> 29931.612 | AM18: =AK18*F18 -> 2696.3768
A19: 14 | B19: =INT((A19-1)/12)+1 -> 2 | C19: ='03_Gia_dinh_Vi_mo'!$G$44 -> 1 | D19: =(1+'03_Gia_dinh_Vi_mo'!$C$10)^(B19-1) -> 1.03 | E19: =(1+'03_Gia_dinh_Vi_mo'!$C$9)^(B19-1) -> 1.078 | F19: =1/(1+'03_Gia_dinh_Vi_mo'!$C$12)^(A19/12) -> 0.84954395 | G19: ='03_Gia_dinh_Vi_mo'!$C$22*C19*D19 -> 2142.4 | H19: =G19*'03_Gia_dinh_Vi_mo'!$C$17 -> 428.48 | I19: ='03_Gia_dinh_Vi_mo'!$F$40*E19 -> 372.26944 | J19: =G19-H19-I19 -> 1341.6506 | K19: =IF(A19<=60, '06_CAPEX_Dau_tu'!$G$32/60, 0) -> 35.67463 | L19: =J19-K19 -> 1305.9759 | M19: =IF(L19>0, L19*'03_Gia_dinh_Vi_mo'!$C$11, 0) -> 261.19519 | N19: =L19-M19 -> 1044.7807 | O19: =J19-M19 -> 1080.4554 | P19: =P18+O19 -> 8987.363 | Q19: =O19*F19 -> 917.89433 | R19: ='03_Gia_dinh_Vi_mo'!$C$23*C19*D19 -> 3749.2 | S19: =R19*'03_Gia_dinh_Vi_mo'!$C$17 -> 749.84 | T19: ='03_Gia_dinh_Vi_mo'!$F$40*E19 -> 372.26944 | U19: =R19-S19-T19 -> 2627.0906 | V19: =IF(A19<=60, '06_CAPEX_Dau_tu'!$G$32/60, 0) -> 35.67463 | W19: =U19-V19 -> 2591.4159 | X19: =IF(W19>0, W19*'03_Gia_dinh_Vi_mo'!$C$11, 0) -> 518.28319 | Y19: =W19-X19 -> 2073.1327 | Z19: =U19-X19 -> 2108.8074 | AA19: =AA18+Z19 -> 21028.067 | AB19: =Z19*F19 -> 1791.5246 | AC19: ='03_Gia_dinh_Vi_mo'!$C$24*C19*D19 -> 5356 | AD19: =AC19*'03_Gia_dinh_Vi_mo'!$C$17 -> 1071.2 | AE19: ='03_Gia_dinh_Vi_mo'!$F$40*E19 -> 372.26944 | AF19: =AC19-AD19-AE19 -> 3912.5306 | AG19: =IF(A19<=60, '06_CAPEX_Dau_tu'!$G$32/60, 0) -> 35.67463 | AH19: =AF19-AG19 -> 3876.8559 | AI19: =IF(AH19>0, AH19*'03_Gia_dinh_Vi_mo'!$C$11, 0) -> 775.37119 | AJ19: =AH19-AI19 -> 3101.4847 | AK19: =AF19-AI19 -> 3137.1594 | AL19: =AL18+AK19 -> 33068.771 | AM19: =AK19*F19 -> 2665.1548
A20: 15 | B20: =INT((A20-1)/12)+1 -> 2 | C20: ='03_Gia_dinh_Vi_mo'!$G$44 -> 1 | D20: =(1+'03_Gia_dinh_Vi_mo'!$C$10)^(B20-1) -> 1.03 | E20: =(1+'03_Gia_dinh_Vi_mo'!$C$9)^(B20-1) -> 1.078 | F20: =1/(1+'03_Gia_dinh_Vi_mo'!$C$12)^(A20/12) -> 0.83970686 | G20: ='03_Gia_dinh_Vi_mo'!$C$22*C20*D20 -> 2142.4 | H20: =G20*'03_Gia_dinh_Vi_mo'!$C$17 -> 428.48 | I20: ='03_Gia_dinh_Vi_mo'!$F$40*E20 -> 372.26944 | J20: =G20-H20-I20 -> 1341.6506 | K20: =IF(A20<=60, '06_CAPEX_Dau_tu'!$G$32/60, 0) -> 35.67463 | L20: =J20-K20 -> 1305.9759 | M20: =IF(L20>0, L20*'03_Gia_dinh_Vi_mo'!$C$11, 0) -> 261.19519 | N20: =L20-M20 -> 1044.7807 | O20: =J20-M20 -> 1080.4554 | P20: =P19+O20 -> 10067.818 | Q20: =O20*F20 -> 907.26579 | R20: ='03_Gia_dinh_Vi_mo'!$C$23*C20*D20 -> 3749.2 | S20: =R20*'03_Gia_dinh_Vi_mo'!$C$17 -> 749.84 | T20: ='03_Gia_dinh_Vi_mo'!$F$40*E20 -> 372.26944 | U20: =R20-S20-T20 -> 2627.0906 | V20: =IF(A20<=60, '06_CAPEX_Dau_tu'!$G$32/60, 0) -> 35.67463 | W20: =U20-V20 -> 2591.4159 | X20: =IF(W20>0, W20*'03_Gia_dinh_Vi_mo'!$C$11, 0) -> 518.28319 | Y20: =W20-X20 -> 2073.1327 | Z20: =U20-X20 -> 2108.8074 | AA20: =AA19+Z20 -> 23136.874 | AB20: =Z20*F20 -> 1770.78 | AC20: ='03_Gia_dinh_Vi_mo'!$C$24*C20*D20 -> 5356 | AD20: =AC20*'03_Gia_dinh_Vi_mo'!$C$17 -> 1071.2 | AE20: ='03_Gia_dinh_Vi_mo'!$F$40*E20 -> 372.26944 | AF20: =AC20-AD20-AE20 -> 3912.5306 | AG20: =IF(A20<=60, '06_CAPEX_Dau_tu'!$G$32/60, 0) -> 35.67463 | AH20: =AF20-AG20 -> 3876.8559 | AI20: =IF(AH20>0, AH20*'03_Gia_dinh_Vi_mo'!$C$11, 0) -> 775.37119 | AJ20: =AH20-AI20 -> 3101.4847 | AK20: =AF20-AI20 -> 3137.1594 | AL20: =AL19+AK20 -> 36205.93 | AM20: =AK20*F20 -> 2634.2942
A21: 16 | B21: =INT((A21-1)/12)+1 -> 2 | C21: ='03_Gia_dinh_Vi_mo'!$G$44 -> 1 | D21: =(1+'03_Gia_dinh_Vi_mo'!$C$10)^(B21-1) -> 1.03 | E21: =(1+'03_Gia_dinh_Vi_mo'!$C$9)^(B21-1) -> 1.078 | F21: =1/(1+'03_Gia_dinh_Vi_mo'!$C$12)^(A21/12) -> 0.82998367 | G21: ='03_Gia_dinh_Vi_mo'!$C$22*C21*D21 -> 2142.4 | H21: =G21*'03_Gia_dinh_Vi_mo'!$C$17 -> 428.48 | I21: ='03_Gia_dinh_Vi_mo'!$F$40*E21 -> 372.26944 | J21: =G21-H21-I21 -> 1341.6506 | K21: =IF(A21<=60, '06_CAPEX_Dau_tu'!$G$32/60, 0) -> 35.67463 | L21: =J21-K21 -> 1305.9759 | M21: =IF(L21>0, L21*'03_Gia_dinh_Vi_mo'!$C$11, 0) -> 261.19519 | N21: =L21-M21 -> 1044.7807 | O21: =J21-M21 -> 1080.4554 | P21: =P20+O21 -> 11148.274 | Q21: =O21*F21 -> 896.76031 | R21: ='03_Gia_dinh_Vi_mo'!$C$23*C21*D21 -> 3749.2 | S21: =R21*'03_Gia_dinh_Vi_mo'!$C$17 -> 749.84 | T21: ='03_Gia_dinh_Vi_mo'!$F$40*E21 -> 372.26944 | U21: =R21-S21-T21 -> 2627.0906 | V21: =IF(A21<=60, '06_CAPEX_Dau_tu'!$G$32/60, 0) -> 35.67463 | W21: =U21-V21 -> 2591.4159 | X21: =IF(W21>0, W21*'03_Gia_dinh_Vi_mo'!$C$11, 0) -> 518.28319 | Y21: =W21-X21 -> 2073.1327 | Z21: =U21-X21 -> 2108.8074 | AA21: =AA20+Z21 -> 25245.682 | AB21: =Z21*F21 -> 1750.2757 | AC21: ='03_Gia_dinh_Vi_mo'!$C$24*C21*D21 -> 5356 | AD21: =AC21*'03_Gia_dinh_Vi_mo'!$C$17 -> 1071.2 | AE21: ='03_Gia_dinh_Vi_mo'!$F$40*E21 -> 372.26944 | AF21: =AC21-AD21-AE21 -> 3912.5306 | AG21: =IF(A21<=60, '06_CAPEX_Dau_tu'!$G$32/60, 0) -> 35.67463 | AH21: =AF21-AG21 -> 3876.8559 | AI21: =IF(AH21>0, AH21*'03_Gia_dinh_Vi_mo'!$C$11, 0) -> 775.37119 | AJ21: =AH21-AI21 -> 3101.4847 | AK21: =AF21-AI21 -> 3137.1594 | AL21: =AL20+AK21 -> 39343.09 | AM21: =AK21*F21 -> 2603.791
A22: 17 | B22: =INT((A22-1)/12)+1 -> 2 | C22: ='03_Gia_dinh_Vi_mo'!$G$44 -> 1 | D22: =(1+'03_Gia_dinh_Vi_mo'!$C$10)^(B22-1) -> 1.03 | E22: =(1+'03_Gia_dinh_Vi_mo'!$C$9)^(B22-1) -> 1.078 | F22: =1/(1+'03_Gia_dinh_Vi_mo'!$C$12)^(A22/12) -> 0.82037306 | G22: ='03_Gia_dinh_Vi_mo'!$C$22*C22*D22 -> 2142.4 | H22: =G22*'03_Gia_dinh_Vi_mo'!$C$17 -> 428.48 | I22: ='03_Gia_dinh_Vi_mo'!$F$40*E22 -> 372.26944 | J22: =G22-H22-I22 -> 1341.6506 | K22: =IF(A22<=60, '06_CAPEX_Dau_tu'!$G$32/60, 0) -> 35.67463 | L22: =J22-K22 -> 1305.9759 | M22: =IF(L22>0, L22*'03_Gia_dinh_Vi_mo'!$C$11, 0) -> 261.19519 | N22: =L22-M22 -> 1044.7807 | O22: =J22-M22 -> 1080.4554 | P22: =P21+O22 -> 12228.729 | Q22: =O22*F22 -> 886.37649 | R22: ='03_Gia_dinh_Vi_mo'!$C$23*C22*D22 -> 3749.2 | S22: =R22*'03_Gia_dinh_Vi_mo'!$C$17 -> 749.84 | T22: ='03_Gia_dinh_Vi_mo'!$F$40*E22 -> 372.26944 | U22: =R22-S22-T22 -> 2627.0906 | V22: =IF(A22<=60, '06_CAPEX_Dau_tu'!$G$32/60, 0) -> 35.67463 | W22: =U22-V22 -> 2591.4159 | X22: =IF(W22>0, W22*'03_Gia_dinh_Vi_mo'!$C$11, 0) -> 518.28319 | Y22: =W22-X22 -> 2073.1327 | Z22: =U22-X22 -> 2108.8074 | AA22: =AA21+Z22 -> 27354.489 | AB22: =Z22*F22 -> 1730.0088 | AC22: ='03_Gia_dinh_Vi_mo'!$C$24*C22*D22 -> 5356 | AD22: =AC22*'03_Gia_dinh_Vi_mo'!$C$17 -> 1071.2 | AE22: ='03_Gia_dinh_Vi_mo'!$F$40*E22 -> 372.26944 | AF22: =AC22-AD22-AE22 -> 3912.5306 | AG22: =IF(A22<=60, '06_CAPEX_Dau_tu'!$G$32/60, 0) -> 35.67463 | AH22: =AF22-AG22 -> 3876.8559 | AI22: =IF(AH22>0, AH22*'03_Gia_dinh_Vi_mo'!$C$11, 0) -> 775.37119 | AJ22: =AH22-AI22 -> 3101.4847 | AK22: =AF22-AI22 -> 3137.1594 | AL22: =AL21+AK22 -> 42480.249 | AM22: =AK22*F22 -> 2573.6411
... A65: 60 | B65: =INT((A65-1)/12)+1 -> 5 | C65: ='03_Gia_dinh_Vi_mo'!$G$44 -> 1 | D65: =(1+'03_Gia_dinh_Vi_mo'!$C$10)^(B65-1) -> 1.1255088 | E65: =(1+'03_Gia_dinh_Vi_mo'!$C$9)^(B65-1) -> 1.3504392 | F65: =1/(1+'03_Gia_dinh_Vi_mo'!$C$12)^(A65/12) -> 0.49717674 | G65: ='03_Gia_dinh_Vi_mo'!$C$22*C65*D65 -> 2341.0583 | H65: =G65*'03_Gia_dinh_Vi_mo'!$C$17 -> 468.21166 | I65: ='03_Gia_dinh_Vi_mo'!$F$40*E65 -> 466.35181 | J65: =G65-H65-I65 -> 1406.4948 | K65: =IF(A65<=60, '06_CAPEX_Dau_tu'!$G$32/60, 0) -> 35.67463 | L65: =J65-K65 -> 1370.8202 | M65: =IF(L65>0, L65*'03_Gia_dinh_Vi_mo'!$C$11, 0) -> 274.16404 | N65: =L65-M65 -> 1096.6562 | O65: =J65-M65 -> 1132.3308 | P65: =P64+O65 -> 59948.442 | Q65: =O65*F65 -> 562.96853 | R65: ='03_Gia_dinh_Vi_mo'!$C$23*C65*D65 -> 4096.8521 | S65: =R65*'03_Gia_dinh_Vi_mo'!$C$17 -> 819.37041 | T65: ='03_Gia_dinh_Vi_mo'!$F$40*E65 -> 466.35181 | U65: =R65-S65-T65 -> 2811.1298 | V65: =IF(A65<=60, '06_CAPEX_Dau_tu'!$G$32/60, 0) -> 35.67463 | W65: =U65-V65 -> 2775.4552 | X65: =IF(W65>0, W65*'03_Gia_dinh_Vi_mo'!$C$11, 0) -> 555.09104 | Y65: =W65-X65 -> 2220.3642 | Z65: =U65-X65 -> 2256.0388 | AA65: =AA64+Z65 -> 121559.34 | AB65: =Z65*F65 -> 1121.65 | AC65: ='03_Gia_dinh_Vi_mo'!$C$24*C65*D65 -> 5852.6458 | AD65: =AC65*'03_Gia_dinh_Vi_mo'!$C$17 -> 1170.5292 | AE65: ='03_Gia_dinh_Vi_mo'!$F$40*E65 -> 466.35181 | AF65: =AC65-AD65-AE65 -> 4215.7648 | AG65: =IF(A65<=60, '06_CAPEX_Dau_tu'!$G$32/60, 0) -> 35.67463 | AH65: =AF65-AG65 -> 4180.0902 | AI65: =IF(AH65>0, AH65*'03_Gia_dinh_Vi_mo'!$C$11, 0) -> 836.01804 | AJ65: =AH65-AI65 -> 3344.0722 | AK65: =AF65-AI65 -> 3379.7468 | AL65: =AL64+AK65 -> 183170.23 | AM65: =AK65*F65 -> 1680.3315
A66: TỔNG CỘNG 5 NĂM (THÁNG 1 - 60) | G66: =SUM(G6:G65) -> 128356.03 | H66: =SUM(H6:H65) -> 25671.206 | I66: =SUM(I6:I65) -> 24214.434 | J66: =SUM(J6:J65) -> 78470.39 | K66: =SUM(K6:K65) -> 2140.4778 | L66: =SUM(L6:L65) -> 76329.912 | M66: =SUM(M6:M65) -> 15265.982 | N66: =SUM(N6:N65) -> 61063.93 | O66: =SUM(O6:O65) -> 63204.408 | P66: =P65 -> 59948.442 | Q66: =SUM(Q5:Q65) -> 41059.314 | R66: =SUM(R6:R65) -> 224623.05 | S66: =SUM(S6:S65) -> 44924.61 | T66: =SUM(T6:T65) -> 24214.434 | U66: =SUM(U6:U65) -> 155484.01 | V66: =SUM(V6:V65) -> 2140.4778 | W66: =SUM(W6:W65) -> 153343.53 | X66: =SUM(X6:X65) -> 30668.706 | Y66: =SUM(Y6:Y65) -> 122674.82 | Z66: =SUM(Z6:Z65) -> 124815.3 | AA66: =AA65 -> 121559.34 | AB66: =SUM(AB5:AB65) -> 84244.263 | AC66: =SUM(AC6:AC65) -> 320890.07 | AD66: =SUM(AD6:AD65) -> 64178.015 | AE66: =SUM(AE6:AE65) -> 24214.434 | AF66: =SUM(AF6:AF65) -> 232497.63 | AG66: =SUM(AG6:AG65) -> 2140.4778 | AH66: =SUM(AH6:AH65) -> 230357.15 | AI66: =SUM(AI6:AI65) -> 46071.43 | AJ66: =SUM(AJ6:AJ65) -> 184285.72 | AK66: =SUM(AK6:AK65) -> 186426.2 | AL66: =AL65 -> 183170.23 | AM66: =SUM(AM5:AM65) -> 127429.21
A67: GIÁ TRỊ HIỆN TẠI THUẦN (NPV 5 NĂM, WACC 15%) | Q67: =Q66 -> 41059.314 | AB67: =AB66 -> 84244.263 | AM67: =AM66 -> 127429.21
A68: TỶ SUẤT SINH LỜI NỘI BỘ (IRR NĂM) | Q68: =(1+IRR(O5:O65))^12-1 -> 9.007962 | AB68: =(1+IRR(Z5:Z65))^12-1 -> 38.714094 | AM68: =(1+IRR(AK5:AK65))^12-1 -> 117.02152

Sheet 08_Phan_tich_Hoan_von
A1: PHÂN TÍCH ĐIỂM HÒA VỐN & TIẾN ĐỘ THU HỒI VỐN ĐẦU TƯ (BREAK-EVEN & PAYBACK)
A2: Thẩm định cơ chế tự nuôi dòng tiền và đối chiếu dòng tiền thu hồi vốn 12 tháng đầu
