Workbook

Sheet Tong_hop_3_Kich_ban
A1: MÔ HÌNH DỰ TOÁN TÀI CHÍNH NHA KHOA PAKSE (CHAMPASAK, LÀO)
A2: BẢNG SO SÁNH 3 KỊCH BẢN DOANH THU THEO NGÀY: MIN (80 TR) — KỲ VỌNG (140 TR) — MAX (200 TR/NGÀY)
A4: CHỌN TIỀN TỆ HIỂN THỊ: | B4: VND | C4: Đơn vị tính: | D4: =IF(B4="VND","Triệu VNĐ",IF(B4="USD","USD","Triệu LAK")) | E4: Tỷ giá áp dụng: | F4: =IF(B4="VND","1 USD = 25,882 VND",IF(B4="USD","Gốc USD","1 USD = 22,403 LAK")) | G4: =IF($B$4="VND", 1, IF($B$4="USD", 1000000/Gia_dinh_Dau_vao!$C$6, Gia_dinh_Dau_vao!$C$7/Gia_dinh_Dau_vao!$C$6))
B6: KỊCH BẢN MIN (80 TRIỆU/NGÀY) | D6: KỲ VỌNG (140 TRIỆU/NGÀY) | F6: KỊCH BẢN MAX (200 TRIỆU/NGÀY)
B7: =B24 | D7: =C24 | F7: =D24
B8: ="EBITDA: " & TEXT(B24,"#,##0.0") & " " & $D$4 & "/tháng | Hoàn vốn: 6 tháng" | D8: ="EBITDA: " & TEXT(C24,"#,##0.0") & " " & $D$4 & "/tháng | Hoàn vốn: 4 tháng" | F8: ="EBITDA: " & TEXT(D24,"#,##0.0") & " " & $D$4 & "/tháng | Hoàn vốn: 3 tháng"
A10: CHỈ TIÊU TÀI CHÍNH & VẬN HÀNH | B10: TIÊU CỰC (MIN) | C10: KỲ VỌNG (TRUNG BÌNH) | D10: TÍCH CỰC (MAX) | E10: ĐƠN VỊ | F10: CƠ SỞ TÍNH TOÁN & GHI CHÚ
A11: I. DOANH THU & HIỆU SUẤT KHAI THÁC
A12: Doanh thu mục tiêu 1 NGÀY | B12: =Gia_dinh_Dau_vao!$C$19*$G$4 | C12: =Gia_dinh_Dau_vao!$C$20*$G$4 | D12: =Gia_dinh_Dau_vao!$C$21*$G$4 | E12: =$D$4 & "/ngày" | F12: Mức doanh thu ngày mục tiêu (Min 80 tr, TB 140 tr, Max 200 tr)
A13: Doanh thu mục tiêu 1 THÁNG (26 ngày làm việc) | B13: =Gia_dinh_Dau_vao!$C$22*$G$4 | C13: =Gia_dinh_Dau_vao!$C$23*$G$4 | D13: =Gia_dinh_Dau_vao!$C$24*$G$4 | E13: =$D$4 & "/tháng"
A14: Doanh thu thực tế Năm 1 (gồm ramp-up 5 tháng) | B14: =SUM(Dong_tien_Chi_tiet!G6:G17)*$G$4 | C14: =SUM(Dong_tien_Chi_tiet!R6:R17)*$G$4 | D14: =SUM(Dong_tien_Chi_tiet!AC6:AC17)*$G$4 | E14: =$D$4 | F14: Năm 1 tính thận trọng độ trễ thâm nhập (T1: 30%, T2: 45%, T3: 60%, T4: 75%, T5: 90%)
A15: Doanh thu ổn định / năm (12 tháng đầy tải) | B15: =B13*12 | C15: =C13*12 | D15: =D13*12 | E15: =$D$4 | F15: Doanh thu 1 năm khi hoạt động trọn vẹn công suất ổn định
A16: Lượt khám điều trị dự kiến / ngày | B16: =Gia_dinh_Dau_vao!$C$19/Gia_dinh_Dau_vao!$E$25 | C16: =Gia_dinh_Dau_vao!$C$20/Gia_dinh_Dau_vao!$E$25 | D16: =Gia_dinh_Dau_vao!$C$21/Gia_dinh_Dau_vao!$E$25 | E16: Lượt / ngày | F16: Ước tính theo doanh thu bình quân 239,45 USD (~6,2 triệu VNĐ) / lượt khám từ file gốc
A17: II. CƠ CẤU CHI PHÍ HÀNG THÁNG (GIÁ ỔN ĐỊNH NĂM 1)
A18: Chi phí biến đổi / tháng (Vật tư y tế + Labo) | B18: =B13*Gia_dinh_Dau_vao!$C$17 | C18: =C13*Gia_dinh_Dau_vao!$C$17 | D18: =D13*Gia_dinh_Dau_vao!$C$17 | E18: =$D$4 | F18: Định mức 20% doanh thu (vật tư tiêu hao, implant, răng sứ - Gia_dinh!C63:C70)
A19: Chi phí cố định / tháng (Mặt bằng, lương, vận hành) | B19: =Gia_dinh_Dau_vao!$F$40*$G$4 | C19: =Gia_dinh_Dau_vao!$F$40*$G$4 | D19: =Gia_dinh_Dau_vao!$F$40*$G$4 | E19: =$D$4 | F19: Bộ máy gốc: 2 BS ($4k), 3 Phụ tá, Lễ tân, Sale, Quản lý, Mặt bằng 100m², MKT ($5k)... (~346,6 tr)
A20: Tổng chi phí hoạt động / tháng | B20: =B18+B19 | C20: =C18+C19 | D20: =D18+D19 | E20: =$D$4 | F20: =Chi phí biến đổi + Chi phí cố định hàng tháng
A21: Tỷ lệ chi phí hoạt động / Doanh thu (%) | B21: =B20/B13 | C21: =C20/C13 | D21: =D20/D13 | E21: % | F21: Tỷ trọng tổng chi phí trên tổng doanh thu (chỉ chiếm ~27% - 37%)
A22: III. LỢI NHUẬN & HIỆU QUẢ HOẠT ĐỘNG
A23: Lợi nhuận gộp / tháng | B23: =B13-B18 | C23: =C13-C18 | D23: =D13-D18 | E23: =$D$4
A24: Lợi nhuận EBITDA / tháng (ổn định) | B24: =B23-B19 | C24: =C23-C19 | D24: =D23-D19 | E24: =$D$4 | F24: Lợi nhuận kinh doanh trước khấu hao, lãi vay & thuế (Dòng tiền ròng/tháng)
A25: Biên lợi nhuận EBITDA (%) | B25: =B24/B13 | C25: =C24/C13 | D25: =D24/D13 | E25: %
A26: Khấu hao tài sản / tháng (khấu hao 60 tháng) | B26: =(CAPEX_Dau_tu!$G$32/60)*$G$4 | C26: =(CAPEX_Dau_tu!$G$32/60)*$G$4 | D26: =(CAPEX_Dau_tu!$G$32/60)*$G$4 | E26: =$D$4 | F26: Khấu hao đường thẳng thiết bị, cải tạo, máy CT toàn cảnh ($88.230 USD/60 th ~ 38 tr)
A27: Lợi nhuận trước thuế (EBT) / tháng | B27: =B24-B26 | C27: =C24-C26 | D27: =D24-D26 | E27: =$D$4 | F27: =EBITDA - Khấu hao tài sản
A28: Thuế thu nhập doanh nghiệp (20%) / tháng | B28: =IF(B27>0, B27*Gia_dinh_Dau_vao!$C$11, 0) | C28: =IF(C27>0, C27*Gia_dinh_Dau_vao!$C$11, 0) | D28: =IF(D27>0, D27*Gia_dinh_Dau_vao!$C$11, 0) | E28: =$D$4 | F28: Thuế TNDN Lào 20% trên thu nhập chịu thuế
A29: Lợi nhuận sau thuế (NPAT) / tháng | B29: =B27-B28 | C29: =C27-C28 | D29: =D27-D28 | E29: =$D$4 | F29: Lợi nhuận ròng kế toán hàng tháng
A30: Tổng lợi nhuận ròng Năm 1 | B30: =SUM(Dong_tien_Chi_tiet!N6:N17)*$G$4 | C30: =SUM(Dong_tien_Chi_tiet!Y6:Y17)*$G$4 | D30: =SUM(Dong_tien_Chi_tiet!AJ6:AJ17)*$G$4 | E30: =$D$4 | F30: Lợi nhuận ròng cả năm đầu tiên (đã trừ giai đoạn tăng tốc và thuế)
A31: Tổng lợi nhuận ròng 5 năm lũy kế | B31: =SUM(Dong_tien_Chi_tiet!N6:N65)*$G$4 | C31: =SUM(Dong_tien_Chi_tiet!Y6:Y65)*$G$4 | D31: =SUM(Dong_tien_Chi_tiet!AJ6:AJ65)*$G$4 | E31: =$D$4 | F31: Tổng lợi nhuận ròng tích lũy sau thuế cả 5 năm
A32: IV. ĐIỂM HÒA VỐN & ĐỘ AN TOÀN TÀI CHÍNH
A33: Doanh thu hòa vốn vận hành / tháng (EBITDA = 0) | B33: =(Gia_dinh_Dau_vao!$F$40/(1-Gia_dinh_Dau_vao!$C$17))*$G$4 | C33: =(Gia_dinh_Dau_vao!$F$40/(1-Gia_dinh_Dau_vao!$C$17))*$G$4 | D33: =(Gia_dinh_Dau_vao!$F$40/(1-Gia_dinh_Dau_vao!$C$17))*$G$4 | E33: =$D$4
A34: Doanh thu hòa vốn vận hành / ngày (26 ngày) | B34: =B33/Gia_dinh_Dau_vao!$C$18 | C34: =C33/Gia_dinh_Dau_vao!$C$18 | D34: =D33/Gia_dinh_Dau_vao!$C$18 | E34: =$D$4 & "/ngày" | F34: Chỉ cần thu ~16,66 triệu VNĐ/ngày là đã hòa vốn 100% chi phí hoạt động!
A35: Tỷ lệ an toàn doanh thu (Margin of Safety) | B35: =(B13-B33)/B13 | C35: =(C13-C33)/C13 | D35: =(D13-D33)/D13 | E35: % | F35: Biên an toàn cực lớn (79% - 92%): Doanh thu sụt giảm 79% vẫn không lỗ!
A36: V. VỐN ĐẦU TƯ, HOÀN VỐN & ĐỊNH GIÁ (CAPEX, NPV, IRR)
A37: Tổng vốn đầu tư ban đầu cần huy động | B37: =CAPEX_Dau_tu!$G$31*$G$4 | C37: =CAPEX_Dau_tu!$G$31*$G$4 | D37: =CAPEX_Dau_tu!$G$31*$G$4 | E37: =$D$4 | F37: Khớp 100% CAPEX gốc: $127.872,72 USD (~3.309,66 triệu VNĐ)
A38: Lũy kế dòng tiền thuần sau 5 năm | B38: =Dong_tien_Chi_tiet!P65*$G$4 | C38: =Dong_tien_Chi_tiet!AA65*$G$4 | D38: =Dong_tien_Chi_tiet!AL65*$G$4 | E38: =$D$4 | F38: Dòng tiền thuần tích lũy sau 60 tháng (ĐÃ trừ vốn đầu tư ban đầu và thuế)
A39: Thời gian thu hồi vốn đầu tư (Payback Period) | B39: 6 tháng | C39: 4 tháng | D39: 3 tháng | E39: Tháng | F39: Thời điểm dòng tiền tích lũy vượt điểm 0 (Hoàn vốn siêu tốc ngay trong năm đầu!)
A40: Giá trị hiện tại thuần (NPV 5 năm, WACC 15%) | B40: =Dong_tien_Chi_tiet!Q67*$G$4 | C40: =Dong_tien_Chi_tiet!AB67*$G$4 | D40: =Dong_tien_Chi_tiet!AM67*$G$4 | E40: =$D$4 | F40: Chiết khấu dòng tiền 15%/năm theo chuẩn thẩm định đầu tư
A41: Tỷ suất sinh lời nội bộ (IRR năm) | B41: =Dong_tien_Chi_tiet!Q68 | C41: =Dong_tien_Chi_tiet!AB68 | D41: =Dong_tien_Chi_tiet!AM68 | E41: % | F41: Tỷ suất sinh lời nội bộ hàng năm vượt trội
A42: ĐÁNH GIÁ CHUNG & KHUYẾN NGHỊ | B42: Siêu hiệu quả: Thu 80 tr/ngày (~2,08 tỷ/tháng), hoàn vốn sau 6 tháng, EBITDA đạt 1,32 tỷ/tháng. | C42: Mục tiêu xuất sắc: Thu 140 tr/ngày (~3,64 tỷ/tháng), hoàn vốn sau 4 tháng, EBITDA đạt 2,57 tỷ/tháng. | D42: Kỷ lục doanh thu: Thu 200 tr/ngày (~5,20 tỷ/tháng), hoàn vốn ngay tháng thứ 3, EBITDA đạt 3,81 tỷ/tháng. | F42: Khuyến nghị điều hành chiến lược cho Hội đồng quản trị & Cổ đông
A44: VI. BẢNG TRA CỨU ĐỒNG THỜI ĐA TIỀN TỆ (VND | USD | LAK) — KHÔNG CẦN CHUYỂN ĐỔI
...

Sheet Gia_dinh_Dau_vao
A1: BẢNG GIẢ ĐỊNH ĐẦU VÀO TOÀN DIỆN — NHA KHOA PAKSE (CHAMPASAK, LÀO)
A2: Dữ liệu chi phí & CAPEX đối chiếu chuẩn xác từ mo_hinh_phong_kham_pakse.xlsx | 3 kịch bản doanh thu chuẩn hóa theo NGÀY
A4: I. THÔNG SỐ VĨ MÔ & TÀI CHÍNH
A5: Mã | B5: Tên thông số giả định | C5: Giá trị | D5: Đơn vị | E5: Ký hiệu | F5: Ghi chú & Cơ sở tham chiếu
A6: M01 | B6: Tỷ giá USD / VND | C6: 25882.44 | D6: VND/USD | E6: FX_VND | F6: Tỷ giá Vietcombank bán ra tham chiếu
A7: M02 | B7: Tỷ giá USD / LAK | C7: 22402.5 | D7: LAK/USD | E7: FX_LAK | F7: Tỷ giá BCEL Lào tham chiếu
A8: M03 | B8: Tỷ giá quy đổi LAK sang VND | C8: =C6/C7 | D8: VND/LAK | E8: FX_CROSS
A9: M04 | B9: Lạm phát chi phí hàng năm (CPI Lào) | C9: 0.078 | D9: % / năm | E9: CPI | F9: Theo dữ liệu lạm phát thực tế tại Lào
A10: M05 | B10: Trượt giá / Tăng giá dịch vụ hàng năm | C10: 0.03 | D10: % / năm | E10: PRICE_INC | F10: Dự kiến điều chỉnh tăng giá sau năm 1
A11: M06 | B11: Thuế thu nhập doanh nghiệp Lào (CIT) | C11: 0.2 | D11: % | E11: CIT | F11: Thuế suất phổ thông cho y tế tại Lào
A12: M07 | B12: Tỷ lệ chiết khấu WACC (Chi phí vốn) | C12: 0.15 | D12: % / năm | E12: WACC | F12: Lãi suất chiết khấu thận trọng theo chuẩn thẩm định
A13: M08 | B13: Thời gian khấu hao tài sản cố định | C13: 60 | D13: Tháng | E13: DEPR_M | F13: Khấu hao đường thẳng 5 năm (60 tháng)
A15: II. MỤC TIÊU DOANH THU THEO NGÀY & ĐỊNH MỨC BIẾN PHÍ
A16: Mã | B16: Chỉ tiêu doanh thu & Biến phí | C16: Giá trị | D16: Đơn vị | E16: Quy đổi USD | F16: Ghi chú & Cơ sở
A17: R01 | B17: Tỷ lệ chi phí biến đổi (% Doanh thu) | C17: 0.2 | D17: % | F17: Vật tư tiêu hao, trụ implant, xưởng labo (từ Gia_dinh!C63:C70)
A18: R02 | B18: Số ngày làm việc trong tháng | C18: 26 | D18: Ngày/tháng | F18: Chuẩn 26 ngày (nghỉ chủ nhật, hoặc đổi sang 30 ngày)
A19: R03 | B19: Doanh thu mục tiêu 1 NGÀY — MIN (Thận trọng) | C19: 80 | D19: Triệu VND/ngày | E19: =C19*1000000/$C$6 | F19: Mức sàn doanh thu ngày bạn cung cấp (~$3,091 USD/ngày)
A20: R04 | B20: Doanh thu mục tiêu 1 NGÀY — KỲ VỌNG (Trung bình) | C20: 140 | D20: Triệu VND/ngày | E20: =C20*1000000/$C$6 | F20: Mục tiêu kinh doanh thực tế bình quân (~$5,409 USD/ngày)
A21: R05 | B21: Doanh thu mục tiêu 1 NGÀY — MAX (Tích cực) | C21: 200 | D21: Triệu VND/ngày | E21: =C21*1000000/$C$6 | F21: Công suất khai thác cao điểm (~$7,727 USD/ngày)
A22: R06 | B22: Doanh thu mục tiêu 1 THÁNG — MIN | C22: =C19*C18 | D22: Triệu VND/th | E22: =C22*1000000/$C$6
A23: R07 | B23: Doanh thu mục tiêu 1 THÁNG — KỲ VỌNG | C23: =C20*C18 | D23: Triệu VND/th | E23: =C23*1000000/$C$6
A24: R08 | B24: Doanh thu mục tiêu 1 THÁNG — MAX | C24: =C21*C18 | D24: Triệu VND/th | E24: =C24*1000000/$C$6
A25: R09 | B25: Doanh thu bình quân theo lượt khám (Doanh_thu!B9) | C25: 239.45 | D25: USD/lượt | E25: =C25*$C$6/1000000 | F25: Bình quân gia quyền cơ cấu dịch vụ theo file gốc (~6,2 triệu VNĐ/lượt)
A27: III. ĐỊNH MỨC CHI PHÍ CỐ ĐỊNH HÀNG THÁNG (CHUẨN TỪ MO_HINH_PHONG_KHAM_PAKSE)
A28: Mã | B28: Hạng mục chi phí cố định | C28: Số lượng | D28: Đơn vị tiền gốc | E28: Đơn giá gốc | F28: Thành tiền (Triệu VND) | G28: Ghi chú & Cơ sở từ file gốc
A29: F01 | B29: Bác sĩ nha khoa (Chi_phi_VH!D4) | C29: 2 | D29: USD | E29: 2000 | F29: =C29*E29*$C$6/1000000 | G29: 2 Bác sĩ toàn thời gian (tổng $4.000 USD/tháng)
A30: F02 | B30: Phụ tá nha khoa, vệ sinh, tiệt trùng (Chi_phi_VH!D5) | C30: 3 | D30: LAK | E30: 8000000 | F30: =C30*E30*($C$6/$C$7)/1000000 | G30: 3 Phụ tá (24 triệu LAK/tháng ~ $1.071,31 USD)
A31: F03 | B31: Lễ tân, kế toán, CSKH (Chi_phi_VH!D6) | C31: 1 | D31: LAK | E31: 8000000 | F31: =C31*E31*($C$6/$C$7)/1000000 | G31: 1 Lễ tân / CSKH (8 triệu LAK/tháng ~ $357,10 USD)
A32: F04 | B32: Sale / Tư vấn khách hàng (Chi_phi_VH!D7) | C32: 1 | D32: LAK | E32: 8000000 | F32: =C32*E32*($C$6/$C$7)/1000000 | G32: 1 Nhân viên Sale (8 triệu LAK/tháng ~ $357,10 USD)
A33: F05 | B33: Quản lý phòng khám (Chi_phi_VH!D8) | C33: 1 | D33: LAK | E33: 15000000 | F33: =C33*E33*($C$6/$C$7)/1000000 | G33: 1 Quản lý cơ sở (15 triệu LAK/tháng ~ $669,57 USD)
A34: F06 | B34: BHXH phần doanh nghiệp 6% (Chi_phi_VH!D10) | C34: 1 | D34: USD | E34: 387.3 | F34: =C34*E34*$C$6/1000000 | G34: Bảo hiểm xã hội 6% trên tổng quỹ lương ($387,30 USD)
A35: F07 | B35: Thuê mặt bằng 100m² (Chi_phi_VH!D11) | C35: 1 | D35: USD | E35: 500 | F35: =C35*E35*$C$6/1000000 | G35: 100 m² x 5,5 USD/m² = $550 USD/tháng (~14,2 triệu VNĐ)
A36: F08 | B36: Điện, nước, internet (Chi_phi_VH!D12) | C36: 1 | D36: USD | E36: 400 | F36: =C36*E36*$C$6/1000000 | G36: Chi phí vận hành điện lạnh, máy nén khí ($400 USD)
A37: F09 | B37: Marketing thường xuyên (Chi_phi_VH!D13) | C37: 1 | D37: USD | E37: 5000 | F37: =C37*E37*$C$6/1000000 | G37: Ngân sách quảng cáo Facebook/TikTok/OOH duy trì doanh thu lớn ($5.000 USD)
A38: F10 | B38: Bảo trì thiết bị, vật tư cố định (Chi_phi_VH!D14) | C38: 1 | D38: USD | E38: 300 | F38: =C38*E38*$C$6/1000000 | G38: Bảo trì định kỳ máy móc nha khoa ($300 USD)
A39: F11 | B39: Kế toán, pháp lý, bảo hiểm, giấy phép (Chi_phi_VH!D15) | C39: 1 | D39: USD | E39: 300 | F39: =C39*E39*$C$6/1000000 | G39: Duy trì hành chính, kế toán thuế Champasak ($300 USD)
A40: F12 | B40: TỔNG CHI PHÍ CỐ ĐỊNH / THÁNG (Chi_phi_VH!D16) | D40: USD | E40: =F40*1000000/$C$6 | F40: =SUM(F29:F39) | G40: Tổng định phí gốc: $13.392,39 USD/tháng (~346,63 triệu VNĐ)
A42: IV. LỘ TRÌNH TĂNG TỐC CÔNG SUẤT KHAI THÁC (RAMP-UP NĂM 1)
A43: Tháng | B43: Tháng 1 | C43: Tháng 2 | D43: Tháng 3 | E43: Tháng 4 | F43: Tháng 5 | G43: Tháng 6 trở đi
A44: Tỷ lệ công suất (%) | B44: 0.3 | C44: 0.45 | D44: 0.6 | E44: 0.75 | F44: 0.9 | G44: 1

Sheet Dong_tien_Chi_tiet
A1: BẢNG DÒNG TIỀN VÀ HIỆU QUẢ TÀI CHÍNH CHI TIẾT 60 THÁNG (5 NĂM) — 3 KỊCH BẢN DOANH THU THEO NGÀY
A2: Đơn vị tính: Triệu VNĐ | Doanh thu ngày: Min 80 tr - TB 140 tr - Max 200 tr/ngày | Chi phí & CAPEX gốc từ mo_hinh_phong_kham_pakse.xlsx
A3: THÔNG SỐ THỜI GIAN & HỆ SỐ MÔ HÌNH | G3: KỊCH BẢN 1: MIN (80 TRIỆU/NGÀY — 2.080 TR/THÁNG) | R3: KỊCH BẢN 2: KỲ VỌNG (140 TRIỆU/NGÀY — 3.640 TR/THÁNG) | AC3: KỊCH BẢN 3: MAX (200 TRIỆU/NGÀY — 5.200 TR/THÁNG)
A4: Tháng | B4: Năm | C4: Tăng tốc | D4: Trượt giá DT | E4: Lạm phát CP | F4: Chiết khấu | G4: Doanh thu | H4: CP biến đổi | I4: CP cố định | J4: EBITDA | K4: Khấu hao | L4: EBT | M4: Thuế TNDN | N4: LN sau thuế | O4: Dòng tiền (CF) | P4: Lũy kế CF | Q4: DCF | R4: Doanh thu | S4: CP biến đổi | T4: CP cố định | U4: EBITDA | V4: Khấu hao | W4: EBT | X4: Thuế TNDN | Y4: LN sau thuế | Z4: Dòng tiền (CF) | AA4: Lũy kế CF | AB4: DCF | AC4: Doanh thu | AD4: CP biến đổi | AE4: CP cố định | AF4: EBITDA | AG4: Khấu hao | AH4: EBT | AI4: Thuế TNDN | AJ4: LN sau thuế | AK4: Dòng tiền (CF) | AL4: Lũy kế CF | AM4: DCF
A5: 0 | B5: 0 | C5: 0 | D5: 1 | E5: 1 | F5: 1 | O5: =-CAPEX_Dau_tu!$G$31 | P5: =O5 | Q5: =O5*F5 | Z5: =-CAPEX_Dau_tu!$G$31 | AA5: =Z5 | AB5: =Z5*F5 | AK5: =-CAPEX_Dau_tu!$G$31 | AL5: =AK5 | AM5: =AK5*F5
A6: 1 | B6: =INT((A6-1)/12)+1 | C6: =Gia_dinh_Dau_vao!$B$44 | D6: =(1+Gia_dinh_Dau_vao!$C$10)^(B6-1) | E6: =(1+Gia_dinh_Dau_vao!$C$9)^(B6-1) | F6: =1/(1+Gia_dinh_Dau_vao!$C$12)^(A6/12) | G6: =Gia_dinh_Dau_vao!$C$22*C6*D6 | H6: =G6*Gia_dinh_Dau_vao!$C$17 | I6: =Gia_dinh_Dau_vao!$F$40*E6 | J6: =G6-H6-I6 | K6: =IF(A6<=60, CAPEX_Dau_tu!$G$32/60, 0) | L6: =J6-K6 | M6: =IF(L6>0, L6*Gia_dinh_Dau_vao!$C$11, 0) | N6: =L6-M6 | O6: =J6-M6 | P6: =P5+O6 | Q6: =O6*F6 | R6: =Gia_dinh_Dau_vao!$C$23*C6*D6 | S6: =R6*Gia_dinh_Dau_vao!$C$17 | T6: =Gia_dinh_Dau_vao!$F$40*E6 | U6: =R6-S6-T6 | V6: =IF(A6<=60, CAPEX_Dau_tu!$G$32/60, 0) | W6: =U6-V6 | X6: =IF(W6>0, W6*Gia_dinh_Dau_vao!$C$11, 0) | Y6: =W6-X6 | Z6: =U6-X6 | AA6: =AA5+Z6 | AB6: =Z6*F6 | AC6: =Gia_dinh_Dau_vao!$C$24*C6*D6 | AD6: =AC6*Gia_dinh_Dau_vao!$C$17 | AE6: =Gia_dinh_Dau_vao!$F$40*E6 | AF6: =AC6-AD6-AE6 | AG6: =IF(A6<=60, CAPEX_Dau_tu!$G$32/60, 0) | AH6: =AF6-AG6 | AI6: =IF(AH6>0, AH6*Gia_dinh_Dau_vao!$C$11, 0) | AJ6: =AH6-AI6 | AK6: =AF6-AI6 | AL6: =AL5+AK6 | AM6: =AK6*F6
A7: 2 | B7: =INT((A7-1)/12)+1 | C7: =Gia_dinh_Dau_vao!$C$44 | D7: =(1+Gia_dinh_Dau_vao!$C$10)^(B7-1) | E7: =(1+Gia_dinh_Dau_vao!$C$9)^(B7-1) | F7: =1/(1+Gia_dinh_Dau_vao!$C$12)^(A7/12) | G7: =Gia_dinh_Dau_vao!$C$22*C7*D7 | H7: =G7*Gia_dinh_Dau_vao!$C$17 | I7: =Gia_dinh_Dau_vao!$F$40*E7 | J7: =G7-H7-I7 | K7: =IF(A7<=60, CAPEX_Dau_tu!$G$32/60, 0) | L7: =J7-K7 | M7: =IF(L7>0, L7*Gia_dinh_Dau_vao!$C$11, 0) | N7: =L7-M7 | O7: =J7-M7 | P7: =P6+O7 | Q7: =O7*F7 | R7: =Gia_dinh_Dau_vao!$C$23*C7*D7 | S7: =R7*Gia_dinh_Dau_vao!$C$17 | T7: =Gia_dinh_Dau_vao!$F$40*E7 | U7: =R7-S7-T7 | V7: =IF(A7<=60, CAPEX_Dau_tu!$G$32/60, 0) | W7: =U7-V7 | X7: =IF(W7>0, W7*Gia_dinh_Dau_vao!$C$11, 0) | Y7: =W7-X7 | Z7: =U7-X7 | AA7: =AA6+Z7 | AB7: =Z7*F7 | AC7: =Gia_dinh_Dau_vao!$C$24*C7*D7 | AD7: =AC7*Gia_dinh_Dau_vao!$C$17 | AE7: =Gia_dinh_Dau_vao!$F$40*E7 | AF7: =AC7-AD7-AE7 | AG7: =IF(A7<=60, CAPEX_Dau_tu!$G$32/60, 0) | AH7: =AF7-AG7 | AI7: =IF(AH7>0, AH7*Gia_dinh_Dau_vao!$C$11, 0) | AJ7: =AH7-AI7 | AK7: =AF7-AI7 | AL7: =AL6+AK7 | AM7: =AK7*F7
A8: 3 | B8: =INT((A8-1)/12)+1 | C8: =Gia_dinh_Dau_vao!$D$44 | D8: =(1+Gia_dinh_Dau_vao!$C$10)^(B8-1) | E8: =(1+Gia_dinh_Dau_vao!$C$9)^(B8-1) | F8: =1/(1+Gia_dinh_Dau_vao!$C$12)^(A8/12) | G8: =Gia_dinh_Dau_vao!$C$22*C8*D8 | H8: =G8*Gia_dinh_Dau_vao!$C$17 | I8: =Gia_dinh_Dau_vao!$F$40*E8 | J8: =G8-H8-I8 | K8: =IF(A8<=60, CAPEX_Dau_tu!$G$32/60, 0) | L8: =J8-K8 | M8: =IF(L8>0, L8*Gia_dinh_Dau_vao!$C$11, 0) | N8: =L8-M8 | O8: =J8-M8 | P8: =P7+O8 | Q8: =O8*F8 | R8: =Gia_dinh_Dau_vao!$C$23*C8*D8 | S8: =R8*Gia_dinh_Dau_vao!$C$17 | T8: =Gia_dinh_Dau_vao!$F$40*E8 | U8: =R8-S8-T8 | V8: =IF(A8<=60, CAPEX_Dau_tu!$G$32/60, 0) | W8: =U8-V8 | X8: =IF(W8>0, W8*Gia_dinh_Dau_vao!$C$11, 0) | Y8: =W8-X8 | Z8: =U8-X8 | AA8: =AA7+Z8 | AB8: =Z8*F8 | AC8: =Gia_dinh_Dau_vao!$C$24*C8*D8 | AD8: =AC8*Gia_dinh_Dau_vao!$C$17 | AE8: =Gia_dinh_Dau_vao!$F$40*E8 | AF8: =AC8-AD8-AE8 | AG8: =IF(A8<=60, CAPEX_Dau_tu!$G$32/60, 0) | AH8: =AF8-AG8 | AI8: =IF(AH8>0, AH8*Gia_dinh_Dau_vao!$C$11, 0) | AJ8: =AH8-AI8 | AK8: =AF8-AI8 | AL8: =AL7+AK8 | AM8: =AK8*F8
A9: 4 | B9: =INT((A9-1)/12)+1 | C9: =Gia_dinh_Dau_vao!$E$44 | D9: =(1+Gia_dinh_Dau_vao!$C$10)^(B9-1) | E9: =(1+Gia_dinh_Dau_vao!$C$9)^(B9-1) | F9: =1/(1+Gia_dinh_Dau_vao!$C$12)^(A9/12) | G9: =Gia_dinh_Dau_vao!$C$22*C9*D9 | H9: =G9*Gia_dinh_Dau_vao!$C$17 | I9: =Gia_dinh_Dau_vao!$F$40*E9 | J9: =G9-H9-I9 | K9: =IF(A9<=60, CAPEX_Dau_tu!$G$32/60, 0) | L9: =J9-K9 | M9: =IF(L9>0, L9*Gia_dinh_Dau_vao!$C$11, 0) | N9: =L9-M9 | O9: =J9-M9 | P9: =P8+O9 | Q9: =O9*F9 | R9: =Gia_dinh_Dau_vao!$C$23*C9*D9 | S9: =R9*Gia_dinh_Dau_vao!$C$17 | T9: =Gia_dinh_Dau_vao!$F$40*E9 | U9: =R9-S9-T9 | V9: =IF(A9<=60, CAPEX_Dau_tu!$G$32/60, 0) | W9: =U9-V9 | X9: =IF(W9>0, W9*Gia_dinh_Dau_vao!$C$11, 0) | Y9: =W9-X9 | Z9: =U9-X9 | AA9: =AA8+Z9 | AB9: =Z9*F9 | AC9: =Gia_dinh_Dau_vao!$C$24*C9*D9 | AD9: =AC9*Gia_dinh_Dau_vao!$C$17 | AE9: =Gia_dinh_Dau_vao!$F$40*E9 | AF9: =AC9-AD9-AE9 | AG9: =IF(A9<=60, CAPEX_Dau_tu!$G$32/60, 0) | AH9: =AF9-AG9 | AI9: =IF(AH9>0, AH9*Gia_dinh_Dau_vao!$C$11, 0) | AJ9: =AH9-AI9 | AK9: =AF9-AI9 | AL9: =AL8+AK9 | AM9: =AK9*F9
A10: 5 | B10: =INT((A10-1)/12)+1 | C10: =Gia_dinh_Dau_vao!$F$44 | D10: =(1+Gia_dinh_Dau_vao!$C$10)^(B10-1) | E10: =(1+Gia_dinh_Dau_vao!$C$9)^(B10-1) | F10: =1/(1+Gia_dinh_Dau_vao!$C$12)^(A10/12) | G10: =Gia_dinh_Dau_vao!$C$22*C10*D10 | H10: =G10*Gia_dinh_Dau_vao!$C$17 | I10: =Gia_dinh_Dau_vao!$F$40*E10 | J10: =G10-H10-I10 | K10: =IF(A10<=60, CAPEX_Dau_tu!$G$32/60, 0) | L10: =J10-K10 | M10: =IF(L10>0, L10*Gia_dinh_Dau_vao!$C$11, 0) | N10: =L10-M10 | O10: =J10-M10 | P10: =P9+O10 | Q10: =O10*F10 | R10: =Gia_dinh_Dau_vao!$C$23*C10*D10 | S10: =R10*Gia_dinh_Dau_vao!$C$17 | T10: =Gia_dinh_Dau_vao!$F$40*E10 | U10: =R10-S10-T10 | V10: =IF(A10<=60, CAPEX_Dau_tu!$G$32/60, 0) | W10: =U10-V10 | X10: =IF(W10>0, W10*Gia_dinh_Dau_vao!$C$11, 0) | Y10: =W10-X10 | Z10: =U10-X10 | AA10: =AA9+Z10 | AB10: =Z10*F10 | AC10: =Gia_dinh_Dau_vao!$C$24*C10*D10 | AD10: =AC10*Gia_dinh_Dau_vao!$C$17 | AE10: =Gia_dinh_Dau_vao!$F$40*E10 | AF10: =AC10-AD10-AE10 | AG10: =IF(A10<=60, CAPEX_Dau_tu!$G$32/60, 0) | AH10: =AF10-AG10 | AI10: =IF(AH10>0, AH10*Gia_dinh_Dau_vao!$C$11, 0) | AJ10: =AH10-AI10 | AK10: =AF10-AI10 | AL10: =AL9+AK10 | AM10: =AK10*F10
A11: 6 | B11: =INT((A11-1)/12)+1 | C11: =Gia_dinh_Dau_vao!$G$44 | D11: =(1+Gia_dinh_Dau_vao!$C$10)^(B11-1) | E11: =(1+Gia_dinh_Dau_vao!$C$9)^(B11-1) | F11: =1/(1+Gia_dinh_Dau_vao!$C$12)^(A11/12) | G11: =Gia_dinh_Dau_vao!$C$22*C11*D11 | H11: =G11*Gia_dinh_Dau_vao!$C$17 | I11: =Gia_dinh_Dau_vao!$F$40*E11 | J11: =G11-H11-I11 | K11: =IF(A11<=60, CAPEX_Dau_tu!$G$32/60, 0) | L11: =J11-K11 | M11: =IF(L11>0, L11*Gia_dinh_Dau_vao!$C$11, 0) | N11: =L11-M11 | O11: =J11-M11 | P11: =P10+O11 | Q11: =O11*F11 | R11: =Gia_dinh_Dau_vao!$C$23*C11*D11 | S11: =R11*Gia_dinh_Dau_vao!$C$17 | T11: =Gia_dinh_Dau_vao!$F$40*E11 | U11: =R11-S11-T11 | V11: =IF(A11<=60, CAPEX_Dau_tu!$G$32/60, 0) | W11: =U11-V11 | X11: =IF(W11>0, W11*Gia_dinh_Dau_vao!$C$11, 0) | Y11: =W11-X11 | Z11: =U11-X11 | AA11: =AA10+Z11 | AB11: =Z11*F11 | AC11: =Gia_dinh_Dau_vao!$C$24*C11*D11 | AD11: =AC11*Gia_dinh_Dau_vao!$C$17 | AE11: =Gia_dinh_Dau_vao!$F$40*E11 | AF11: =AC11-AD11-AE11 | AG11: =IF(A11<=60, CAPEX_Dau_tu!$G$32/60, 0) | AH11: =AF11-AG11 | AI11: =IF(AH11>0, AH11*Gia_dinh_Dau_vao!$C$11, 0) | AJ11: =AH11-AI11 | AK11: =AF11-AI11 | AL11: =AL10+AK11 | AM11: =AK11*F11
A12: 7 | B12: =INT((A12-1)/12)+1 | C12: =Gia_dinh_Dau_vao!$G$44 | D12: =(1+Gia_dinh_Dau_vao!$C$10)^(B12-1) | E12: =(1+Gia_dinh_Dau_vao!$C$9)^(B12-1) | F12: =1/(1+Gia_dinh_Dau_vao!$C$12)^(A12/12) | G12: =Gia_dinh_Dau_vao!$C$22*C12*D12 | H12: =G12*Gia_dinh_Dau_vao!$C$17 | I12: =Gia_dinh_Dau_vao!$F$40*E12 | J12: =G12-H12-I12 | K12: =IF(A12<=60, CAPEX_Dau_tu!$G$32/60, 0) | L12: =J12-K12 | M12: =IF(L12>0, L12*Gia_dinh_Dau_vao!$C$11, 0) | N12: =L12-M12 | O12: =J12-M12 | P12: =P11+O12 | Q12: =O12*F12 | R12: =Gia_dinh_Dau_vao!$C$23*C12*D12 | S12: =R12*Gia_dinh_Dau_vao!$C$17 | T12: =Gia_dinh_Dau_vao!$F$40*E12 | U12: =R12-S12-T12 | V12: =IF(A12<=60, CAPEX_Dau_tu!$G$32/60, 0) | W12: =U12-V12 | X12: =IF(W12>0, W12*Gia_dinh_Dau_vao!$C$11, 0) | Y12: =W12-X12 | Z12: =U12-X12 | AA12: =AA11+Z12 | AB12: =Z12*F12 | AC12: =Gia_dinh_Dau_vao!$C$24*C12*D12 | AD12: =AC12*Gia_dinh_Dau_vao!$C$17 | AE12: =Gia_dinh_Dau_vao!$F$40*E12 | AF12: =AC12-AD12-AE12 | AG12: =IF(A12<=60, CAPEX_Dau_tu!$G$32/60, 0) | AH12: =AF12-AG12 | AI12: =IF(AH12>0, AH12*Gia_dinh_Dau_vao!$C$11, 0) | AJ12: =AH12-AI12 | AK12: =AF12-AI12 | AL12: =AL11+AK12 | AM12: =AK12*F12
A13: 8 | B13: =INT((A13-1)/12)+1 | C13: =Gia_dinh_Dau_vao!$G$44 | D13: =(1+Gia_dinh_Dau_vao!$C$10)^(B13-1) | E13: =(1+Gia_dinh_Dau_vao!$C$9)^(B13-1) | F13: =1/(1+Gia_dinh_Dau_vao!$C$12)^(A13/12) | G13: =Gia_dinh_Dau_vao!$C$22*C13*D13 | H13: =G13*Gia_dinh_Dau_vao!$C$17 | I13: =Gia_dinh_Dau_vao!$F$40*E13 | J13: =G13-H13-I13 | K13: =IF(A13<=60, CAPEX_Dau_tu!$G$32/60, 0) | L13: =J13-K13 | M13: =IF(L13>0, L13*Gia_dinh_Dau_vao!$C$11, 0) | N13: =L13-M13 | O13: =J13-M13 | P13: =P12+O13 | Q13: =O13*F13 | R13: =Gia_dinh_Dau_vao!$C$23*C13*D13 | S13: =R13*Gia_dinh_Dau_vao!$C$17 | T13: =Gia_dinh_Dau_vao!$F$40*E13 | U13: =R13-S13-T13 | V13: =IF(A13<=60, CAPEX_Dau_tu!$G$32/60, 0) | W13: =U13-V13 | X13: =IF(W13>0, W13*Gia_dinh_Dau_vao!$C$11, 0) | Y13: =W13-X13 | Z13: =U13-X13 | AA13: =AA12+Z13 | AB13: =Z13*F13 | AC13: =Gia_dinh_Dau_vao!$C$24*C13*D13 | AD13: =AC13*Gia_dinh_Dau_vao!$C$17 | AE13: =Gia_dinh_Dau_vao!$F$40*E13 | AF13: =AC13-AD13-AE13 | AG13: =IF(A13<=60, CAPEX_Dau_tu!$G$32/60, 0) | AH13: =AF13-AG13 | AI13: =IF(AH13>0, AH13*Gia_dinh_Dau_vao!$C$11, 0) | AJ13: =AH13-AI13 | AK13: =AF13-AI13 | AL13: =AL12+AK13 | AM13: =AK13*F13
A14: 9 | B14: =INT((A14-1)/12)+1 | C14: =Gia_dinh_Dau_vao!$G$44 | D14: =(1+Gia_dinh_Dau_vao!$C$10)^(B14-1) | E14: =(1+Gia_dinh_Dau_vao!$C$9)^(B14-1) | F14: =1/(1+Gia_dinh_Dau_vao!$C$12)^(A14/12) | G14: =Gia_dinh_Dau_vao!$C$22*C14*D14 | H14: =G14*Gia_dinh_Dau_vao!$C$17 | I14: =Gia_dinh_Dau_vao!$F$40*E14 | J14: =G14-H14-I14 | K14: =IF(A14<=60, CAPEX_Dau_tu!$G$32/60, 0) | L14: =J14-K14 | M14: =IF(L14>0, L14*Gia_dinh_Dau_vao!$C$11, 0) | N14: =L14-M14 | O14: =J14-M14 | P14: =P13+O14 | Q14: =O14*F14 | R14: =Gia_dinh_Dau_vao!$C$23*C14*D14 | S14: =R14*Gia_dinh_Dau_vao!$C$17 | T14: =Gia_dinh_Dau_vao!$F$40*E14 | U14: =R14-S14-T14 | V14: =IF(A14<=60, CAPEX_Dau_tu!$G$32/60, 0) | W14: =U14-V14 | X14: =IF(W14>0, W14*Gia_dinh_Dau_vao!$C$11, 0) | Y14: =W14-X14 | Z14: =U14-X14 | AA14: =AA13+Z14 | AB14: =Z14*F14 | AC14: =Gia_dinh_Dau_vao!$C$24*C14*D14 | AD14: =AC14*Gia_dinh_Dau_vao!$C$17 | AE14: =Gia_dinh_Dau_vao!$F$40*E14 | AF14: =AC14-AD14-AE14 | AG14: =IF(A14<=60, CAPEX_Dau_tu!$G$32/60, 0) | AH14: =AF14-AG14 | AI14: =IF(AH14>0, AH14*Gia_dinh_Dau_vao!$C$11, 0) | AJ14: =AH14-AI14 | AK14: =AF14-AI14 | AL14: =AL13+AK14 | AM14: =AK14*F14
A15: 10 | B15: =INT((A15-1)/12)+1 | C15: =Gia_dinh_Dau_vao!$G$44 | D15: =(1+Gia_dinh_Dau_vao!$C$10)^(B15-1) | E15: =(1+Gia_dinh_Dau_vao!$C$9)^(B15-1) | F15: =1/(1+Gia_dinh_Dau_vao!$C$12)^(A15/12) | G15: =Gia_dinh_Dau_vao!$C$22*C15*D15 | H15: =G15*Gia_dinh_Dau_vao!$C$17 | I15: =Gia_dinh_Dau_vao!$F$40*E15 | J15: =G15-H15-I15 | K15: =IF(A15<=60, CAPEX_Dau_tu!$G$32/60, 0) | L15: =J15-K15 | M15: =IF(L15>0, L15*Gia_dinh_Dau_vao!$C$11, 0) | N15: =L15-M15 | O15: =J15-M15 | P15: =P14+O15 | Q15: =O15*F15 | R15: =Gia_dinh_Dau_vao!$C$23*C15*D15 | S15: =R15*Gia_dinh_Dau_vao!$C$17 | T15: =Gia_dinh_Dau_vao!$F$40*E15 | U15: =R15-S15-T15 | V15: =IF(A15<=60, CAPEX_Dau_tu!$G$32/60, 0) | W15: =U15-V15 | X15: =IF(W15>0, W15*Gia_dinh_Dau_vao!$C$11, 0) | Y15: =W15-X15 | Z15: =U15-X15 | AA15: =AA14+Z15 | AB15: =Z15*F15 | AC15: =Gia_dinh_Dau_vao!$C$24*C15*D15 | AD15: =AC15*Gia_dinh_Dau_vao!$C$17 | AE15: =Gia_dinh_Dau_vao!$F$40*E15 | AF15: =AC15-AD15-AE15 | AG15: =IF(A15<=60, CAPEX_Dau_tu!$G$32/60, 0) | AH15: =AF15-AG15 | AI15: =IF(AH15>0, AH15*Gia_dinh_Dau_vao!$C$11, 0) | AJ15: =AH15-AI15 | AK15: =AF15-AI15 | AL15: =AL14+AK15 | AM15: =AK15*F15
A16: 11 | B16: =INT((A16-1)/12)+1 | C16: =Gia_dinh_Dau_vao!$G$44 | D16: =(1+Gia_dinh_Dau_vao!$C$10)^(B16-1) | E16: =(1+Gia_dinh_Dau_vao!$C$9)^(B16-1) | F16: =1/(1+Gia_dinh_Dau_vao!$C$12)^(A16/12) | G16: =Gia_dinh_Dau_vao!$C$22*C16*D16 | H16: =G16*Gia_dinh_Dau_vao!$C$17 | I16: =Gia_dinh_Dau_vao!$F$40*E16 | J16: =G16-H16-I16 | K16: =IF(A16<=60, CAPEX_Dau_tu!$G$32/60, 0) | L16: =J16-K16 | M16: =IF(L16>0, L16*Gia_dinh_Dau_vao!$C$11, 0) | N16: =L16-M16 | O16: =J16-M16 | P16: =P15+O16 | Q16: =O16*F16 | R16: =Gia_dinh_Dau_vao!$C$23*C16*D16 | S16: =R16*Gia_dinh_Dau_vao!$C$17 | T16: =Gia_dinh_Dau_vao!$F$40*E16 | U16: =R16-S16-T16 | V16: =IF(A16<=60, CAPEX_Dau_tu!$G$32/60, 0) | W16: =U16-V16 | X16: =IF(W16>0, W16*Gia_dinh_Dau_vao!$C$11, 0) | Y16: =W16-X16 | Z16: =U16-X16 | AA16: =AA15+Z16 | AB16: =Z16*F16 | AC16: =Gia_dinh_Dau_vao!$C$24*C16*D16 | AD16: =AC16*Gia_dinh_Dau_vao!$C$17 | AE16: =Gia_dinh_Dau_vao!$F$40*E16 | AF16: =AC16-AD16-AE16 | AG16: =IF(A16<=60, CAPEX_Dau_tu!$G$32/60, 0) | AH16: =AF16-AG16 | AI16: =IF(AH16>0, AH16*Gia_dinh_Dau_vao!$C$11, 0) | AJ16: =AH16-AI16 | AK16: =AF16-AI16 | AL16: =AL15+AK16 | AM16: =AK16*F16
A17: 12 | B17: =INT((A17-1)/12)+1 | C17: =Gia_dinh_Dau_vao!$G$44 | D17: =(1+Gia_dinh_Dau_vao!$C$10)^(B17-1) | E17: =(1+Gia_dinh_Dau_vao!$C$9)^(B17-1) | F17: =1/(1+Gia_dinh_Dau_vao!$C$12)^(A17/12) | G17: =Gia_dinh_Dau_vao!$C$22*C17*D17 | H17: =G17*Gia_dinh_Dau_vao!$C$17 | I17: =Gia_dinh_Dau_vao!$F$40*E17 | J17: =G17-H17-I17 | K17: =IF(A17<=60, CAPEX_Dau_tu!$G$32/60, 0) | L17: =J17-K17 | M17: =IF(L17>0, L17*Gia_dinh_Dau_vao!$C$11, 0) | N17: =L17-M17 | O17: =J17-M17 | P17: =P16+O17 | Q17: =O17*F17 | R17: =Gia_dinh_Dau_vao!$C$23*C17*D17 | S17: =R17*Gia_dinh_Dau_vao!$C$17 | T17: =Gia_dinh_Dau_vao!$F$40*E17 | U17: =R17-S17-T17 | V17: =IF(A17<=60, CAPEX_Dau_tu!$G$32/60, 0) | W17: =U17-V17 | X17: =IF(W17>0, W17*Gia_dinh_Dau_vao!$C$11, 0) | Y17: =W17-X17 | Z17: =U17-X17 | AA17: =AA16+Z17 | AB17: =Z17*F17 | AC17: =Gia_dinh_Dau_vao!$C$24*C17*D17 | AD17: =AC17*Gia_dinh_Dau_vao!$C$17 | AE17: =Gia_dinh_Dau_vao!$F$40*E17 | AF17: =AC17-AD17-AE17 | AG17: =IF(A17<=60, CAPEX_Dau_tu!$G$32/60, 0) | AH17: =AF17-AG17 | AI17: =IF(AH17>0, AH17*Gia_dinh_Dau_vao!$C$11, 0) | AJ17: =AH17-AI17 | AK17: =AF17-AI17 | AL17: =AL16+AK17 | AM17: =AK17*F17
A18: 13 | B18: =INT((A18-1)/12)+1 | C18: =Gia_dinh_Dau_vao!$G$44 | D18: =(1+Gia_dinh_Dau_vao!$C$10)^(B18-1) | E18: =(1+Gia_dinh_Dau_vao!$C$9)^(B18-1) | F18: =1/(1+Gia_dinh_Dau_vao!$C$12)^(A18/12) | G18: =Gia_dinh_Dau_vao!$C$22*C18*D18 | H18: =G18*Gia_dinh_Dau_vao!$C$17 | I18: =Gia_dinh_Dau_vao!$F$40*E18 | J18: =G18-H18-I18 | K18: =IF(A18<=60, CAPEX_Dau_tu!$G$32/60, 0) | L18: =J18-K18 | M18: =IF(L18>0, L18*Gia_dinh_Dau_vao!$C$11, 0) | N18: =L18-M18 | O18: =J18-M18 | P18: =P17+O18 | Q18: =O18*F18 | R18: =Gia_dinh_Dau_vao!$C$23*C18*D18 | S18: =R18*Gia_dinh_Dau_vao!$C$17 | T18: =Gia_dinh_Dau_vao!$F$40*E18 | U18: =R18-S18-T18 | V18: =IF(A18<=60, CAPEX_Dau_tu!$G$32/60, 0) | W18: =U18-V18 | X18: =IF(W18>0, W18*Gia_dinh_Dau_vao!$C$11, 0) | Y18: =W18-X18 | Z18: =U18-X18 | AA18: =AA17+Z18 | AB18: =Z18*F18 | AC18: =Gia_dinh_Dau_vao!$C$24*C18*D18 | AD18: =AC18*Gia_dinh_Dau_vao!$C$17 | AE18: =Gia_dinh_Dau_vao!$F$40*E18 | AF18: =AC18-AD18-AE18 | AG18: =IF(A18<=60, CAPEX_Dau_tu!$G$32/60, 0) | AH18: =AF18-AG18 | AI18: =IF(AH18>0, AH18*Gia_dinh_Dau_vao!$C$11, 0) | AJ18: =AH18-AI18 | AK18: =AF18-AI18 | AL18: =AL17+AK18 | AM18: =AK18*F18
A19: 14 | B19: =INT((A19-1)/12)+1 | C19: =Gia_dinh_Dau_vao!$G$44 | D19: =(1+Gia_dinh_Dau_vao!$C$10)^(B19-1) | E19: =(1+Gia_dinh_Dau_vao!$C$9)^(B19-1) | F19: =1/(1+Gia_dinh_Dau_vao!$C$12)^(A19/12) | G19: =Gia_dinh_Dau_vao!$C$22*C19*D19 | H19: =G19*Gia_dinh_Dau_vao!$C$17 | I19: =Gia_dinh_Dau_vao!$F$40*E19 | J19: =G19-H19-I19 | K19: =IF(A19<=60, CAPEX_Dau_tu!$G$32/60, 0) | L19: =J19-K19 | M19: =IF(L19>0, L19*Gia_dinh_Dau_vao!$C$11, 0) | N19: =L19-M19 | O19: =J19-M19 | P19: =P18+O19 | Q19: =O19*F19 | R19: =Gia_dinh_Dau_vao!$C$23*C19*D19 | S19: =R19*Gia_dinh_Dau_vao!$C$17 | T19: =Gia_dinh_Dau_vao!$F$40*E19 | U19: =R19-S19-T19 | V19: =IF(A19<=60, CAPEX_Dau_tu!$G$32/60, 0) | W19: =U19-V19 | X19: =IF(W19>0, W19*Gia_dinh_Dau_vao!$C$11, 0) | Y19: =W19-X19 | Z19: =U19-X19 | AA19: =AA18+Z19 | AB19: =Z19*F19 | AC19: =Gia_dinh_Dau_vao!$C$24*C19*D19 | AD19: =AC19*Gia_dinh_Dau_vao!$C$17 | AE19: =Gia_dinh_Dau_vao!$F$40*E19 | AF19: =AC19-AD19-AE19 | AG19: =IF(A19<=60, CAPEX_Dau_tu!$G$32/60, 0) | AH19: =AF19-AG19 | AI19: =IF(AH19>0, AH19*Gia_dinh_Dau_vao!$C$11, 0) | AJ19: =AH19-AI19 | AK19: =AF19-AI19 | AL19: =AL18+AK19 | AM19: =AK19*F19
A20: 15 | B20: =INT((A20-1)/12)+1 | C20: =Gia_dinh_Dau_vao!$G$44 | D20: =(1+Gia_dinh_Dau_vao!$C$10)^(B20-1) | E20: =(1+Gia_dinh_Dau_vao!$C$9)^(B20-1) | F20: =1/(1+Gia_dinh_Dau_vao!$C$12)^(A20/12) | G20: =Gia_dinh_Dau_vao!$C$22*C20*D20 | H20: =G20*Gia_dinh_Dau_vao!$C$17 | I20: =Gia_dinh_Dau_vao!$F$40*E20 | J20: =G20-H20-I20 | K20: =IF(A20<=60, CAPEX_Dau_tu!$G$32/60, 0) | L20: =J20-K20 | M20: =IF(L20>0, L20*Gia_dinh_Dau_vao!$C$11, 0) | N20: =L20-M20 | O20: =J20-M20 | P20: =P19+O20 | Q20: =O20*F20 | R20: =Gia_dinh_Dau_vao!$C$23*C20*D20 | S20: =R20*Gia_dinh_Dau_vao!$C$17 | T20: =Gia_dinh_Dau_vao!$F$40*E20 | U20: =R20-S20-T20 | V20: =IF(A20<=60, CAPEX_Dau_tu!$G$32/60, 0) | W20: =U20-V20 | X20: =IF(W20>0, W20*Gia_dinh_Dau_vao!$C$11, 0) | Y20: =W20-X20 | Z20: =U20-X20 | AA20: =AA19+Z20 | AB20: =Z20*F20 | AC20: =Gia_dinh_Dau_vao!$C$24*C20*D20 | AD20: =AC20*Gia_dinh_Dau_vao!$C$17 | AE20: =Gia_dinh_Dau_vao!$F$40*E20 | AF20: =AC20-AD20-AE20 | AG20: =IF(A20<=60, CAPEX_Dau_tu!$G$32/60, 0) | AH20: =AF20-AG20 | AI20: =IF(AH20>0, AH20*Gia_dinh_Dau_vao!$C$11, 0) | AJ20: =AH20-AI20 | AK20: =AF20-AI20 | AL20: =AL19+AK20 | AM20: =AK20*F20
A21: 16 | B21: =INT((A21-1)/12)+1 | C21: =Gia_dinh_Dau_vao!$G$44 | D21: =(1+Gia_dinh_Dau_vao!$C$10)^(B21-1) | E21: =(1+Gia_dinh_Dau_vao!$C$9)^(B21-1) | F21: =1/(1+Gia_dinh_Dau_vao!$C$12)^(A21/12) | G21: =Gia_dinh_Dau_vao!$C$22*C21*D21 | H21: =G21*Gia_dinh_Dau_vao!$C$17 | I21: =Gia_dinh_Dau_vao!$F$40*E21 | J21: =G21-H21-I21 | K21: =IF(A21<=60, CAPEX_Dau_tu!$G$32/60, 0) | L21: =J21-K21 | M21: =IF(L21>0, L21*Gia_dinh_Dau_vao!$C$11, 0) | N21: =L21-M21 | O21: =J21-M21 | P21: =P20+O21 | Q21: =O21*F21 | R21: =Gia_dinh_Dau_vao!$C$23*C21*D21 | S21: =R21*Gia_dinh_Dau_vao!$C$17 | T21: =Gia_dinh_Dau_vao!$F$40*E21 | U21: =R21-S21-T21 | V21: =IF(A21<=60, CAPEX_Dau_tu!$G$32/60, 0) | W21: =U21-V21 | X21: =IF(W21>0, W21*Gia_dinh_Dau_vao!$C$11, 0) | Y21: =W21-X21 | Z21: =U21-X21 | AA21: =AA20+Z21 | AB21: =Z21*F21 | AC21: =Gia_dinh_Dau_vao!$C$24*C21*D21 | AD21: =AC21*Gia_dinh_Dau_vao!$C$17 | AE21: =Gia_dinh_Dau_vao!$F$40*E21 | AF21: =AC21-AD21-AE21 | AG21: =IF(A21<=60, CAPEX_Dau_tu!$G$32/60, 0) | AH21: =AF21-AG21 | AI21: =IF(AH21>0, AH21*Gia_dinh_Dau_vao!$C$11, 0) | AJ21: =AH21-AI21 | AK21: =AF21-AI21 | AL21: =AL20+AK21 | AM21: =AK21*F21
A22: 17 | B22: =INT((A22-1)/12)+1 | C22: =Gia_dinh_Dau_vao!$G$44 | D22: =(1+Gia_dinh_Dau_vao!$C$10)^(B22-1) | E22: =(1+Gia_dinh_Dau_vao!$C$9)^(B22-1) | F22: =1/(1+Gia_dinh_Dau_vao!$C$12)^(A22/12) | G22: =Gia_dinh_Dau_vao!$C$22*C22*D22 | H22: =G22*Gia_dinh_Dau_vao!$C$17 | I22: =Gia_dinh_Dau_vao!$F$40*E22 | J22: =G22-H22-I22 | K22: =IF(A22<=60, CAPEX_Dau_tu!$G$32/60, 0) | L22: =J22-K22 | M22: =IF(L22>0, L22*Gia_dinh_Dau_vao!$C$11, 0) | N22: =L22-M22 | O22: =J22-M22 | P22: =P21+O22 | Q22: =O22*F22 | R22: =Gia_dinh_Dau_vao!$C$23*C22*D22 | S22: =R22*Gia_dinh_Dau_vao!$C$17 | T22: =Gia_dinh_Dau_vao!$F$40*E22 | U22: =R22-S22-T22 | V22: =IF(A22<=60, CAPEX_Dau_tu!$G$32/60, 0) | W22: =U22-V22 | X22: =IF(W22>0, W22*Gia_dinh_Dau_vao!$C$11, 0) | Y22: =W22-X22 | Z22: =U22-X22 | AA22: =AA21+Z22 | AB22: =Z22*F22 | AC22: =Gia_dinh_Dau_vao!$C$24*C22*D22 | AD22: =AC22*Gia_dinh_Dau_vao!$C$17 | AE22: =Gia_dinh_Dau_vao!$F$40*E22 | AF22: =AC22-AD22-AE22 | AG22: =IF(A22<=60, CAPEX_Dau_tu!$G$32/60, 0) | AH22: =AF22-AG22 | AI22: =IF(AH22>0, AH22*Gia_dinh_Dau_vao!$C$11, 0) | AJ22: =AH22-AI22 | AK22: =AF22-AI22 | AL22: =AL21+AK22 | AM22: =AK22*F22
... A65: 60 | B65: =INT((A65-1)/12)+1 | C65: =Gia_dinh_Dau_vao!$G$44 | D65: =(1+Gia_dinh_Dau_vao!$C$10)^(B65-1) | E65: =(1+Gia_dinh_Dau_vao!$C$9)^(B65-1) | F65: =1/(1+Gia_dinh_Dau_vao!$C$12)^(A65/12) | G65: =Gia_dinh_Dau_vao!$C$22*C65*D65 | H65: =G65*Gia_dinh_Dau_vao!$C$17 | I65: =Gia_dinh_Dau_vao!$F$40*E65 | J65: =G65-H65-I65 | K65: =IF(A65<=60, CAPEX_Dau_tu!$G$32/60, 0) | L65: =J65-K65 | M65: =IF(L65>0, L65*Gia_dinh_Dau_vao!$C$11, 0) | N65: =L65-M65 | O65: =J65-M65 | P65: =P64+O65 | Q65: =O65*F65 | R65: =Gia_dinh_Dau_vao!$C$23*C65*D65 | S65: =R65*Gia_dinh_Dau_vao!$C$17 | T65: =Gia_dinh_Dau_vao!$F$40*E65 | U65: =R65-S65-T65 | V65: =IF(A65<=60, CAPEX_Dau_tu!$G$32/60, 0) | W65: =U65-V65 | X65: =IF(W65>0, W65*Gia_dinh_Dau_vao!$C$11, 0) | Y65: =W65-X65 | Z65: =U65-X65 | AA65: =AA64+Z65 | AB65: =Z65*F65 | AC65: =Gia_dinh_Dau_vao!$C$24*C65*D65 | AD65: =AC65*Gia_dinh_Dau_vao!$C$17 | AE65: =Gia_dinh_Dau_vao!$F$40*E65 | AF65: =AC65-AD65-AE65 | AG65: =IF(A65<=60, CAPEX_Dau_tu!$G$32/60, 0) | AH65: =AF65-AG65 | AI65: =IF(AH65>0, AH65*Gia_dinh_Dau_vao!$C$11, 0) | AJ65: =AH65-AI65 | AK65: =AF65-AI65 | AL65: =AL64+AK65 | AM65: =AK65*F65
A66: TỔNG CỘNG 5 NĂM (THÁNG 1 - 60) | G66: =SUM(G6:G65) | H66: =SUM(H6:H65) | I66: =SUM(I6:I65) | J66: =SUM(J6:J65) | K66: =SUM(K6:K65) | L66: =SUM(L6:L65) | M66: =SUM(M6:M65) | N66: =SUM(N6:N65) | O66: =SUM(O6:O65) | P66: =P65 | Q66: =SUM(Q5:Q65) | R66: =SUM(R6:R65) | S66: =SUM(S6:S65) | T66: =SUM(T6:T65) | U66: =SUM(U6:U65) | V66: =SUM(V6:V65) | W66: =SUM(W6:W65) | X66: =SUM(X6:X65) | Y66: =SUM(Y6:Y65) | Z66: =SUM(Z6:Z65) | AA66: =AA65 | AB66: =SUM(AB5:AB65) | AC66: =SUM(AC6:AC65) | AD66: =SUM(AD6:AD65) | AE66: =SUM(AE6:AE65) | AF66: =SUM(AF6:AF65) | AG66: =SUM(AG6:AG65) | AH66: =SUM(AH6:AH65) | AI66: =SUM(AI6:AI65) | AJ66: =SUM(AJ6:AJ65) | AK66: =SUM(AK6:AK65) | AL66: =AL65 | AM66: =SUM(AM5:AM65)
A67: GIÁ TRỊ HIỆN TẠI THUẦN (NPV 5 NĂM, WACC 15%) | Q67: =Q66 | AB67: =AB66 | AM67: =AM66
A68: TỶ SUẤT SINH LỜI NỘI BỘ (IRR NĂM) | Q68: =(1+IRR(O5:O65))^12-1 | AB68: =(1+IRR(Z5:Z65))^12-1 | AM68: =(1+IRR(AK5:AK65))^12-1

Sheet CAPEX_Dau_tu
A1: DỰ TOÁN VỐN ĐẦU TƯ BAN ĐẦU (CAPEX & WORKING CAPITAL) — NHA KHOA PAKSE
A2: Dữ liệu khớp 100% sheet CAPEX gốc từ mo_hinh_phong_kham_pakse.xlsx (Tổng vốn: $127.872,72 USD ~ 3,31 Tỷ VNĐ)
A4: Mã | B4: Hạng mục đầu tư chi tiết | C4: Số lượng | D4: ĐVT | E4: Đơn giá (USD) | F4: Thành tiền (USD) | G4: Thành tiền (Triệu VND) | H4: Tính khấu hao?
A5: A. PHÁP LÝ & GIẤY PHÉP KHỞI TẠO
A6: A01 | B6: Pháp lý, đăng ký doanh nghiệp, giấy phép Sở Y tế | C6: 1 | D6: Gói | E6: 8000 | F6: =C6*E6 | G6: =F6*Gia_dinh_Dau_vao!$C$6/1000000 | H6: Có
A7: B. CẢI TẠO & CHỈNH TRANG MẶT BẰNG
A8: B01 | B8: Đặt cọc tiền thuê mặt bằng | C8: 12 | D8: Tháng | E8: 500 | F8: =C8*E8 | G8: =F8*Gia_dinh_Dau_vao!$C$6/1000000 | H8: Không
A9: B02 | B9: Thiết kế và xin phép thi công (100 m² x $10) | C9: 100 | D9: m² | E9: 10 | F9: =C9*E9 | G9: =F9*Gia_dinh_Dau_vao!$C$6/1000000 | H9: Có
A10: B03 | B10: Thi công cải tạo fit-out (100 m² x $20) | C10: 100 | D10: m² | E10: 20 | F10: =C10*E10 | G10: =F10*Gia_dinh_Dau_vao!$C$6/1000000 | H10: Có
A11: C. TRANG THIẾT BỊ MÁY MÓC NHA KHOA CHUYÊN DỤNG
A12: C01 | B12: Ghế nha khoa đa năng cao cấp (3 bộ x $3.000) | C12: 3 | D12: Bộ | E12: 3000 | F12: =C12*E12 | G12: =F12*Gia_dinh_Dau_vao!$C$6/1000000 | H12: Có
A13: C02 | B13: Hệ thống máy nén khí và hút trung tâm | C13: 1 | D13: Hệ | E13: 1000 | F13: =C13*E13 | G13: =F13*Gia_dinh_Dau_vao!$C$6/1000000 | H13: Có
A14: C03 | B14: Máy chụp X-quang cận chóp | C14: 1 | D14: Bộ | E14: 2000 | F14: =C14*E14 | G14: =F14*Gia_dinh_Dau_vao!$C$6/1000000 | H14: Có
A15: C04 | B15: Máy chụp X-quang toàn cảnh (Panorama CT) | C15: 1 | D15: Máy | E15: 40000 | F15: =C15*E15 | G15: =F15*Gia_dinh_Dau_vao!$C$6/1000000 | H15: Có
A16: C05 | B16: Nồi hấp tiệt trùng, khu vô trùng | C16: 1 | D16: Hệ | E16: 1000 | F16: =C16*E16 | G16: =F16*Gia_dinh_Dau_vao!$C$6/1000000 | H16: Có
A17: C06 | B17: Dụng cụ khám chữa, tay khoan (3 bộ x $1.500) | C17: 3 | D17: Bộ | E17: 1500 | F17: =C17*E17 | G17: =F17*Gia_dinh_Dau_vao!$C$6/1000000 | H17: Có
A18: D. NỘI THẤT, CNTT & LOGISTICS
A19: D01 | B19: Nội thất, máy vi tính, CNTT, phần mềm quản lý | C19: 1 | D19: Gói | E19: 5500 | F19: =C19*E19 | G19: =F19*Gia_dinh_Dau_vao!$C$6/1000000 | H19: Có
A20: D02 | B20: Biển hiệu, nhận diện thương hiệu ngoài trời | C20: 1 | D20: Bộ | E20: 2500 | F20: =C20*E20 | G20: =F20*Gia_dinh_Dau_vao!$C$6/1000000 | H20: Có
A21: D03 | B21: Cước vận chuyển, bảo hiểm thiết bị (4%) | C21: 1 | D21: Gói | E21: 2620 | F21: =C21*E21 | G21: =F21*Gia_dinh_Dau_vao!$C$6/1000000 | H21: Có
A22: D04 | B22: Thuế nhập khẩu thiết bị (2%) | C22: 1 | D22: Gói | E22: 1362.4 | F22: =C22*E22 | G22: =F22*Gia_dinh_Dau_vao!$C$6/1000000 | H22: Có
A23: D05 | B23: VAT nhập khẩu (10%) | C23: 1 | D23: Gói | E23: 6948.24 | F23: =C23*E23 | G23: =F23*Gia_dinh_Dau_vao!$C$6/1000000 | H23: Có
A24: D06 | B24: Phí hải quan, forwarder thông quan | C24: 1 | D24: Chuyến | E24: 800 | F24: =C24*E24 | G24: =F24*Gia_dinh_Dau_vao!$C$6/1000000 | H24: Có
A25: E. VỐN LƯU ĐỘNG & DỰ PHÒNG KHỞI TẠO
A26: E01 | B26: Lương nhân sự trước khai trương (1 tháng) | C26: 1 | D26: Tháng | E26: 6842.39 | F26: =C26*E26 | G26: =F26*Gia_dinh_Dau_vao!$C$6/1000000 | H26: Không
A27: E02 | B27: Chiến dịch marketing trước khai trương | C27: 1 | D27: Chiến dịch | E27: 3000 | F27: =C27*E27 | G27: =F27*Gia_dinh_Dau_vao!$C$6/1000000 | H27: Không
A28: E03 | B28: Vật tư tiêu hao tồn kho ban đầu | C28: 1 | D28: Gói | E28: 6000 | F28: =C28*E28 | G28: =F28*Gia_dinh_Dau_vao!$C$6/1000000 | H28: Không
A29: E04 | B29: Dự phòng phát sinh (10%) | C29: 1 | D29: Gói | E29: 10407.3 | F29: =C29*E29 | G29: =F29*Gia_dinh_Dau_vao!$C$6/1000000 | H29: Không
A30: E05 | B30: Vốn lưu động dự trữ ban đầu (1 tháng chi phí cố định) | C30: 1 | D30: Gói | E30: 13392.39 | F30: =C30*E30 | G30: =F30*Gia_dinh_Dau_vao!$C$6/1000000 | H30: Không
A31: TỔNG CỘNG VỐN ĐẦU TƯ BAN ĐẦU CẦN HUY ĐỘNG (CAPEX!D27) | F31: =F6+F8+F9+F10+F12+F13+F14+F15+F16+F17+F19+F20+F21+F22+F23+F24+F26+F27+F28+F29+F30 | G31: =G6+G8+G9+G10+G12+G13+G14+G15+G16+G17+G19+G20+G21+G22+G23+G24+G26+G27+G28+G29+G30
A32: Trong đó: Cơ sở tính khấu hao (Thiết bị, cải tạo, pháp lý, thuế NK - 60 tháng) | F32: =F6+F9+F10+F12+F13+F14+F15+F16+F17+F19+F20+F21+F22+F23+F24 | G32: =G6+G9+G10+G12+G13+G14+G15+G16+G17+G19+G20+G21+G22+G23+G24 | H32: Khấu hao 5 năm
